Workbook

Sheet 卸车数据
A1: 处理中心子系统-路单查询
A4: 统计条件（当前机构：淄博中心 类型：进口 开始时间：2026-04-01 00:00:00 截止时间：2026-04-03 23:59:59）
A5: 类型 | B5: 交接对象 | C5: 派车单号 | D5: 航班/车牌号 | E5: 车厢/车牌号 | F5: 车厢码 | G5: 封车码 | H5: 路单流水号 | I5: 邮件总数 | J5: 总数 | K5: 未勾核数 | L5: 已勾核数 | M5: 重量(kg) | N5: 状态 | O5: 操作方式 | P5: 操作员 | Q5: 进局时间 | R5: 解车时间 | S5: 卸车完毕时间 | T5: 卸车时长
A6: 进口 | B6: 大宗快包-淄博中心(淄市1) | H6: 4017318 | I6: 103 | J6: 1 | K6: 1 | L6: 0 | M6: 5.15 | N6: 已解车 | O6: 批量接收 | P6: 王才华 | Q6: 46113.466 | R6: 46113.466 | S6: 46113.578 | T6: 2.68小时
A7: 进口 | B7: 淄报刊进 | D7: * | H7: 4012093 | I7: 0 | J7: 117 | K7: 0 | L7: 117 | M7: 0 | N7: 已解车 | O7: 批量接收 | P7: 王才华 | Q7: 46113.474 | R7: 46113.474 | S7: 46113.581 | T7: 2.55小时
A8: 进口 | B8: 淄博中心市趟西(淄汇1)废20260401 | H8: 4013353 | I8: 104 | J8: 7 | K8: 2 | L8: 5 | M8: 25.819 | N8: 已解车 | O8: 批量接收 | P8: 王才华 | Q8: 46113.477 | R8: 46113.477 | S8: 46113.577 | T8: 2.38小时
A9: 进口 | B9: 淄博中心市趟中(淄汇1)废20260401 | H9: 40101 | I9: 4 | J9: 4 | K9: 0 | L9: 4 | M9: 4.651 | N9: 已解车 | O9: 批量接收 | P9: 王才华 | Q9: 46113.478 | R9: 46113.478 | S9: 46113.924 | T9: 4.92小时
A10: 进口 | B10: 淄博中心市趟南(淄汇1)废20260401 | H10: 40101 | I10: 1 | J10: 1 | K10: 0 | L10: 1 | M10: 6.97 | N10: 已解车 | O10: 批量接收 | P10: 王才华 | Q10: 46113.478 | R10: 46113.478 | S10: 46113.578 | T10: 2.38小时
A11: 进口 | B11: 铁山-淄博中心(淄市1)废20260401 | C11: W120538395 | D11: 鲁VA9K89 | H11: 4010001 | I11: 618 | J11: 618 | K11: 0 | L11: 618 | M11: 426.583 | N11: 已解车 | O11: 批量接收 | P11: 王才华 | Q11: 46113.471 | R11: 46113.478 | S11: 46113.578 | T11: 2.38小时
A12: 进口 | B12: 直投-淄博中心(淄市1)废20260401 | C12: W120577356 | D12: 鲁C190X6 | H12: 4010001 | I12: 268 | J12: 22 | K12: 6 | L12: 16 | M12: 108.867 | N12: 已解车 | O12: 批量接收 | P12: 王才华 | Q12: 46113.474 | R12: 46113.478 | S12: 46113.578 | T12: 2.38小时
A13: 进口 | B13: 桓台-淄博中心(淄支1)废20260401 | C13: W120539508 | D13: 鲁CM0733 | H13: 4010001 | I13: 691 | J13: 421 | K13: 11 | L13: 410 | M13: 146.737 | N13: 已解车 | O13: 批量接收 | P13: 王才华 | Q13: 46113.483 | R13: 46113.485 | S13: 46113.58 | T13: 2.28小时
A14: 进口 | B14: 淄博中心市趟中(淄汇1)废20260401 | H14: 40101 | I14: 1 | J14: 1 | K14: 0 | L14: 1 | M14: 7.86 | N14: 已解车 | O14: 批量接收 | P14: 王才华 | Q14: 46113.478 | R14: 46113.485 | S14: 46113.924 | T14: 4.92小时
A15: 进口 | B15: 淄博中心市趟中(淄汇1)废20260401 | H15: 40102 | I15: 1 | J15: 1 | K15: 0 | L15: 1 | M15: 0.236 | N15: 已解车 | O15: 批量接收 | P15: 王才华 | Q15: 46113.485 | R15: 46113.485 | S15: 46113.578 | T15: 2.22小时
A16: 进口 | B16: 淄博中心市趟北(淄汇1)废20260401 | H16: 40101 | I16: 6 | J16: 6 | K16: 0 | L16: 6 | M16: 13.776 | N16: 已解车 | O16: 批量接收 | P16: 王才华 | Q16: 46113.487 | R16: 46113.487 | S16: 46113.923 | T16: 4.37小时
A17: 进口 | B17: 淄博中心市趟中(淄汇1)废20260401 | H17: 40101 | I17: 2 | J17: 2 | K17: 0 | L17: 2 | M17: 5.752 | N17: 已解车 | O17: 批量接收 | P17: 王才华 | Q17: 46113.478 | R17: 46113.487 | S17: 46113.924 | T17: 4.92小时
A18: 进口 | B18: 沣东-淄博中心(淄市1)废20260401 | C18: W120540260 | D18: 鲁C5399S | H18: 4010001 | I18: 45 | J18: 31 | K18: 1 | L18: 30 | M18: 197.194 | N18: 已解车 | O18: 批量接收 | P18: 王才华 | Q18: 46113.49 | R18: 46113.492 | S18: 46113.578 | T18: 2.05小时
A19: 进口 | B19: 经开-淄博中心(淄市1)废20260401 | C19: W120564234 | D19: 鲁V3GF39 | H19: 4010001 | I19: 97 | J19: 22 | K19: 2 | L19: 20 | M19: 91.99 | N19: 已解车 | O19: 批量接收 | P19: 王才华 | Q19: 46113.492 | R19: 46113.492 | S19: 46122.533 | T19: 216.95小时
A20: 进口 | B20: 周村-淄博中心(淄支1)废20260401 | C20: W120537902 | D20: 鲁NH5667 | E20: 鲁A8A00挂 | F20: SDA8A00GG | H20: 4010001 | I20: 122 | J20: 101 | K20: 13 | L20: 52 | M20: 85.128 | N20: 已解车 | O20: 批量接收 | P20: 王才华 | Q20: 46113.491 | R20: 46113.493 | S20: 46113.58 | T20: 2.08小时
A21: 进口 | B21: 淄博中心市趟北(淄汇1)废20260401 | H21: 40101 | I21: 1 | J21: 1 | K21: 0 | L21: 1 | M21: 6.305 | N21: 已解车 | O21: 批量接收 | P21: 王才华 | Q21: 46113.487 | R21: 46113.493 | S21: 46113.923 | T21: 4.37小时
A22: 进口 | B22: 临淄-淄博中心(淄支1)废20260401 | C22: W120538081 | D22: 鲁VW1570 | H22: 4010001 | I22: 625 | J22: 625 | K22: 6 | L22: 619 | M22: 773.78 | N22: 已解车 | O22: 批量接收 | P22: 王才华 | Q22: 46113.494 | R22: 46113.494 | S22: 46113.58 | T22: 2.07小时
A23: 进口 | B23: 济南-淄博(淄快包1)废20260401 | C23: W120537257 | D23: 鲁AE2529 | H23: 4010001 | I23: 208 | J23: 52 | K23: 1 | L23: 51 | M23: 120.829 | N23: 已解车 | O23: 扫描接收 | P23: 王才华 | Q23: 46113.494 | R23: 46113.496 | S23: 46113.581 | T23: 2.03小时
A24: 进口 | B24: 高新-淄博中心(淄市1)废20260401 | C24: W120540086 | D24: 鲁CD36Y6 | H24: 4010001 | I24: 211 | J24: 83 | K24: 3 | L24: 80 | M24: 142.73 | N24: 已解车 | O24: 批量接收 | P24: 王才华 | Q24: 46113.502 | R24: 46113.502 | S24: 46113.578 | T24: 1.80小时
A25: 进口 | B25: 博山-淄博中心(淄支1)废20260401 | C25: W120564245 | D25: 鲁AP3397 | F25: SDC8T71GG | H25: 4010001 | I25: 1452 | J25: 1444 | K25: 2 | L25: 1442 | M25: 3765.295 | N25: 已解车 | O25: 批量接收 | P25: 王才华 | Q25: 46113.501 | R25: 46113.503 | S25: 46113.58 | T25: 1.85小时
A26: 进口 | B26: 铁山-淄博中心(淄市2) | H26: 4013561 | I26: 13 | J26: 11 | K26: 0 | L26: 11 | M26: 8.299 | N26: 已解车 | O26: 批量接收 | P26: 王才华 | Q26: 46113.714 | R26: 46113.714 | S26: 46113.924 | T26: 5.02小时
A27: 进口 | B27: 铁山-淄博中心(淄市2) | H27: 40101 | I27: 98 | J27: 15 | K27: 0 | L27: 15 | M27: 27.458 | N27: 已解车 | O27: 批量接收 | P27: 王才华 | Q27: 46113.714 | R27: 46113.714 | S27: 46113.924 | T27: 5.02小时
A28: 进口 | B28: 铁山-淄博中心(淄市2) | H28: 4013805 | I28: 12 | J28: 3 | K28: 0 | L28: 3 | M28: 5.942 | N28: 已解车 | O28: 批量接收 | P28: 王才华 | Q28: 46113.714 | R28: 46113.714 | S28: 46113.924 | T28: 5.02小时
A29: 进口 | B29: 铁山-淄博中心(淄市2) | H29: 4013793 | I29: 91 | J29: 4 | K29: 0 | L29: 4 | M29: 35.961 | N29: 已解车 | O29: 批量接收 | P29: 王才华 | Q29: 46113.714 | R29: 46113.714 | S29: 46113.924 | T29: 5.02小时
A30: 进口 | B30: 铁山-淄博中心(淄市2) | H30: 4013646 | I30: 25 | J30: 12 | K30: 0 | L30: 12 | M30: 8.24 | N30: 已解车 | O30: 批量接收 | P30: 王才华 | Q30: 46113.714 | R30: 46113.714 | S30: 46113.924 | T30: 5.02小时
A31: 进口 | B31: 淄博中心市趟西(淄汇2) | H31: 40101 | I31: 27 | J31: 9 | K31: 0 | L31: 9 | M31: 17.511 | N31: 已解车 | O31: 批量接收 | P31: 王才华 | Q31: 46113.715 | R31: 46113.715 | S31: 46113.923 | T31: 4.38小时
A32: 进口 | B32: 淄博中心市趟西(淄汇2) | H32: 4013647 | I32: 49 | J32: 15 | K32: 2 | L32: 13 | M32: 12.29 | N32: 已解车 | O32: 批量接收 | P32: 王才华 | Q32: 46113.715 | R32: 46113.715 | S32: 46113.923 | T32: 5.00小时
A33: 进口 | B33: 淄博中心市趟北(淄汇2) | H33: 40101 | I33: 18 | J33: 3 | K33: 0 | L33: 3 | M33: 13.148 | N33: 已解车 | O33: 批量接收 | P33: 王才华 | Q33: 46113.715 | R33: 46113.715 | S33: 46113.924 | T33: 4.38小时
A34: 进口 | B34: 淄博中心市趟中(淄汇2) | H34: 40101 | I34: 5 | J34: 4 | K34: 0 | L34: 4 | M34: 5.142 | N34: 已解车 | O34: 批量接收 | P34: 王才华 | Q34: 46113.715 | R34: 46113.715 | S34: 46113.924 | T34: 4.93小时
A35: 进口 | B35: 淄博中心市趟南(淄汇2) | H35: 40101 | I35: 19 | J35: 7 | K35: 0 | L35: 7 | M35: 12.804 | N35: 已解车 | O35: 批量接收 | P35: 王才华 | Q35: 46113.717 | R35: 46113.717 | S35: 46113.924 | T35: 4.38小时
A36: 进口 | B36: 淄博中心市趟西(淄汇2) | H36: 40101 | I36: 21 | J36: 8 | K36: 0 | L36: 8 | M36: 3.183 | N36: 已解车 | O36: 批量接收 | P36: 王才华 | Q36: 46113.715 | R36: 46113.717 | S36: 46113.923 | T36: 4.38小时
A37: 进口 | B37: 淄博中心市趟北(淄汇2) | H37: 40101 | I37: 19 | J37: 11 | K37: 0 | L37: 11 | M37: 23.03 | N37: 已解车 | O37: 批量接收 | P37: 王才华 | Q37: 46113.715 | R37: 46113.717 | S37: 46113.924 | T37: 4.38小时
... A41: 进口 | B41: 淄博中心市趟中(淄汇1)废20260401 | H41: 40101 | I41: 1 | J41: 1 | K41: 0 | L41: 1 | M41: 0.486 | N41: 已解车 | O41: 批量接收 | P41: 王才华 | Q41: 46113.478 | R41: 46113.718 | S41: 46113.924 | T41: 4.92小时
A42: 进口 | B42: 淄川-淄博中心(钟家临1)废20260401 | C42: W120587076 | D42: 鲁H48C53 | G42: 12345678911111 | H42: 4010002 | I42: 1350 | J42: 1350 | K42: 8 | L42: 1342 | M42: 2421.625 | N42: 已解车 | O42: 批量接收 | P42: 王才华 | Q42: 46113.713 | R42: 46113.719 | S42: 46114.003 | T42: 6.83小时
A43: 进口 | B43: 淄博中心市趟西(淄汇2) | H43: 4013729 | I43: 2 | J43: 1 | K43: 1 | L43: 0 | M43: 1.31 | N43: 已解车 | O43: 批量接收 | P43: 王才华 | Q43: 46113.722 | R43: 46113.722 | S43: 46113.923 | T43: 4.83小时
A44: 进口 | B44: 淄博中心市趟西(淄汇2) | H44: 40101 | I44: 54 | J44: 12 | K44: 0 | L44: 12 | M44: 6.502 | N44: 已解车 | O44: 批量接收 | P44: 王才华 | Q44: 46113.715 | R44: 46113.74 | S44: 46113.923 | T44: 4.38小时
A45: 进口 | B45: 淄博中心市趟北(淄汇2) | H45: 40101 | I45: 11 | J45: 4 | K45: 0 | L45: 4 | M45: 6.415 | N45: 已解车 | O45: 批量接收 | P45: 王才华 | Q45: 46113.715 | R45: 46113.74 | S45: 46113.924 | T45: 4.38小时
...

Sheet 环线数据
A1: 处理量-总量统计
A2: 统计日期: 2026年04月01日00时 - 2026年04月01日23时
A3: 查询方案： 否 展示方式： 按邮件种类展示
A4: 总处理量
A5: 序 号 | B5: 所属机构 | C5: 所属车间 | D5: 统计时间 | E5: 合计 | G5: 散件外走量 | X5: 分拣封发量 | BG5: 总包经转量
E6: 处理量合计 | F6: 纯散件合计 | G6: 合计 | H6: 平信 | I6: 平刷 | J6: 报刊 | K6: 杂志 | L6: 特快专递 | M6: 快包 | N6: 普包 | O6: 挂信 | P6: 挂刷 | Q6: 约投挂信 | R6: 国际 | S6: 条码化平信 | T6: 国内即日 | U6: 国内标快 | V6: 电商标快 | W6: 其他 | X6: 合计 | Y6: 小计 | AA6: 平信 | AC6: 平刷 | AE6: 报刊 | AG6: 杂志 | AI6: 特快专递 | AK6: 快包 | AM6: 普包 | AO6: 挂信 | AQ6: 挂刷 | AS6: 约投挂信 | AU6: 国际 | AW6: 条码化平信 | AY6: 国内即日 | BA6: 国内标快 | BC6: 电商标快 | BE6: 其他 | BG6: 合计 | BH6: 小计 | BJ6: 平信 | BL6: 平刷 | BN6: 报刊 | BP6: 杂志 | BR6: 特快专递 | BT6: 快包 | BV6: 普包 | BX6: 挂信 | BZ6: 挂刷 | CB6: 约投挂信 | CD6: 国际 | CF6: 条码化平信 | CH6: 国内即日 | CJ6: 国内标快 | CL6: 电商标快 | CN6: 其他
Y7: 总包数 | Z7: 内件数 | AA7: 总包数 | AB7: 内件数 | AC7: 总包数 | AD7: 内件数 | AE7: 总包数 | AF7: 内件数 | AG7: 总包数 | AH7: 内件数 | AI7: 总包数 | AJ7: 内件数 | AK7: 总包数 | AL7: 内件数 | AM7: 总包数 | AN7: 内件数 | AO7: 总包数 | AP7: 内件数 | AQ7: 总包数 | AR7: 内件数 | AS7: 总包数 | AT7: 内件数 | AU7: 总包数 | AV7: 内件数 | AW7: 总包数 | AX7: 内件数 | AY7: 总包数 | AZ7: 内件数 | BA7: 总包数 | BB7: 内件数 | BC7: 总包数 | BD7: 内件数 | BE7: 总包数 | BF7: 内件数 | BH7: 总包数 | BI7: 内件数 | BJ7: 总包数 | BK7: 内件数 | BL7: 总包数 | BM7: 内件数 | BN7: 总包数 | BO7: 内件数 | BP7: 总包数 | BQ7: 内件数 | BR7: 总包数 | BS7: 内件数 | BT7: 总包数 | BU7: 内件数 | BV7: 总包数 | BW7: 内件数 | BX7: 总包数 | BY7: 内件数 | BZ7: 总包数 | CA7: 内件数 | CB7: 总包数 | CC7: 内件数 | CD7: 总包数 | CE7: 内件数 | CF7: 总包数 | CG7: 内件数 | CH7: 总包数 | CI7: 内件数 | CJ7: 总包数 | CK7: 内件数 | CL7: 总包数 | CM7: 内件数 | CN7: 总包数 | CO7: 内件数
A8: 1 | B8: 淄博中心(综合进出)(25500071) | C8: 淄博分拨(WS25500003) | D8: 2026-04-01 00 | E8: 8828 | F8: =G8+Y8+BH8 -> 1608 | G8: 1440 | H8: 0 | I8: 0 | J8: 0 | K8: 0 | L8: 215 | M8: 1003 | N8: 16 | O8: 0 | P8: 1 | Q8: 0 | R8: 0 | S8: 0 | T8: 0 | U8: 2 | V8: 203 | W8: 0 | X8: 7347 | Y8: 127 | Z8: 7220 | AA8: 0 | AB8: 0 | AC8: 7 | AD8: 833 | AE8: 0 | AF8: 0 | AG8: 0 | AH8: 0 | AI8: 4 | AJ8: 101 | AK8: 116 | AL8: 6280 | AM8: 0 | AN8: 6 | AO8: 0 | AP8: 0 | AQ8: 0 | AR8: 0 | AS8: 0 | AT8: 0 | AU8: 0 | AV8: 0 | AW8: 0 | AX8: 0 | AY8: 0 | AZ8: 0 | BA8: 0 | BB8: 0 | BC8: 0 | BD8: 0 | BE8: 0 | BF8: 0 | BG8: 41 | BH8: 41 | BI8: 894 | BJ8: 0 | BK8: 0 | BL8: 0 | BM8: 0 | BN8: 0 | BO8: 0 | BP8: 0 | BQ8: 0 | BR8: 0 | BS8: 0 | BT8: 41 | BU8: 894 | BV8: 0 | BW8: 0 | BX8: 0 | BY8: 0 | BZ8: 0 | CA8: 0 | CB8: 0 | CC8: 0 | CD8: 0 | CE8: 0 | CF8: 0 | CG8: 0 | CH8: 0 | CI8: 0 | CJ8: 0 | CK8: 0 | CL8: 0 | CM8: 0 | CN8: 0 | CO8: 0
A9: 2 | B9: 淄博中心(综合进出)(25500071) | C9: 淄博分拨(WS25500003) | D9: 2026-04-01 01 | E9: 17122 | F9: =G9+Y9+BH9 -> 4607 | G9: 4348 | H9: 0 | I9: 0 | J9: 0 | K9: 0 | L9: 372 | M9: 3089 | N9: 20 | O9: 0 | P9: 0 | Q9: 0 | R9: 0 | S9: 0 | T9: 0 | U9: 10 | V9: 857 | W9: 0 | X9: 12714 | Y9: 199 | Z9: 12515 | AA9: 0 | AB9: 0 | AC9: 2 | AD9: 238 | AE9: 0 | AF9: 0 | AG9: 0 | AH9: 0 | AI9: 17 | AJ9: 568 | AK9: 180 | AL9: 11706 | AM9: 0 | AN9: 3 | AO9: 0 | AP9: 0 | AQ9: 0 | AR9: 0 | AS9: 0 | AT9: 0 | AU9: 0 | AV9: 0 | AW9: 0 | AX9: 0 | AY9: 0 | AZ9: 0 | BA9: 0 | BB9: 0 | BC9: 0 | BD9: 0 | BE9: 0 | BF9: 0 | BG9: 60 | BH9: 60 | BI9: 2471 | BJ9: 0 | BK9: 0 | BL9: 0 | BM9: 0 | BN9: 0 | BO9: 0 | BP9: 0 | BQ9: 0 | BR9: 0 | BS9: 0 | BT9: 55 | BU9: 2431 | BV9: 0 | BW9: 0 | BX9: 5 | BY9: 40 | BZ9: 0 | CA9: 0 | CB9: 0 | CC9: 0 | CD9: 0 | CE9: 0 | CF9: 0 | CG9: 0 | CH9: 0 | CI9: 0 | CJ9: 0 | CK9: 0 | CL9: 0 | CM9: 0 | CN9: 0 | CO9: 0
A10: 3 | B10: 淄博中心(综合进出)(25500071) | C10: 淄博分拨(WS25500003) | D10: 2026-04-01 02 | E10: 18519 | F10: =G10+Y10+BH10 -> 3701 | G10: 3414 | H10: 0 | I10: 0 | J10: 0 | K10: 0 | L10: 268 | M10: 2581 | N10: 7 | O10: 0 | P10: 2 | Q10: 0 | R10: 0 | S10: 0 | T10: 0 | U10: 6 | V10: 550 | W10: 0 | X10: 15043 | Y10: 225 | Z10: 14818 | AA10: 0 | AB10: 0 | AC10: 1 | AD10: 119 | AE10: 0 | AF10: 0 | AG10: 0 | AH10: 0 | AI10: 15 | AJ10: 476 | AK10: 209 | AL10: 14219 | AM10: 0 | AN10: 4 | AO10: 0 | AP10: 0 | AQ10: 0 | AR10: 0 | AS10: 0 | AT10: 0 | AU10: 0 | AV10: 0 | AW10: 0 | AX10: 0 | AY10: 0 | AZ10: 0 | BA10: 0 | BB10: 0 | BC10: 0 | BD10: 0 | BE10: 0 | BF10: 0 | BG10: 62 | BH10: 62 | BI10: 1392 | BJ10: 0 | BK10: 0 | BL10: 0 | BM10: 0 | BN10: 0 | BO10: 0 | BP10: 0 | BQ10: 0 | BR10: 0 | BS10: 0 | BT10: 51 | BU10: 1299 | BV10: 0 | BW10: 0 | BX10: 11 | BY10: 93 | BZ10: 0 | CA10: 0 | CB10: 0 | CC10: 0 | CD10: 0 | CE10: 0 | CF10: 0 | CG10: 0 | CH10: 0 | CI10: 0 | CJ10: 0 | CK10: 0 | CL10: 0 | CM10: 0 | CN10: 0 | CO10: 0
A11: 4 | B11: 淄博中心(综合进出)(25500071) | C11: 淄博分拨(WS25500003) | D11: 2026-04-01 03 | E11: 17442 | F11: =G11+Y11+BH11 -> 4838 | G11: 4644 | H11: 0 | I11: 0 | J11: 0 | K11: 0 | L11: 1477 | M11: 2596 | N11: 7 | O11: 0 | P11: 1 | Q11: 0 | R11: 0 | S11: 0 | T11: 0 | U11: 6 | V11: 557 | W11: 0 | X11: 12772 | Y11: 168 | Z11: 12604 | AA11: 0 | AB11: 0 | AC11: 0 | AD11: 0 | AE11: 0 | AF11: 0 | AG11: 0 | AH11: 0 | AI11: 16 | AJ11: 397 | AK11: 152 | AL11: 12203 | AM11: 0 | AN11: 4 | AO11: 0 | AP11: 0 | AQ11: 0 | AR11: 0 | AS11: 0 | AT11: 0 | AU11: 0 | AV11: 0 | AW11: 0 | AX11: 0 | AY11: 0 | AZ11: 0 | BA11: 0 | BB11: 0 | BC11: 0 | BD11: 0 | BE11: 0 | BF11: 0 | BG11: 26 | BH11: 26 | BI11: 926 | BJ11: 0 | BK11: 0 | BL11: 0 | BM11: 0 | BN11: 0 | BO11: 0 | BP11: 0 | BQ11: 0 | BR11: 1 | BS11: 1 | BT11: 25 | BU11: 925 | BV11: 0 | BW11: 0 | BX11: 0 | BY11: 0 | BZ11: 0 | CA11: 0 | CB11: 0 | CC11: 0 | CD11: 0 | CE11: 0 | CF11: 0 | CG11: 0 | CH11: 0 | CI11: 0 | CJ11: 0 | CK11: 0 | CL11: 0 | CM11: 0 | CN11: 0 | CO11: 0
A12: 5 | B12: 淄博中心(综合进出)(25500071) | C12: 淄博分拨(WS25500003) | D12: 2026-04-01 04 | E12: 21881 | F12: =G12+Y12+BH12 -> 5326 | G12: 4995 | H12: 0 | I12: 0 | J12: 0 | K12: 0 | L12: 842 | M12: 3312 | N12: 21 | O12: 0 | P12: 1 | Q12: 0 | R12: 0 | S12: 0 | T12: 0 | U12: 8 | V12: 811 | W12: 0 | X12: 16818 | Y12: 263 | Z12: 16555 | AA12: 0 | AB12: 0 | AC12: 11 | AD12: 1309 | AE12: 0 | AF12: 0 | AG12: 0 | AH12: 0 | AI12: 86 | AJ12: 2546 | AK12: 166 | AL12: 12694 | AM12: 0 | AN12: 6 | AO12: 0 | AP12: 0 | AQ12: 0 | AR12: 0 | AS12: 0 | AT12: 0 | AU12: 0 | AV12: 0 | AW12: 0 | AX12: 0 | AY12: 0 | AZ12: 0 | BA12: 0 | BB12: 0 | BC12: 0 | BD12: 0 | BE12: 0 | BF12: 0 | BG12: 68 | BH12: 68 | BI12: 4097 | BJ12: 0 | BK12: 0 | BL12: 0 | BM12: 0 | BN12: 0 | BO12: 0 | BP12: 0 | BQ12: 0 | BR12: 0 | BS12: 0 | BT12: 68 | BU12: 4097 | BV12: 0 | BW12: 0 | BX12: 0 | BY12: 0 | BZ12: 0 | CA12: 0 | CB12: 0 | CC12: 0 | CD12: 0 | CE12: 0 | CF12: 0 | CG12: 0 | CH12: 0 | CI12: 0 | CJ12: 0 | CK12: 0 | CL12: 0 | CM12: 0 | CN12: 0 | CO12: 0
A13: 6 | B13: 淄博中心(综合进出)(25500071) | C13: 淄博分拨(WS25500003) | D13: 2026-04-01 05 | E13: 12631 | F13: =G13+Y13+BH13 -> 3064 | G13: 2517 | H13: 0 | I13: 0 | J13: 0 | K13: 0 | L13: 291 | M13: 1999 | N13: 4 | O13: 3 | P13: 1 | Q13: 0 | R13: 0 | S13: 0 | T13: 0 | U13: 3 | V13: 216 | W13: 0 | X13: 9994 | Y13: 427 | Z13: 9567 | AA13: 0 | AB13: 0 | AC13: 0 | AD13: 0 | AE13: 0 | AF13: 0 | AG13: 0 | AH13: 0 | AI13: 204 | AJ13: 1662 | AK13: 223 | AL13: 7896 | AM13: 0 | AN13: 9 | AO13: 0 | AP13: 0 | AQ13: 0 | AR13: 0 | AS13: 0 | AT13: 0 | AU13: 0 | AV13: 0 | AW13: 0 | AX13: 0 | AY13: 0 | AZ13: 0 | BA13: 0 | BB13: 0 | BC13: 0 | BD13: 0 | BE13: 0 | BF13: 0 | BG13: 120 | BH13: 120 | BI13: 216 | BJ13: 0 | BK13: 0 | BL13: 0 | BM13: 0 | BN13: 118 | BO13: 127 | BP13: 0 | BQ13: 0 | BR13: 0 | BS13: 0 | BT13: 2 | BU13: 89 | BV13: 0 | BW13: 0 | BX13: 0 | BY13: 0 | BZ13: 0 | CA13: 0 | CB13: 0 | CC13: 0 | CD13: 0 | CE13: 0 | CF13: 0 | CG13: 0 | CH13: 0 | CI13: 0 | CJ13: 0 | CK13: 0 | CL13: 0 | CM13: 0 | CN13: 0 | CO13: 0
A14: 7 | B14: 淄博中心(综合进出)(25500071) | C14: 淄博分拨(WS25500003) | D14: 2026-04-01 06 | E14: 1229 | F14: =G14+Y14+BH14 -> 1229 | G14: 1229 | H14: 0 | I14: 0 | J14: 0 | K14: 0 | L14: 603 | M14: 175 | N14: 0 | O14: 0 | P14: 1 | Q14: 0 | R14: 0 | S14: 0 | T14: 0 | U14: 0 | V14: 450 | W14: 0 | X14: 0 | Y14: 0 | Z14: 0 | AA14: 0 | AB14: 0 | AC14: 0 | AD14: 0 | AE14: 0 | AF14: 0 | AG14: 0 | AH14: 0 | AI14: 0 | AJ14: 0 | AK14: 0 | AL14: 0 | AM14: 0 | AN14: 0 | AO14: 0 | AP14: 0 | AQ14: 0 | AR14: 0 | AS14: 0 | AT14: 0 | AU14: 0 | AV14: 0 | AW14: 0 | AX14: 0 | AY14: 0 | AZ14: 0 | BA14: 0 | BB14: 0 | BC14: 0 | BD14: 0 | BE14: 0 | BF14: 0 | BG14: 0 | BH14: 0 | BI14: 0 | BJ14: 0 | BK14: 0 | BL14: 0 | BM14: 0 | BN14: 0 | BO14: 0 | BP14: 0 | BQ14: 0 | BR14: 0 | BS14: 0 | BT14: 0 | BU14: 0 | BV14: 0 | BW14: 0 | BX14: 0 | BY14: 0 | BZ14: 0 | CA14: 0 | CB14: 0 | CC14: 0 | CD14: 0 | CE14: 0 | CF14: 0 | CG14: 0 | CH14: 0 | CI14: 0 | CJ14: 0 | CK14: 0 | CL14: 0 | CM14: 0 | CN14: 0 | CO14: 0
A15: 8 | B15: 淄博中心(综合进出)(25500071) | C15: 淄博分拨(WS25500003) | D15: 2026-04-01 07 | E15: 1528 | F15: =G15+Y15+BH15 -> 1528 | G15: 1521 | H15: 0 | I15: 0 | J15: 0 | K15: 0 | L15: 84 | M15: 1057 | N15: 6 | O15: 0 | P15: 0 | Q15: 0 | R15: 0 | S15: 0 | T15: 0 | U15: 1 | V15: 373 | W15: 0 | X15: 0 | Y15: 0 | Z15: 0 | AA15: 0 | AB15: 0 | AC15: 0 | AD15: 0 | AE15: 0 | AF15: 0 | AG15: 0 | AH15: 0 | AI15: 0 | AJ15: 0 | AK15: 0 | AL15: 0 | AM15: 0 | AN15: 0 | AO15: 0 | AP15: 0 | AQ15: 0 | AR15: 0 | AS15: 0 | AT15: 0 | AU15: 0 | AV15: 0 | AW15: 0 | AX15: 0 | AY15: 0 | AZ15: 0 | BA15: 0 | BB15: 0 | BC15: 0 | BD15: 0 | BE15: 0 | BF15: 0 | BG15: 7 | BH15: 7 | BI15: 7 | BJ15: 0 | BK15: 0 | BL15: 0 | BM15: 0 | BN15: 7 | BO15: 7 | BP15: 0 | BQ15: 0 | BR15: 0 | BS15: 0 | BT15: 0 | BU15: 0 | BV15: 0 | BW15: 0 | BX15: 0 | BY15: 0 | BZ15: 0 | CA15: 0 | CB15: 0 | CC15: 0 | CD15: 0 | CE15: 0 | CF15: 0 | CG15: 0 | CH15: 0 | CI15: 0 | CJ15: 0 | CK15: 0 | CL15: 0 | CM15: 0 | CN15: 0 | CO15: 0
A16: 9 | B16: 淄博中心(综合进出)(25500071) | C16: 淄博分拨(WS25500003) | D16: 2026-04-01 08 | E16: 7398 | F16: =G16+Y16+BH16 -> 3243 | G16: 3048 | H16: 0 | I16: 0 | J16: 0 | K16: 0 | L16: 212 | M16: 2217 | N16: 10 | O16: 0 | P16: 0 | Q16: 0 | R16: 0 | S16: 0 | T16: 0 | U16: 5 | V16: 604 | W16: 0 | X16: 4252 | Y16: 97 | Z16: 4155 | AA16: 0 | AB16: 0 | AC16: 0 | AD16: 0 | AE16: 0 | AF16: 0 | AG16: 0 | AH16: 0 | AI16: 2 | AJ16: 44 | AK16: 95 | AL16: 4110 | AM16: 0 | AN16: 1 | AO16: 0 | AP16: 0 | AQ16: 0 | AR16: 0 | AS16: 0 | AT16: 0 | AU16: 0 | AV16: 0 | AW16: 0 | AX16: 0 | AY16: 0 | AZ16: 0 | BA16: 0 | BB16: 0 | BC16: 0 | BD16: 0 | BE16: 0 | BF16: 0 | BG16: 98 | BH16: 98 | BI16: 5168 | BJ16: 7 | BK16: 0 | BL16: 0 | BM16: 0 | BN16: 0 | BO16: 0 | BP16: 0 | BQ16: 0 | BR16: 0 | BS16: 0 | BT16: 82 | BU16: 5052 | BV16: 0 | BW16: 0 | BX16: 9 | BY16: 116 | BZ16: 0 | CA16: 0 | CB16: 0 | CC16: 0 | CD16: 0 | CE16: 0 | CF16: 0 | CG16: 0 | CH16: 0 | CI16: 0 | CJ16: 0 | CK16: 0 | CL16: 0 | CM16: 0 | CN16: 0 | CO16: 0
A17: 10 | B17: 淄博中心(综合进出)(25500071) | C17: 淄博分拨(WS25500003) | D17: 2026-04-01 09 | E17: 18134 | F17: =G17+Y17+BH17 -> 3163 | G17: 2650 | H17: 0 | I17: 0 | J17: 0 | K17: 0 | L17: 240 | M17: 1916 | N17: 13 | O17: 0 | P17: 0 | Q17: 0 | R17: 0 | S17: 0 | T17: 0 | U17: 5 | V17: 476 | W17: 0 | X17: 15424 | Y17: 453 | Z17: 14971 | AA17: 0 | AB17: 0 | AC17: 0 | AD17: 0 | AE17: 0 | AF17: 0 | AG17: 0 | AH17: 0 | AI17: 41 | AJ17: 891 | AK17: 412 | AL17: 14073 | AM17: 0 | AN17: 7 | AO17: 0 | AP17: 0 | AQ17: 0 | AR17: 0 | AS17: 0 | AT17: 0 | AU17: 0 | AV17: 0 | AW17: 0 | AX17: 0 | AY17: 0 | AZ17: 0 | BA17: 0 | BB17: 0 | BC17: 0 | BD17: 0 | BE17: 0 | BF17: 0 | BG17: 60 | BH17: 60 | BI17: 3112 | BJ17: 0 | BK17: 0 | BL17: 0 | BM17: 0 | BN17: 0 | BO17: 0 | BP17: 0 | BQ17: 0 | BR17: 0 | BS17: 0 | BT17: 60 | BU17: 3112 | BV17: 0 | BW17: 0 | BX17: 0 | BY17: 0 | BZ17: 0 | CA17: 0 | CB17: 0 | CC17: 0 | CD17: 0 | CE17: 0 | CF17: 0 | CG17: 0 | CH17: 0 | CI17: 0 | CJ17: 0 | CK17: 0 | CL17: 0 | CM17: 0 | CN17: 0 | CO17: 0
A18: 11 | B18: 淄博中心(综合进出)(25500071) | C18: 淄博分拨(WS25500003) | D18: 2026-04-01 10 | E18: 1253 | F18: =G18+Y18+BH18 -> 763 | G18: 403 | H18: 0 | I18: 0 | J18: 0 | K18: 0 | L18: 38 | M18: 340 | N18: 3 | O18: 0 | P18: 0 | Q18: 0 | R18: 0 | S18: 0 | T18: 0 | U18: 0 | V18: 22 | W18: 0 | X18: 505 | Y18: 15 | Z18: 490 | AA18: 0 | AB18: 0 | AC18: 2 | AD18: 238 | AE18: 0 | AF18: 0 | AG18: 0 | AH18: 0 | AI18: 0 | AJ18: 1 | AK18: 13 | AL18: 251 | AM18: 0 | AN18: 0 | AO18: 0 | AP18: 0 | AQ18: 0 | AR18: 0 | AS18: 0 | AT18: 0 | AU18: 0 | AV18: 0 | AW18: 0 | AX18: 0 | AY18: 0 | AZ18: 0 | BA18: 0 | BB18: 0 | BC18: 0 | BD18: 0 | BE18: 0 | BF18: 0 | BG18: 345 | BH18: 345 | BI18: 345 | BJ18: 0 | BK18: 0 | BL18: 0 | BM18: 0 | BN18: 345 | BO18: 345 | BP18: 0 | BQ18: 0 | BR18: 0 | BS18: 0 | BT18: 0 | BU18: 0 | BV18: 0 | BW18: 0 | BX18: 0 | BY18: 0 | BZ18: 0 | CA18: 0 | CB18: 0 | CC18: 0 | CD18: 0 | CE18: 0 | CF18: 0 | CG18: 0 | CH18: 0 | CI18: 0 | CJ18: 0 | CK18: 0 | CL18: 0 | CM18: 0 | CN18: 0 | CO18: 0
A19: 12 | B19: 淄博中心(综合进出)(25500071) | C19: 淄博分拨(WS25500003) | D19: 2026-04-01 11 | E19: 2067 | F19: =G19+Y19+BH19 -> 520 | G19: 489 | H19: 0 | I19: 0 | J19: 0 | K19: 0 | L19: 30 | M19: 381 | N19: 2 | O19: 0 | P19: 1 | Q19: 0 | R19: 0 | S19: 0 | T19: 0 | U19: 0 | V19: 75 | W19: 0 | X19: 1560 | Y19: 13 | Z19: 1547 | AA19: 0 | AB19: 0 | AC19: 13 | AD19: 1547 | AE19: 0 | AF19: 0 | AG19: 0 | AH19: 0 | AI19: 0 | AJ19: 0 | AK19: 0 | AL19: 0 | AM19: 0 | AN19: 0 | AO19: 0 | AP19: 0 | AQ19: 0 | AR19: 0 | AS19: 0 | AT19: 0 | AU19: 0 | AV19: 0 | AW19: 0 | AX19: 0 | AY19: 0 | AZ19: 0 | BA19: 0 | BB19: 0 | BC19: 0 | BD19: 0 | BE19: 0 | BF19: 0 | BG19: 18 | BH19: 18 | BI19: 25 | BJ19: 0 | BK19: 0 | BL19: 0 | BM19: 0 | BN19: 2 | BO19: 2 | BP19: 0 | BQ19: 0 | BR19: 0 | BS19: 0 | BT19: 15 | BU19: 22 | BV19: 0 | BW19: 0 | BX19: 0 | BY19: 0 | BZ19: 0 | CA19: 0 | CB19: 0 | CC19: 0 | CD19: 0 | CE19: 0 | CF19: 0 | CG19: 0 | CH19: 0 | CI19: 0 | CJ19: 1 | CK19: 1 | CL19: 0 | CM19: 0 | CN19: 0 | CO19: 0
... A31: 24 | B31: 淄博中心(综合进出)(25500071) | C31: 淄博分拨(WS25500003) | D31: 2026-04-01 23 | E31: 15589 | F31: =G31+Y31+BH31 -> 4959 | G31: 4682 | H31: 0 | I31: 0 | J31: 0 | K31: 0 | L31: 348 | M31: 3365 | N31: 15 | O31: 0 | P31: 0 | Q31: 0 | R31: 0 | S31: 0 | T31: 0 | U31: 10 | V31: 944 | W31: 0 | X31: 10809 | Y31: 179 | Z31: 10630 | AA31: 0 | AB31: 0 | AC31: 0 | AD31: 0 | AE31: 0 | AF31: 0 | AG31: 0 | AH31: 0 | AI31: 5 | AJ31: 163 | AK31: 174 | AL31: 10463 | AM31: 0 | AN31: 4 | AO31: 0 | AP31: 0 | AQ31: 0 | AR31: 0 | AS31: 0 | AT31: 0 | AU31: 0 | AV31: 0 | AW31: 0 | AX31: 0 | AY31: 0 | AZ31: 0 | BA31: 0 | BB31: 0 | BC31: 0 | BD31: 0 | BE31: 0 | BF31: 0 | BG31: 98 | BH31: 98 | BI31: 2559 | BJ31: 1 | BK31: 0 | BL31: 0 | BM31: 0 | BN31: 20 | BO31: 20 | BP31: 0 | BQ31: 0 | BR31: 0 | BS31: 0 | BT31: 73 | BU31: 2519 | BV31: 0 | BW31: 0 | BX31: 4 | BY31: 20 | BZ31: 0 | CA31: 0 | CB31: 0 | CC31: 0 | CD31: 0 | CE31: 0 | CF31: 0 | CG31: 0 | CH31: 0 | CI31: 0 | CJ31: 0 | CK31: 0 | CL31: 0 | CM31: 0 | CN31: 0 | CO31: 0
A32: 1 | B32: 淄博中心(综合进出)(25500071) | C32: 淄博分拨(WS25500003) | D32: 2026-04-02 00 | E32: 6,299 | F32: =G32+Y32+BH32 -> 1431 | G32: 1,345 | H32: 0 | I32: 0 | J32: 0 | K32: 0 | L32: 290 | M32: 754 | N32: 6 | O32: 0 | P32: 1 | Q32: 0 | R32: 0 | S32: 0 | T32: 0 | U32: 4 | V32: 290 | W32: 0 | X32: 4,947 | Y32: 79 | Z32: 4,868 | AA32: 0 | AB32: 0 | AC32: 0 | AD32: 0 | AE32: 0 | AF32: 0 | AG32: 0 | AH32: 0 | AI32: 6 | AJ32: 230 | AK32: 73 | AL32: 4,636 | AM32: 0 | AN32: 2 | AO32: 0 | AP32: 0 | AQ32: 0 | AR32: 0 | AS32: 0 | AT32: 0 | AU32: 0 | AV32: 0 | AW32: 0 | AX32: 0 | AY32: 0 | AZ32: 0 | BA32: 0 | BB32: 0 | BC32: 0 | BD32: 0 | BE32: 0 | BF32: 0 | BG32: 7 | BH32: 7 | BI32: 349 | BJ32: 0 | BK32: 0 | BL32: 0 | BM32: 0 | BN32: 1 | BO32: 1 | BP32: 0 | BQ32: 0 | BR32: 0 | BS32: 0 | BT32: 6 | BU32: 348 | BV32: 0 | BW32: 0 | BX32: 0 | BY32: 0 | BZ32: 0 | CA32: 0 | CB32: 0 | CC32: 0 | CD32: 0 | CE32: 0 | CF32: 0 | CG32: 0 | CH32: 0 | CI32: 0 | CJ32: 0 | CK32: 0 | CL32: 0 | CM32: 0 | CN32: 0 | CO32: 0
A33: 2 | B33: 淄博中心(综合进出)(25500071) | C33: 淄博分拨(WS25500003) | D33: 2026-04-02 01 | E33: 18,293 | F33: =G33+Y33+BH33 -> 3938 | G33: 3,665 | H33: 0 | I33: 0 | J33: 0 | K33: 0 | L33: 526 | M33: 2,474 | N33: 12 | O33: 0 | P33: 0 | Q33: 0 | R33: 0 | S33: 0 | T33: 0 | U33: 4 | V33: 649 | W33: 0 | X33: 14,575 | Y33: 220 | Z33: 14,355 | AA33: 0 | AB33: 0 | AC33: 8 | AD33: 952 | AE33: 0 | AF33: 0 | AG33: 0 | AH33: 0 | AI33: 17 | AJ33: 615 | AK33: 195 | AL33: 12,787 | AM33: 0 | AN33: 1 | AO33: 0 | AP33: 0 | AQ33: 0 | AR33: 0 | AS33: 0 | AT33: 0 | AU33: 0 | AV33: 0 | AW33: 0 | AX33: 0 | AY33: 0 | AZ33: 0 | BA33: 0 | BB33: 0 | BC33: 0 | BD33: 0 | BE33: 0 | BF33: 0 | BG33: 53 | BH33: 53 | BI33: 1,998 | BJ33: 0 | BK33: 0 | BL33: 0 | BM33: 0 | BN33: 0 | BO33: 0 | BP33: 0 | BQ33: 0 | BR33: 0 | BS33: 0 | BT33: 49 | BU33: 1,983 | BV33: 0 | BW33: 0 | BX33: 4 | BY33: 15 | BZ33: 0 | CA33: 0 | CB33: 0 | CC33: 0 | CD33: 0 | CE33: 0 | CF33: 0 | CG33: 0 | CH33: 0 | CI33: 0 | CJ33: 0 | CK33: 0 | CL33: 0 | CM33: 0 | CN33: 0 | CO33: 0
A34: 3 | B34: 淄博中心(综合进出)(25500071) | C34: 淄博分拨(WS25500003) | D34: 2026-04-02 02 | E34: 18,608 | F34: =G34+Y34+BH34 -> 4248 | G34: 3,931 | H34: 0 | I34: 0 | J34: 0 | K34: 0 | L34: 322 | M34: 2,954 | N34: 10 | O34: 0 | P34: 0 | Q34: 0 | R34: 0 | S34: 0 | T34: 0 | U34: 4 | V34: 641 | W34: 0 | X34: 14,584 | Y34: 224 | Z34: 14,360 | AA34: 0 | AB34: 0 | AC34: 0 | AD34: 0 | AE34: 0 | AF34: 0 | AG34: 0 | AH34: 0 | AI34: 16 | AJ34: 611 | AK34: 208 | AL34: 13,748 | AM34: 0 | AN34: 1 | AO34: 0 | AP34: 0 | AQ34: 0 | AR34: 0 | AS34: 0 | AT34: 0 | AU34: 0 | AV34: 0 | AW34: 0 | AX34: 0 | AY34: 0 | AZ34: 0 | BA34: 0 | BB34: 0 | BC34: 0 | BD34: 0 | BE34: 0 | BF34: 0 | BG34: 93 | BH34: 93 | BI34: 2,240 | BJ34: 0 | BK34: 0 | BL34: 0 | BM34: 0 | BN34: 52 | BO34: 52 | BP34: 0 | BQ34: 0 | BR34: 0 | BS34: 0 | BT34: 36 | BU34: 1,839 | BV34: 0 | BW34: 0 | BX34: 5 | BY34: 349 | BZ34: 0 | CA34: 0 | CB34: 0 | CC34: 0 | CD34: 0 | CE34: 0 | CF34: 0 | CG34: 0 | CH34: 0 | CI34: 0 | CJ34: 0 | CK34: 0 | CL34: 0 | CM34: 0 | CN34: 0 | CO34: 0
A35: 4 | B35: 淄博中心(综合进出)(25500071) | C35: 淄博分拨(WS25500003) | D35: 2026-04-02 03 | E35: 8,541 | F35: =G35+Y35+BH35 -> 4104 | G35: 4,033 | H35: 0 | I35: 0 | J35: 0 | K35: 0 | L35: 756 | M35: 2,883 | N35: 11 | O35: 0 | P35: 0 | Q35: 0 | R35: 0 | S35: 0 | T35: 0 | U35: 3 | V35: 380 | W35: 0 | X35: 4,503 | Y35: 66 | Z35: 4,437 | AA35: 0 | AB35: 0 | AC35: 0 | AD35: 0 | AE35: 0 | AF35: 0 | AG35: 0 | AH35: 0 | AI35: 9 | AJ35: 101 | AK35: 57 | AL35: 4,336 | AM35: 0 | AN35: 0 | AO35: 0 | AP35: 0 | AQ35: 0 | AR35: 0 | AS35: 0 | AT35: 0 | AU35: 0 | AV35: 0 | AW35: 0 | AX35: 0 | AY35: 0 | AZ35: 0 | BA35: 0 | BB35: 0 | BC35: 0 | BD35: 0 | BE35: 0 | BF35: 0 | BG35: 5 | BH35: 5 | BI35: 280 | BJ35: 0 | BK35: 0 | BL35: 0 | BM35: 0 | BN35: 1 | BO35: 1 | BP35: 0 | BQ35: 0 | BR35: 0 | BS35: 0 | BT35: 3 | BU35: 235 | BV35: 0 | BW35: 0 | BX35: 1 | BY35: 44 | BZ35: 0 | CA35: 0 | CB35: 0 | CC35: 0 | CD35: 0 | CE35: 0 | CF35: 0 | CG35: 0 | CH35: 0 | CI35: 0 | CJ35: 0 | CK35: 0 | CL35: 0 | CM35: 0 | CN35: 0 | CO35: 0
A36: 5 | B36: 淄博中心(综合进出)(25500071) | C36: 淄博分拨(WS25500003) | D36: 2026-04-02 04 | E36: 17,415 | F36: =G36+Y36+BH36 -> 4682 | G36: 4,400 | H36: 0 | I36: 0 | J36: 0 | K36: 0 | L36: 579 | M36: 3,242 | N36: 15 | O36: 3 | P36: 0 | Q36: 0 | R36: 0 | S36: 0 | T36: 0 | U36: 6 | V36: 555 | W36: 0 | X36: 12,963 | Y36: 230 | Z36: 12,733 | AA36: 0 | AB36: 0 | AC36: 12 | AD36: 1,428 | AE36: 0 | AF36: 0 | AG36: 0 | AH36: 0 | AI36: 103 | AJ36: 3,607 | AK36: 115 | AL36: 7,693 | AM36: 0 | AN36: 5 | AO36: 0 | AP36: 0 | AQ36: 0 | AR36: 0 | AS36: 0 | AT36: 0 | AU36: 0 | AV36: 0 | AW36: 0 | AX36: 0 | AY36: 0 | AZ36: 0 | BA36: 0 | BB36: 0 | BC36: 0 | BD36: 0 | BE36: 0 | BF36: 0 | BG36: 52 | BH36: 52 | BI36: 2,969 | BJ36: 0 | BK36: 0 | BL36: 0 | BM36: 0 | BN36: 2 | BO36: 2 | BP36: 0 | BQ36: 0 | BR36: 2 | BS36: 2 | BT36: 40 | BU36: 2,798 | BV36: 0 | BW36: 0 | BX36: 8 | BY36: 167 | BZ36: 0 | CA36: 0 | CB36: 0 | CC36: 0 | CD36: 0 | CE36: 0 | CF36: 0 | CG36: 0 | CH36: 0 | CI36: 0 | CJ36: 0 | CK36: 0 | CL36: 0 | CM36: 0 | CN36: 0 | CO36: 0
A37: 6 | B37: 淄博中心(综合进出)(25500071) | C37: 淄博分拨(WS25500003) | D37: 2026-04-02 05 | E37: 14,867 | F37: =G37+Y37+BH37 -> 2297 | G37: 1,749 | H37: 0 | I37: 0 | J37: 0 | K37: 0 | L37: 442 | M37: 1,141 | N37: 4 | O37: 3 | P37: 2 | Q37: 0 | R37: 0 | S37: 0 | T37: 0 | U37: 2 | V37: 155 | W37: 0 | X37: 12,996 | Y37: 426 | Z37: 12,570 | AA37: 0 | AB37: 0 | AC37: 2 | AD37: 238 | AE37: 0 | AF37: 0 | AG37: 0 | AH37: 0 | AI37: 171 | AJ37: 2,194 | AK37: 253 | AL37: 10,127 | AM37: 0 | AN37: 11 | AO37: 0 | AP37: 0 | AQ37: 0 | AR37: 0 | AS37: 0 | AT37: 0 | AU37: 0 | AV37: 0 | AW37: 0 | AX37: 0 | AY37: 0 | AZ37: 0 | BA37: 0 | BB37: 0 | BC37: 0 | BD37: 0 | BE37: 0 | BF37: 0 | BG37: 122 | BH37: 122 | BI37: 371 | BJ37: 0 | BK37: 0 | BL37: 0 | BM37: 0 | BN37: 118 | BO37: 127 | BP37: 0 | BQ37: 0 | BR37: 0 | BS37: 0 | BT37: 4 | BU37: 244 | BV37: 0 | BW37: 0 | BX37: 0 | BY37: 0 | BZ37: 0 | CA37: 0 | CB37: 0 | CC37: 0 | CD37: 0 | CE37: 0 | CF37: 0 | CG37: 0 | CH37: 0 | CI37: 0 | CJ37: 0 | CK37: 0 | CL37: 0 | CM37: 0 | CN37: 0 | CO37: 0
A38: 7 | B38: 淄博中心(综合进出)(25500071) | C38: 淄博分拨(WS25500003) | D38: 2026-04-02 06 | E38: 964 | F38: =G38+Y38+BH38 -> 964 | G38: 964 | H38: 0 | I38: 0 | J38: 0 | K38: 0 | L38: 282 | M38: 360 | N38: 2 | O38: 0 | P38: 0 | Q38: 0 | R38: 0 | S38: 0 | T38: 0 | U38: 1 | V38: 319 | W38: 0 | X38: 0 | Y38: 0 | Z38: 0 | AA38: 0 | AB38: 0 | AC38: 0 | AD38: 0 | AE38: 0 | AF38: 0 | AG38: 0 | AH38: 0 | AI38: 0 | AJ38: 0 | AK38: 0 | AL38: 0 | AM38: 0 | AN38: 0 | AO38: 0 | AP38: 0 | AQ38: 0 | AR38: 0 | AS38: 0 | AT38: 0 | AU38: 0 | AV38: 0 | AW38: 0 | AX38: 0 | AY38: 0 | AZ38: 0 | BA38: 0 | BB38: 0 | BC38: 0 | BD38: 0 | BE38: 0 | BF38: 0 | BG38: 0 | BH38: 0 | BI38: 0 | BJ38: 0 | BK38: 0 | BL38: 0 | BM38: 0 | BN38: 0 | BO38: 0 | BP38: 0 | BQ38: 0 | BR38: 0 | BS38: 0 | BT38: 0 | BU38: 0 | BV38: 0 | BW38: 0 | BX38: 0 | BY38: 0 | BZ38: 0 | CA38: 0 | CB38: 0 | CC38: 0 | CD38: 0 | CE38: 0 | CF38: 0 | CG38: 0 | CH38: 0 | CI38: 0 | CJ38: 0 | CK38: 0 | CL38: 0 | CM38: 0 | CN38: 0 | CO38: 0
A39: 8 | B39: 淄博中心(综合进出)(25500071) | C39: 淄博分拨(WS25500003) | D39: 2026-04-02 07 | E39: 3,316 | F39: =G39+Y39+BH39 -> 3316 | G39: 3,259 | H39: 0 | I39: 0 | J39: 0 | K39: 0 | L39: 153 | M39: 2,344 | N39: 20 | O39: 0 | P39: 0 | Q39: 0 | R39: 0 | S39: 0 | T39: 0 | U39: 6 | V39: 736 | W39: 0 | X39: 0 | Y39: 0 | Z39: 0 | AA39: 0 | AB39: 0 | AC39: 0 | AD39: 0 | AE39: 0 | AF39: 0 | AG39: 0 | AH39: 0 | AI39: 0 | AJ39: 0 | AK39: 0 | AL39: 0 | AM39: 0 | AN39: 0 | AO39: 0 | AP39: 0 | AQ39: 0 | AR39: 0 | AS39: 0 | AT39: 0 | AU39: 0 | AV39: 0 | AW39: 0 | AX39: 0 | AY39: 0 | AZ39: 0 | BA39: 0 | BB39: 0 | BC39: 0 | BD39: 0 | BE39: 0 | BF39: 0 | BG39: 57 | BH39: 57 | BI39: 3,216 | BJ39: 0 | BK39: 0 | BL39: 0 | BM39: 0 | BN39: 7 | BO39: 7 | BP39: 0 | BQ39: 0 | BR39: 0 | BS39: 0 | BT39: 50 | BU39: 3,209 | BV39: 0 | BW39: 0 | BX39: 0 | BY39: 0 | BZ39: 0 | CA39: 0 | CB39: 0 | CC39: 0 | CD39: 0 | CE39: 0 | CF39: 0 | CG39: 0 | CH39: 0 | CI39: 0 | CJ39: 0 | CK39: 0 | CL39: 0 | CM39: 0 | CN39: 0 | CO39: 0
A40: 9 | B40: 淄博中心(综合进出)(25500071) | C40: 淄博分拨(WS25500003) | D40: 2026-04-02 08 | E40: 12,069 | F40: =G40+Y40+BH40 -> 2330 | G40: 2,081 | H40: 0 | I40: 0 | J40: 0 | K40: 0 | L40: 154 | M40: 1,573 | N40: 18 | O40: 0 | P40: 0 | Q40: 0 | R40: 0 | S40: 0 | T40: 0 | U40: 3 | V40: 333 | W40: 0 | X40: 9,951 | Y40: 212 | Z40: 9,739 | AA40: 0 | AB40: 0 | AC40: 0 | AD40: 0 | AE40: 0 | AF40: 0 | AG40: 0 | AH40: 0 | AI40: 7 | AJ40: 214 | AK40: 205 | AL40: 9,519 | AM40: 0 | AN40: 6 | AO40: 0 | AP40: 0 | AQ40: 0 | AR40: 0 | AS40: 0 | AT40: 0 | AU40: 0 | AV40: 0 | AW40: 0 | AX40: 0 | AY40: 0 | AZ40: 0 | BA40: 0 | BB40: 0 | BC40: 0 | BD40: 0 | BE40: 0 | BF40: 0 | BG40: 37 | BH40: 37 | BI40: 1,046 | BJ40: 8 | BK40: 1 | BL40: 0 | BM40: 0 | BN40: 1 | BO40: 1 | BP40: 0 | BQ40: 0 | BR40: 0 | BS40: 0 | BT40: 20 | BU40: 756 | BV40: 0 | BW40: 0 | BX40: 8 | BY40: 288 | BZ40: 0 | CA40: 0 | CB40: 0 | CC40: 0 | CD40: 0 | CE40: 0 | CF40: 0 | CG40: 0 | CH40: 0 | CI40: 0 | CJ40: 0 | CK40: 0 | CL40: 0 | CM40: 0 | CN40: 0 | CO40: 0
A41: 10 | B41: 淄博中心(综合进出)(25500071) | C41: 淄博分拨(WS25500003) | D41: 2026-04-02 09 | E41: 2,452 | F41: =G41+Y41+BH41 -> 1307 | G41: 1,246 | H41: 0 | I41: 0 | J41: 0 | K41: 0 | L41: 92 | M41: 904 | N41: 3 | O41: 0 | P41: 0 | Q41: 0 | R41: 0 | S41: 0 | T41: 0 | U41: 3 | V41: 244 | W41: 0 | X41: 1,171 | Y41: 26 | Z41: 1,145 | AA41: 0 | AB41: 0 | AC41: 0 | AD41: 0 | AE41: 0 | AF41: 0 | AG41: 0 | AH41: 0 | AI41: 2 | AJ41: 55 | AK41: 24 | AL41: 1,089 | AM41: 0 | AN41: 1 | AO41: 0 | AP41: 0 | AQ41: 0 | AR41: 0 | AS41: 0 | AT41: 0 | AU41: 0 | AV41: 0 | AW41: 0 | AX41: 0 | AY41: 0 | AZ41: 0 | BA41: 0 | BB41: 0 | BC41: 0 | BD41: 0 | BE41: 0 | BF41: 0 | BG41: 35 | BH41: 35 | BI41: 352 | BJ41: 0 | BK41: 0 | BL41: 0 | BM41: 0 | BN41: 26 | BO41: 26 | BP41: 0 | BQ41: 0 | BR41: 0 | BS41: 0 | BT41: 9 | BU41: 326 | BV41: 0 | BW41: 0 | BX41: 0 | BY41: 0 | BZ41: 0 | CA41: 0 | CB41: 0 | CC41: 0 | CD41: 0 | CE41: 0 | CF41: 0 | CG41: 0 | CH41: 0 | CI41: 0 | CJ41: 0 | CK41: 0 | CL41: 0 | CM41: 0 | CN41: 0 | CO41: 0
A42: 11 | B42: 淄博中心(综合进出)(25500071) | C42: 淄博分拨(WS25500003) | D42: 2026-04-02 10 | E42: 11,521 | F42: =G42+Y42+BH42 -> 2124 | G42: 1,462 | H42: 0 | I42: 0 | J42: 0 | K42: 0 | L42: 96 | M42: 1,136 | N42: 1 | O42: 0 | P42: 0 | Q42: 0 | R42: 0 | S42: 0 | T42: 0 | U42: 4 | V42: 225 | W42: 0 | X42: 9,721 | Y42: 324 | Z42: 9,397 | AA42: 0 | AB42: 0 | AC42: 0 | AD42: 0 | AE42: 0 | AF42: 0 | AG42: 0 | AH42: 0 | AI42: 36 | AJ42: 663 | AK42: 288 | AL42: 8,722 | AM42: 0 | AN42: 12 | AO42: 0 | AP42: 0 | AQ42: 0 | AR42: 0 | AS42: 0 | AT42: 0 | AU42: 0 | AV42: 0 | AW42: 0 | AX42: 0 | AY42: 0 | AZ42: 0 | BA42: 0 | BB42: 0 | BC42: 0 | BD42: 0 | BE42: 0 | BF42: 0 | BG42: 338 | BH42: 338 | BI42: 1,815 | BJ42: 0 | BK42: 0 | BL42: 0 | BM42: 0 | BN42: 310 | BO42: 310 | BP42: 0 | BQ42: 0 | BR42: 0 | BS42: 0 | BT42: 27 | BU42: 1,504 | BV42: 0 | BW42: 0 | BX42: 0 | BY42: 0 | BZ42: 0 | CA42: 0 | CB42: 0 | CC42: 0 | CD42: 0 | CE42: 0 | CF42: 0 | CG42: 0 | CH42: 0 | CI42: 0 | CJ42: 1 | CK42: 1 | CL42: 0 | CM42: 0 | CN42: 0 | CO42: 0
A43: 12 | B43: 淄博中心(综合进出)(25500071) | C43: 淄博分拨(WS25500003) | D43: 2026-04-02 11 | E43: 5,647 | F43: =G43+Y43+BH43 -> 3981 | G43: 3,951 | H43: 0 | I43: 0 | J43: 0 | K43: 0 | L43: 42 | M43: 3,702 | N43: 0 | O43: 0 | P43: 0 | Q43: 0 | R43: 0 | S43: 0 | T43: 0 | U43: 0 | V43: 207 | W43: 0 | X43: 1,680 | Y43: 14 | Z43: 1,666 | AA43: 0 | AB43: 0 | AC43: 14 | AD43: 1,666 | AE43: 0 | AF43: 0 | AG43: 0 | AH43: 0 | AI43: 0 | AJ43: 0 | AK43: 0 | AL43: 0 | AM43: 0 | AN43: 0 | AO43: 0 | AP43: 0 | AQ43: 0 | AR43: 0 | AS43: 0 | AT43: 0 | AU43: 0 | AV43: 0 | AW43: 0 | AX43: 0 | AY43: 0 | AZ43: 0 | BA43: 0 | BB43: 0 | BC43: 0 | BD43: 0 | BE43: 0 | BF43: 0 | BG43: 16 | BH43: 16 | BI43: 16 | BJ43: 0 | BK43: 0 | BL43: 0 | BM43: 0 | BN43: 0 | BO43: 0 | BP43: 0 | BQ43: 0 | BR43: 0 | BS43: 0 | BT43: 16 | BU43: 16 | BV43: 0 | BW43: 0 | BX43: 0 | BY43: 0 | BZ43: 0 | CA43: 0 | CB43: 0 | CC43: 0 | CD43: 0 | CE43: 0 | CF43: 0 | CG43: 0 | CH43: 0 | CI43: 0 | CJ43: 0 | CK43: 0 | CL43: 0 | CM43: 0 | CN43: 0 | CO43: 0
... A223: 48 | B223: 淄博中心(综合进出)(25500071) | C223: 淄博分拨(WS25500003) | D223: 2026-04-09 23 | E223: 7,080 | F223: =G223+Y223+BH223 -> 3895 | G223: 3,679 | H223: 0 | I223: 0 | J223: 0 | K223: 0 | L223: 329 | M223: 2,717 | N223: 16 | O223: 0 | P223: 2 | Q223: 0 | R223: 0 | S223: 0 | T223: 0 | U223: 4 | V223: 611 | W223: 0 | X223: 3,253 | Y223: 68 | Z223: 3,185 | AA223: 0 | AB223: 0 | AC223: 0 | AD223: 0 | AE223: 0 | AF223: 0 | AG223: 0 | AH223: 0 | AI223: 2 | AJ223: 2 | AK223: 66 | AL223: 3,182 | AM223: 0 | AN223: 1 | AO223: 0 | AP223: 0 | AQ223: 0 | AR223: 0 | AS223: 0 | AT223: 0 | AU223: 0 | AV223: 0 | AW223: 0 | AX223: 0 | AY223: 0 | AZ223: 0 | BA223: 0 | BB223: 0 | BC223: 0 | BD223: 0 | BE223: 0 | BF223: 0 | BG223: 148 | BH223: 148 | BI223: 3,344 | BJ223: 2 | BK223: 1 | BL223: 0 | BM223: 0 | BN223: 36 | BO223: 36 | BP223: 0 | BQ223: 0 | BR223: 0 | BS223: 0 | BT223: 106 | BU223: 3,290 | BV223: 0 | BW223: 0 | BX223: 4 | BY223: 17 | BZ223: 0 | CA223: 0 | CB223: 0 | CC223: 0 | CD223: 0 | CE223: 0 | CF223: 0 | CG223: 0 | CH223: 0 | CI223: 0 | CJ223: 0 | CK223: 0 | CL223: 0 | CM223: 0 | CN223: 0 | CO223: 0

Sheet 集包数据
A1: 序号 | B1: 省份 | C1: 地市 | D1: 机构 | E1: 车间 | F1: 统计时间 | G1: 处理量合计 | H1: 上机量-上机总量 | I1: 上机量-散件外走数 | J1: 上机量-分拣封发-总包数 | K1: 上机量-分拣封发-内件数 | L1: 上机量-总包经转-总包数 | M1: 上机量-总包经转-内件数 | N1: 自动化分拣率 | O1: 未上机量 | P1: 未上机量-散件外走数 | Q1: 未上机量-分拣封发-总包数 | R1: 未上机量-分拣封发-内件数 | S1: 未上机量-总包经转-总包数 | T1: 未上机量-总包经转-内件数
A2: 1 | B2: 山东省 | C2: 淄博市 | D2: 淄博中心(综合进出)(25500071) | E2: 淄博分拨(WS25500003) | F2: 2026-04-01 00 | G2: 7987 | H2: 6568 | I2: 188 | J2: 0 | K2: 6380 | L2: 0 | M2: 0 | N2: 82.23% | O2: 1419 | P2: 1251 | Q2: 120 | R2: 7 | S2: 41 | T2: 894
A3: 2 | B3: 山东省 | C3: 淄博市 | D3: 淄博中心(综合进出)(25500071) | E3: 淄博分拨(WS25500003) | F3: 2026-04-01 01 | G3: 16863 | H3: 12491 | I3: 228 | J3: 0 | K3: 12263 | L3: 0 | M3: 0 | N3: 74.07% | O3: 4372 | P3: 4120 | Q3: 197 | R3: 0 | S3: 55 | T3: 2431
A4: 3 | B4: 山东省 | C4: 淄博市 | D4: 淄博中心(综合进出)(25500071) | E4: 淄博分拨(WS25500003) | F4: 2026-04-01 02 | G4: 18106 | H4: 14519 | I4: 100 | J4: 0 | K4: 14419 | L4: 0 | M4: 0 | N4: 80.19% | O4: 3587 | P4: 3312 | Q4: 224 | R4: 0 | S4: 51 | T4: 1299
A5: 4 | B5: 山东省 | C5: 淄博市 | D5: 淄博中心(综合进出)(25500071) | E5: 淄博分拨(WS25500003) | F5: 2026-04-01 03 | G5: 17361 | H5: 12593 | I5: 76 | J5: 0 | K5: 12517 | L5: 0 | M5: 0 | N5: 72.54% | O5: 4768 | P5: 4567 | Q5: 168 | R5: 7 | S5: 26 | T5: 926
A6: 5 | B6: 山东省 | C6: 淄博市 | D6: 淄博中心(综合进出)(25500071) | E6: 淄博分拨(WS25500003) | F6: 2026-04-01 04 | G6: 20492 | H6: 13297 | I6: 50 | J6: 0 | K6: 13247 | L6: 0 | M6: 0 | N6: 64.89% | O6: 7195 | P6: 4944 | Q6: 252 | R6: 1931 | S6: 68 | T6: 4097
A7: 6 | B7: 山东省 | C7: 淄博市 | D7: 淄博中心(综合进出)(25500071) | E7: 淄博分拨(WS25500003) | F7: 2026-04-01 05 | G7: 12472 | H7: 8794 | I7: 205 | J7: 0 | K7: 8589 | L7: 0 | M7: 0 | N7: 70.51% | O7: 3678 | P7: 2307 | Q7: 427 | R7: 942 | S7: 2 | T7: 89
A8: 7 | B8: 山东省 | C8: 淄博市 | D8: 淄博中心(综合进出)(25500071) | E8: 淄博分拨(WS25500003) | F8: 2026-04-01 06 | G8: 1222 | H8: 113 | I8: 113 | J8: 0 | K8: 0 | L8: 0 | M8: 0 | N8: 9.25% | O8: 1109 | P8: 1109 | Q8: 0 | R8: 0 | S8: 0 | T8: 0
A9: 8 | B9: 山东省 | C9: 淄博市 | D9: 淄博中心(综合进出)(25500071) | E9: 淄博分拨(WS25500003) | F9: 2026-04-01 07 | G9: 1518 | H9: 246 | I9: 246 | J9: 0 | K9: 0 | L9: 0 | M9: 0 | N9: 16.21% | O9: 1272 | P9: 1272 | Q9: 0 | R9: 0 | S9: 0 | T9: 0
A10: 9 | B10: 山东省 | C10: 淄博市 | D10: 淄博中心(综合进出)(25500071) | E10: 淄博分拨(WS25500003) | F10: 2026-04-01 08 | G10: 7379 | H10: 4179 | I10: 25 | J10: 0 | K10: 4154 | L10: 0 | M10: 0 | N10: 56.63% | O10: 3200 | P10: 3021 | Q10: 97 | R10: 0 | S10: 82 | T10: 5052
A11: 10 | B11: 山东省 | C11: 淄博市 | D11: 淄博中心(综合进出)(25500071) | E11: 淄博分拨(WS25500003) | F11: 2026-04-01 09 | G11: 18099 | H11: 14973 | I11: 38 | J11: 0 | K11: 14935 | L11: 0 | M11: 0 | N11: 82.73% | O11: 3126 | P11: 2611 | Q11: 453 | R11: 2 | S11: 60 | T11: 3112
A12: 11 | B12: 山东省 | C12: 淄博市 | D12: 淄博中心(综合进出)(25500071) | E12: 淄博分拨(WS25500003) | F12: 2026-04-01 10 | G12: 661 | H12: 325 | I12: 74 | J12: 0 | K12: 251 | L12: 0 | M12: 0 | N12: 49.17% | O12: 336 | P12: 323 | Q12: 13 | R12: 0 | S12: 0 | T12: 0
A13: 12 | B13: 山东省 | C13: 淄博市 | D13: 淄博中心(综合进出)(25500071) | E13: 淄博分拨(WS25500003) | F13: 2026-04-01 11 | G13: 491 | H13: 48 | I13: 48 | J13: 0 | K13: 0 | L13: 0 | M13: 0 | N13: 9.78% | O13: 443 | P13: 427 | Q13: 0 | R13: 0 | S13: 16 | T13: 23
... A217: 192 | B217: 山东省 | C217: 淄博市 | D217: 淄博中心(综合进出)(25500071) | E217: 淄博分拨(WS25500003) | F217: 2026-04-09 23 | G217: 6990 | H217: 3283 | I217: 107 | J217: 0 | K217: 3176 | L217: 0 | M217: 0 | N217: 46.97% | O217: 3707 | P217: 3532 | Q217: 68 | R217: 1 | S217: 106 | T217: 3290

Sheet 1
A1: 日期 | B1: 时段 | C1: 班次 | D1: 频次 | E1: 卸车量 | F1: 环线量 | G1: 集包量 | H1: 管理 | I1: 卸车网格 | U1: 集包网格 | AF1: 北环网格 | AP1: 南环网格 | BA1: 特快 | BB1: 其它 | BH1: 合计 | BI1: 27万
I2: 工作内容 | J2: 关注点 | K2: 小计 | L2: 网格长 | M2: 卸车 | N2: 翻面 | O2: 勾核 | P2: 粗分 | Q2: 疏堵 | R2: 拆包、整理 | S2: 问题邮件 | T2: 复用 | U2: 工作内容 | V2: 关注点 | W2: 小计 | X2: 网格长 | Y2: 供件（均件、疏堵） | Z2: 齐格/封包 | AA2: 处理问题件、预支袋牌 | AB2: 人工集包 | AC2: 人工上包、翻包、异形件盘剥、拆包 | AD2: 复用 | AE2: 工作内容 | AF2: 关注点 | AG2: 小计 | AH2: 网格长 | AI2: 分拣 | AJ2: 扫描 | AK2: 码货 | AL2: 封发车 | AM2: 回流 | AN2: 问题件处理 | AO2: 复用 | AP2: 工作内容 | AQ2: 关注点 | AR2: 小计 | AS2: 网格长 | AT2: 分拣 | AU2: 扫描 | AV2: 码货 | AW2: 封发车 | AX2: 回流 | AY2: 问题件处理 | AZ2: 复用 | BB2: 接挂信、报刊 | BC2: 小计 | BD2: 发验 | BE2: 客服 | BF2: 西场 | BG2: 门卫值班
A3: 46113 | B3: 0000-0100 | C3: 夜班 | D3: 进口 | E3: =SUMIFS(卸车数据!$J$6:$J$1048576,卸车数据!$R$6:$R$1048576,">="&A3+TIME(0,0,0),卸车数据!$R$6:$R$1048576,"<"&A3+TIME(1,0,0)) -> 16991 | F3: 1608 | G3: 6568 | H3: 1 | I3: 0050 济临4卸车，清理落地 破损发验 | K3: =SUM(L3:T3) -> 17 | L3: 1 | M3: 5 | N3: 2 | O3: 2 | P3: 4 | Q3: 1 | R3: 2 | W3: =SUM(X3:AD3) -> 25 | X3: 1 | Y3: 12 | Z3: 9 | AA3: 1 | AC3: 2 | AE3: 0030北京一干发车 0010广州一干发车 | AG3: =SUM(AH3:AO3) -> 26 | AH3: 1 | AI3: 6 | AJ3: 6 | AK3: 11 | AM3: 1 | AN3: 1 | AR3: =SUM(AS3:AZ3) -> 19 | AS3: 1 | AU3: 11 | AV3: 5 | AX3: 1 | AY3: 1 | BA3: 4 | BC3: =BD3+BE3 -> 3 | BD3: 3 | BF3: 1 | BH3: =BC3+BA3+AR3+AG3+W3+K3+H3 -> 95
A4: 46113 | B4: 0100-0200 | C4: 夜班 | D4: 进口 | E4: =SUMIFS(卸车数据!$J$6:$J$1048576,卸车数据!$R$6:$R$1048576,">="&A4+TIME(1,0,0),卸车数据!$R$6:$R$1048576,"<"&A4+TIME(2,0,0)) -> 3241 | F4: 4607 | G4: 12491 | H4: 1 | K4: =SUM(L4:T4) -> 17 | L4: 1 | M4: 5 | N4: 2 | O4: 2 | P4: 4 | Q4: 1 | R4: 2 | W4: =SUM(X4:AD4) -> 25 | X4: 1 | Y4: 12 | Z4: 9 | AA4: 1 | AC4: 2 | AE4: 0200济加三收尾车发车 | AG4: =SUM(AH4:AO4) -> 26 | AH4: 1 | AI4: 6 | AJ4: 6 | AK4: 11 | AM4: 1 | AN4: 1 | AR4: =SUM(AS4:AZ4) -> 19 | AS4: 1 | AU4: 11 | AV4: 5 | AX4: 1 | AY4: 1 | BA4: 4 | BC4: =BD4+BE4 -> 3 | BD4: 3 | BF4: 1 | BH4: =BC4+BA4+AR4+AG4+W4+K4+H4 -> 95
A5: 46113 | B5: 0200-0300 | C5: 夜班 | D5: 进口 | E5: =SUMIFS(卸车数据!$J$6:$J$1048576,卸车数据!$R$6:$R$1048576,">="&A5+TIME(2,0,0),卸车数据!$R$6:$R$1048576,"<"&A5+TIME(3,0,0)) -> 0 | F5: 3701 | G5: 14519 | H5: 1 | I5: 济加1进局卸车 | K5: =SUM(L5:T5) -> 17 | L5: 1 | M5: 5 | N5: 2 | O5: 2 | P5: 4 | Q5: 1 | R5: 2 | U5: 0230分拣进行停机班清，同时处理退换件、轻薄异型件 | W5: =SUM(X5:AD5) -> 25 | X5: 1 | Y5: 12 | Z5: 9 | AA5: 1 | AC5: 2 | AG5: =SUM(AH5:AO5) -> 26 | AH5: 1 | AI5: 6 | AJ5: 6 | AK5: 11 | AM5: 1 | AN5: 1 | AR5: =SUM(AS5:AZ5) -> 19 | AS5: 1 | AU5: 11 | AV5: 5 | AX5: 1 | AY5: 1 | BA5: 4 | BC5: =BD5+BE5 -> 3 | BD5: 3 | BF5: 1 | BH5: =BC5+BA5+AR5+AG5+W5+K5+H5 -> 95
A6: 46113 | B6: 0300-0400 | C6: 夜班 | D6: 进口 | E6: =SUMIFS(卸车数据!$J$6:$J$1048576,卸车数据!$R$6:$R$1048576,">="&A6+TIME(3,0,0),卸车数据!$R$6:$R$1048576,"<"&A6+TIME(4,0,0)) -> 8615 | F6: 4838 | G6: 12593 | H6: 1 | I6: 0315潍坊特快 0345济南特快 文件 特安 贵品交接 | K6: =SUM(L6:T6) -> 17 | L6: 1 | M6: 5 | N6: 2 | O6: 2 | P6: 4 | Q6: 1 | R6: 2 | U6: 0320优先处理博山、高清、沂源赶0530发车 | V6: 7人复用南北环 | W6: =SUM(X6:AD6) -> 18 | X6: 1 | Y6: 5 | Z6: 9 | AA6: 1 | AC6: 2 | AG6: =SUM(AH6:AO6) -> 30 | AH6: 1 | AI6: 6 | AJ6: 6 | AK6: 11 | AM6: 1 | AN6: 1 | AO6: 4 | AP6: 潍坊航站&济南航站 | AQ6: 0330视进口的货量进行清人； | AR6: =SUM(AS6:AZ6) -> 22 | AS6: 1 | AU6: 11 | AV6: 5 | AX6: 1 | AY6: 1 | AZ6: 3 | BA6: 4 | BC6: =BD6+BE6 -> 3 | BD6: 3 | BF6: 1 | BH6: =BC6+BA6+AR6+AG6+W6+K6+H6 -> 95 | BI6: 依据到件情况清人
A7: 46113 | B7: 0400-0500 | C7: 夜班 | D7: 进口 | E7: =SUMIFS(卸车数据!$J$6:$J$1048576,卸车数据!$R$6:$R$1048576,">="&A7+TIME(4,0,0),卸车数据!$R$6:$R$1048576,"<"&A7+TIME(5,0,0)) -> 26 | F7: 5326 | G7: 13297 | H7: 1 | I7: 班清，整理 | K7: =SUM(L7:T7) -> 17 | L7: 1 | M7: 5 | N7: 2 | O7: 2 | P7: 4 | Q7: 1 | R7: 2 | W7: =SUM(X7:AD7) -> 25 | X7: 1 | Y7: 12 | Z7: 9 | AA7: 1 | AC7: 2 | AE7: 0440 平服挂信扫描 0500文件交接 | AG7: =SUM(AH7:AO7) -> 26 | AH7: 1 | AI7: 6 | AJ7: 6 | AK7: 11 | AM7: 1 | AN7: 1 | AR7: =SUM(AS7:AZ7) -> 19 | AS7: 1 | AU7: 11 | AV7: 5 | AX7: 1 | AY7: 1 | BA7: 4 | BC7: =BD7+BE7 -> 3 | BD7: 3 | BF7: 1 | BH7: =BC7+BA7+AR7+AG7+W7+K7+H7 -> 95
A8: 46113 | B8: 0500-0600 | C8: 夜班 | D8: 进口 | E8: =SUMIFS(卸车数据!$J$6:$J$1048576,卸车数据!$R$6:$R$1048576,">="&A8+TIME(5,0,0),卸车数据!$R$6:$R$1048576,"<"&A8+TIME(6,0,0)) -> 225 | F8: 3064 | G8: 8794 | H8: 1 | I8: 0520济加2卸车 | K8: =SUM(L8:T8) -> 17 | L8: 1 | M8: 5 | N8: 2 | O8: 2 | P8: 4 | Q8: 1 | R8: 2 | W8: =SUM(X8:AD8) -> 25 | X8: 1 | Y8: 12 | Z8: 9 | AA8: 1 | AC8: 2 | AE8: 0510报纸靠车尾部装车、报纸车间袋牌 0530博山、沂源、高青一频 其余流向关注发出时间点，提前10分钟完成封车动作 | AG8: =SUM(AH8:AO8) -> 26 | AH8: 1 | AI8: 6 | AJ8: 6 | AK8: 11 | AM8: 1 | AN8: 1 | AR8: =SUM(AS8:AZ8) -> 19 | AS8: 1 | AU8: 11 | AV8: 5 | AX8: 1 | AY8: 1 | BA8: 4 | BC8: =BD8+BE8 -> 3 | BD8: 3 | BF8: 1 | BH8: =BC8+BA8+AR8+AG8+W8+K8+H8 -> 95
A9: 46113 | B9: 0600-0700 | C9: 夜班 | D9: 进口 | E9: =SUMIFS(卸车数据!$J$6:$J$1048576,卸车数据!$R$6:$R$1048576,">="&A9+TIME(6,0,0),卸车数据!$R$6:$R$1048576,"<"&A9+TIME(7,0,0)) -> 794 | F9: 1229 | G9: 113 | H9: 1 | I9: 0610卸车 班清 | K9: =SUM(L9:T9) -> 17 | L9: 1 | M9: 5 | N9: 2 | O9: 2 | P9: 4 | Q9: 1 | R9: 2 | W9: =SUM(X9:AD9) -> 25 | X9: 1 | Y9: 12 | Z9: 9 | AA9: 1 | AC9: 2 | AG9: =SUM(AH9:AO9) -> 26 | AH9: 1 | AI9: 6 | AJ9: 6 | AK9: 11 | AM9: 1 | AN9: 1 | AR9: =SUM(AS9:AZ9) -> 19 | AS9: 1 | AU9: 11 | AV9: 5 | AX9: 1 | AY9: 1 | BA9: 4 | BC9: =BD9+BE9 -> 3 | BD9: 3 | BF9: 1 | BH9: =BC9+BA9+AR9+AG9+W9+K9+H9 -> 95
A10: 46113 | B10: 0700-0800 | C10: 白班 | D10: 进口 | E10: =SUMIFS(卸车数据!$J$6:$J$1048576,卸车数据!$R$6:$R$1048576,">="&A10+TIME(7,0,0),卸车数据!$R$6:$R$1048576,"<"&A10+TIME(8,0,0)) -> 1064 | F10: 1528 | G10: 246 | H10: 1 | I10: 进口赶二频进局车辆 | J10: 外派5人，协助环线装车 场地卫生打扫 | K10: =SUM(L10:T10) -> 8 | L10: 1 | M10: 2 | N10: 0 | O10: 1 | P10: 2 | R10: 1 | S10: 1 | U10: 处理进口博山、淄川、周村二频快件 | W10: =SUM(X10:AD10) -> 21 | X10: 1 | Y10: 12 | Z10: 7 | AC10: 1 | AE10: 开早会 0740装车周村、淄川2频装车 | AF10: 关注扫描人员是否使用PDA 邮路是否正确 龙门架顶扫是否开启 强调码货规则，禁止抛甩 | AG10: =SUM(AH10:AO10) -> 17 | AH10: 1 | AI10: 1 | AJ10: 7 | AK10: 3 | AM10: 1 | AN10: 1 | AO10: 3 | AP10: 早会 2频扫描装车 | AR10: =SUM(AS10:AZ10) -> 16 | AS10: 1 | AT10: 1 | AU10: 7 | AV10: 3 | AW10: 1 | AX10: 1 | AZ10: 2 | BC10: =BD10+BE10 -> 4 | BD10: 2 | BE10: 2 | BF10: 1 | BH10: =BC10+BA10+AR10+AG10+W10+K10+H10 -> 67 | BI10: 基准值 | BJ10: 65
A11: 46113 | B11: 0800-0900 | C11: 白班 | D11: 进口 | E11: =SUMIFS(卸车数据!$J$6:$J$1048576,卸车数据!$R$6:$R$1048576,">="&A11+TIME(8,0,0),卸车数据!$R$6:$R$1048576,"<"&A11+TIME(9,0,0)) -> 5592 | F11: 3243 | G11: 4179 | H11: 1 | I11: 进口赶二频进局车辆 | J11: 外派5人，协助环线装车 场地卫生打扫 | K11: =SUM(L11:T11) -> 8 | L11: 1 | M11: 2 | N11: 0 | O11: 1 | P11: 2 | R11: 1 | S11: 1 | U11: 处理进口博山、淄川、周村二频快件 清退空袋、人工分拣轻薄件 | W11: =SUM(X11:AD11) -> 21 | X11: 1 | Y11: 12 | Z11: 7 | AC11: 1 | AE11: 0830博山2频封车 0850淄川、周村2频封车 | AG11: =SUM(AH11:AO11) -> 17 | AH11: 1 | AI11: 1 | AJ11: 7 | AK11: 3 | AM11: 1 | AN11: 1 | AO11: 3 | AP11: 2频扫描装车 | AQ11: 关注华光、石桥、光学姐、直投中心的错分白给 | AR11: =SUM(AS11:AZ11) -> 16 | AS11: 1 | AT11: 1 | AU11: 7 | AV11: 3 | AW11: 1 | AX11: 1 | AZ11: 2 | BC11: =BD11+BE11 -> 4 | BD11: 2 | BE11: 2 | BF11: 1 | BH11: =BC11+BA11+AR11+AG11+W11+K11+H11 -> 67
A12: 46113 | B12: 0900-1000 | C12: 白班 | D12: 进口 | E12: =SUMIFS(卸车数据!$J$6:$J$1048576,卸车数据!$R$6:$R$1048576,">="&A12+TIME(9,0,0),卸车数据!$R$6:$R$1048576,"<"&A12+TIME(10,0,0)) -> 1711 | F12: 3163 | G12: 14973 | H12: 1 | I12: 进口赶二频进局车辆 0920-0950休息吃饭 | K12: =SUM(L12:T12) -> 13 | L12: 1 | M12: 4 | N12: 2 | O12: 1 | P12: 3 | Q12: 1 | R12: 1 | U12: 0900-0920休息 进口清场，清理三频快件 | W12: =SUM(X12:AD12) -> 21 | X12: 1 | Y12: 12 | Z12: 7 | AC12: 1 | AE12: 0920-0940休息 装车临淄2频 | AG12: =SUM(AH12:AO12) -> 14 | AH12: 1 | AI12: 1 | AJ12: 7 | AK12: 3 | AM12: 1 | AN12: 1 | AP12: 2频扫描装车 | AQ12: 关注华光、石桥、光学姐、直投中心的错分白给 | AR12: =SUM(AS12:AZ12) -> 14 | AS12: 1 | AT12: 1 | AU12: 7 | AV12: 3 | AW12: 1 | AX12: 1 | BC12: =BD12+BE12 -> 4 | BD12: 2 | BE12: 2 | BF12: 1 | BH12: =BC12+BA12+AR12+AG12+W12+K12+H12 -> 67
A13: 46113 | B13: 1000-1100 | C13: 白班 | D13: 进口 | E13: =SUMIFS(卸车数据!$J$6:$J$1048576,卸车数据!$R$6:$R$1048576,">="&A13+TIME(10,0,0),卸车数据!$R$6:$R$1048576,"<"&A13+TIME(11,0,0)) -> 493 | F13: 763 | G13: 325 | H13: 1 | I13: 进口清场，邮报纸，装桓台 装标快邮装，寻找遗留邮件 | K13: =SUM(L13:T13) -> 13 | L13: 1 | M13: 4 | N13: 2 | O13: 1 | P13: 3 | Q13: 1 | R13: 1 | U13: 清理三频快件 | W13: =SUM(X13:AD13) -> 21 | X13: 1 | Y13: 12 | Z13: 7 | AC13: 1 | AE13: 扫件 1040 沂源平服挂信件 1050封沂源2频 | AG13: =SUM(AH13:AO13) -> 14 | AH13: 1 | AI13: 1 | AJ13: 7 | AK13: 3 | AM13: 1 | AN13: 1 | AP13: 2频扫描装车 | AQ13: 关注华光、石桥、光学姐、直投中心的错分白给 | AR13: =SUM(AS13:AZ13) -> 14 | AS13: 1 | AT13: 1 | AU13: 7 | AV13: 3 | AW13: 1 | AX13: 1 | BC13: =BD13+BE13 -> 4 | BD13: 2 | BE13: 2 | BF13: 1 | BH13: =BC13+BA13+AR13+AG13+W13+K13+H13 -> 67
A14: 46113 | B14: 1100-1200 | C14: 白班 | D14: 清场 | E14: =SUMIFS(卸车数据!$J$6:$J$1048576,卸车数据!$R$6:$R$1048576,">="&A14+TIME(11,0,0),卸车数据!$R$6:$R$1048576,"<"&A14+TIME(12,0,0)) -> 2033 | F14: 520 | G14: 48 | H14: 1 | I14: 出口作业，5组出口卸车，每组1个卸车，1个翻面1个粗分共五组 | K14: =SUM(L14:T14) -> 15 | L14: 1 | M14: 5 | N14: 5 | P14: 4 | U14: 1100-1130进口清场，清理三频快件 1130-1200整组外派1人拆包，1人预制袋牌，2人南环，6人标快，10人北环 | W14: =SUM(X14:AD14) -> 21 | X14: 1 | Y14: 12 | Z14: 6 | AC14: 2 | AE14: 1120进口清场转场出口 | AG14: =SUM(AH14:AO14) -> 19 | AH14: 1 | AI14: 1 | AJ14: 5 | AK14: 10 | AM14: 1 | AN14: 1 | AP14: 串行车辆装装车 | AQ14: 1、关注串行车辆装车隔离 2、班清检查邮件全部按频次赶发 3、关注文件、挂信、报纸装车情况 | AR14: =SUM(AS14:AZ14) -> 14 | AS14: 1 | AT14: 1 | AU14: 7 | AV14: 3 | AW14: 1 | AX14: 1 | BC14: =BD14+BE14 -> 4 | BD14: 2 | BE14: 2 | BF14: 1 | BH14: =BC14+BA14+AR14+AG14+W14+K14+H14 -> 74 | BI14: 中班 1130-2330 | BJ14: 6
A15: 46113 | B15: 1200-1300 | C15: 白班 | D15: 出口 | E15: =SUMIFS(卸车数据!$J$6:$J$1048576,卸车数据!$R$6:$R$1048576,">="&A15+TIME(12,0,0),卸车数据!$R$6:$R$1048576,"<"&A15+TIME(13,0,0)) -> 18883 | F15: 7662 | G15: 15 | H15: 1 | I15: 1130-1420增加作业垛口赶发济南邮航路 | J15: 确保一频返程车辆贵重物品、标快文件、生鲜类快件及时赶发3频 | K15: =SUM(L15:T15) -> 20 | L15: 1 | M15: 5 | N15: 5 | P15: 4 | T15: 5 | U15: 整组外派1人拆包，1人预制袋牌，2人南环，6人标快，10人北环 | V15: 外派10人北环2人南环 | W15: =SUM(X15:AD15) -> 4 | X15: 1 | AA15: 1 | AC15: 2 | AE15: 1200分济南航站邮件，配发扫描装车 1240装淄川、周村、高青落地邮件 | AG15: =SUM(AH15:AO15) -> 29 | AH15: 1 | AI15: 3 | AJ15: 5 | AK15: 10 | AO15: 10 | AP15: 切换出口 | AQ15: 一干顶扫，邮路及装车情况 | AR15: =SUM(AS15:AZ15) -> 16 | AS15: 1 | AT15: 1 | AU15: 7 | AV15: 3 | AW15: 1 | AZ15: 3 | BC15: =BD15+BE15 -> 4 | BD15: 2 | BE15: 2 | BF15: 1 | BH15: =BC15+BA15+AR15+AG15+W15+K15+H15 -> 74
A16: 46113 | B16: 1300-1400 | C16: 白班 | D16: 出口 | E16: =SUMIFS(卸车数据!$J$6:$J$1048576,卸车数据!$R$6:$R$1048576,">="&A16+TIME(13,0,0),卸车数据!$R$6:$R$1048576,"<"&A16+TIME(14,0,0)) -> 9384 | F16: 4201 | G16: 4314 | H16: 1 | I16: 1130-1420增加作业垛口赶发济南邮航路 | J16: 确保一频返程车辆贵重物品、标快文件、生鲜类快件及时赶发3频 2人与北环装车复用 | K16: =SUM(L16:T16) -> 13 | L16: 1 | M16: 3 | N16: 5 | P16: 4 | U16: 出口快件清理 | W16: =SUM(X16:AD16) -> 27 | X16: 1 | Y16: 12 | Z16: 12 | AC16: 2 | AE16: 1320济南航站文件，扫描配发装车 1330封区县3频 1340从19号口北环区域清理南环邮件 | AG16: =SUM(AH16:AO16) -> 16 | AH16: 1 | AI16: 1 | AJ16: 5 | AK16: 5 | AM16: 1 | AN16: 1 | AO16: 2 | AP16: 切换出口 | AQ16: 一干顶扫，邮路及装车情况 | AR16: =SUM(AS16:AZ16) -> 13 | AS16: 1 | AT16: 1 | AU16: 7 | AV16: 3 | AW16: 1 | BC16: =BD16+BE16 -> 4 | BD16: 2 | BE16: 2 | BF16: 1 | BH16: =BC16+BA16+AR16+AG16+W16+K16+H16 -> 74
A17: 46113 | B17: 1400-1500 | C17: 白班 | D17: 出口 | E17: =SUMIFS(卸车数据!$J$6:$J$1048576,卸车数据!$R$6:$R$1048576,">="&A17+TIME(14,0,0),卸车数据!$R$6:$R$1048576,"<"&A17+TIME(15,0,0)) -> 6307 | F17: 1069 | G17: 10046 | H17: 1 | I17: 1420-1530切换进口作业 | J17: 外派集包网格5人 进口邮件落地5人 2人与北环装车复用 | K17: =SUM(L17:T17) -> 13 | L17: 1 | M17: 3 | N17: 5 | P17: 4 | U17: 出口快件清理 | W17: =SUM(X17:AD17) -> 27 | X17: 1 | Y17: 12 | Z17: 12 | AC17: 2 | AG17: =SUM(AH17:AO17) -> 16 | AH17: 1 | AI17: 1 | AJ17: 5 | AK17: 5 | AM17: 1 | AN17: 1 | AO17: 2 | AP17: 切换出口 | AQ17: 一干顶扫，邮路及装车情况 | AR17: =SUM(AS17:AZ17) -> 13 | AS17: 1 | AT17: 1 | AU17: 7 | AV17: 3 | AW17: 1 | BC17: =BD17+BE17 -> 4 | BD17: 2 | BE17: 2 | BF17: 1 | BH17: =BC17+BA17+AR17+AG17+W17+K17+H17 -> 74
A18: 46113 | B18: 1500-1600 | C18: 白班 | D18: 进口 | E18: =SUMIFS(卸车数据!$J$6:$J$1048576,卸车数据!$R$6:$R$1048576,">="&A18+TIME(15,0,0),卸车数据!$R$6:$R$1048576,"<"&A18+TIME(16,0,0)) -> 0 | F18: 3796 | G18: 9093 | H18: 1 | I18: 进口作业 | J18: 进口邮件落地5人 2人与北环装车复用 | K18: =SUM(L18:T18) -> 17 | L18: 1 | M18: 6 | N18: 2 | P18: 5 | R18: 3 | U18: 转进口 | W18: =SUM(X18:AD18) -> 23 | X18: 1 | Y18: 12 | Z18: 8 | AC18: 2 | AE18: 1500封济自半一 1540进口操作，扫描人员扫 | AG18: =SUM(AH18:AO18) -> 16 | AH18: 1 | AI18: 1 | AJ18: 5 | AK18: 5 | AM18: 1 | AN18: 1 | AO18: 2 | AP18: 切换出口 | AQ18: 一干顶扫，邮路及装车情况 | AR18: =SUM(AS18:AZ18) -> 13 | AS18: 1 | AT18: 1 | AU18: 7 | AV18: 3 | AW18: 1 | BC18: =BD18+BE18 -> 4 | BD18: 2 | BE18: 2 | BF18: 1 | BH18: =BC18+BA18+AR18+AG18+W18+K18+H18 -> 74
A19: 46113 | B19: 1600-1700 | C19: 白班 | D19: 进口 | E19: =SUMIFS(卸车数据!$J$6:$J$1048576,卸车数据!$R$6:$R$1048576,">="&A19+TIME(16,0,0),卸车数据!$R$6:$R$1048576,"<"&A19+TIME(17,0,0)) -> 786 | F19: 3310 | G19: 14333 | H19: 1 | I19: 进口作业 | J19: 进口邮件落地5人 2人与北环装车复用 | K19: =SUM(L19:T19) -> 17 | L19: 1 | M19: 6 | N19: 2 | P19: 5 | R19: 3 | U19: 进口清场 | W19: =SUM(X19:AD19) -> 23 | X19: 1 | Y19: 12 | Z19: 8 | AC19: 2 | AE19: 1600装广东、北京落地邮路 | AG19: =SUM(AH19:AO19) -> 16 | AH19: 1 | AI19: 1 | AJ19: 5 | AK19: 5 | AM19: 1 | AN19: 1 | AO19: 2 | AP19: 切换进口 | AQ19: 检查清场情况 | AR19: =SUM(AS19:AZ19) -> 13 | AS19: 1 | AT19: 1 | AU19: 7 | AV19: 3 | AW19: 1 | BC19: =BD19+BE19 -> 4 | BD19: 2 | BE19: 2 | BF19: 1 | BH19: =BC19+BA19+AR19+AG19+W19+K19+H19 -> 74
A20: 46113 | B20: 1700-1800 | C20: 白班 | D20: 出口 | E20: =SUMIFS(卸车数据!$J$6:$J$1048576,卸车数据!$R$6:$R$1048576,">="&A20+TIME(17,0,0),卸车数据!$R$6:$R$1048576,"<"&A20+TIME(18,0,0)) -> 8467 | F20: 4220 | G20: 31 | H20: 1 | I20: 进口作业 | J20: 进口邮件落地5人 2人与北环装车复用 | K20: =SUM(L20:T20) -> 17 | L20: 1 | M20: 6 | N20: 2 | P20: 5 | R20: 3 | U20: 转出口 | W20: =SUM(X20:AD20) -> 23 | X20: 1 | Y20: 12 | Z20: 8 | AC20: 2 | AE20: 出口作业 | AG20: =SUM(AH20:AO20) -> 16 | AH20: 1 | AI20: 1 | AJ20: 5 | AK20: 5 | AM20: 1 | AN20: 1 | AO20: 2 | AP20: 切换进口 | AQ20: 检查清场情况 | AR20: =SUM(AS20:AZ20) -> 13 | AS20: 1 | AT20: 1 | AU20: 7 | AV20: 3 | AW20: 1 | BC20: =BD20+BE20 -> 4 | BD20: 2 | BE20: 2 | BF20: 1 | BH20: =BC20+BA20+AR20+AG20+W20+K20+H20 -> 74
A21: 46113 | B21: 1800-1900 | C21: 夜班 | D21: 出口 | E21: =SUMIFS(卸车数据!$J$6:$J$1048576,卸车数据!$R$6:$R$1048576,">="&A21+TIME(18,0,0),卸车数据!$R$6:$R$1048576,"<"&A21+TIME(19,0,0)) -> 16740 | F21: 5114 | G21: 4803 | H21: 1 | I21: 进口操作 | K21: =SUM(L21:T21) -> 21 | L21: 1 | M21: 8 | P21: 6 | Q21: 4 | T21: 2 | U21: 协助北环及卸车口进行人员复用 | W21: =SUM(X21:AD21) -> 15 | X21: 1 | Y21: 6 | Z21: 5 | AA21: 1 | AC21: 2 | AG21: =SUM(AH21:AO21) -> 39 | AH21: 1 | AI21: 6 | AJ21: 6 | AK21: 11 | AM21: 1 | AN21: 1 | AO21: 13 | AQ21: 分拣7快包2标快 | AR21: =SUM(AS21:AZ21) -> 18 | AS21: 1 | AU21: 9 | AV21: 7 | AX21: 1 | BA21: 4 | BC21: =BD21+BE21 -> 3 | BD21: 3 | BF21: 1 | BH21: =BC21+BA21+AR21+AG21+W21+K21+H21 -> 101 | BI21: 夜班 | BJ21: 96
A22: 46113 | B22: 1900-2000 | C22: 夜班 | D22: 出口 | E22: =SUMIFS(卸车数据!$J$6:$J$1048576,卸车数据!$R$6:$R$1048576,">="&A22+TIME(19,0,0),卸车数据!$R$6:$R$1048576,"<"&A22+TIME(20,0,0)) -> 30064 | F22: 5639 | G22: 14123 | H22: 1 | K22: =SUM(L22:T22) -> 19 | L22: 1 | M22: 8 | P22: 6 | Q22: 4 | W22: =SUM(X22:AD22) -> 30 | X22: 1 | Y22: 14 | Z22: 12 | AA22: 1 | AC22: 2 | AG22: =SUM(AH22:AO22) -> 26 | AH22: 1 | AI22: 6 | AJ22: 6 | AK22: 11 | AM22: 1 | AN22: 1 | AR22: =SUM(AS22:AZ22) -> 18 | AS22: 1 | AU22: 9 | AV22: 7 | AX22: 1 | BA22: 4 | BC22: =BD22+BE22 -> 3 | BD22: 3 | BF22: 1 | BH22: =BC22+BA22+AR22+AG22+W22+K22+H22 -> 101
A23: 46113 | B23: 2000-2100 | C23: 夜班 | D23: 出口 | E23: =SUMIFS(卸车数据!$J$6:$J$1048576,卸车数据!$R$6:$R$1048576,">="&A23+TIME(20,0,0),卸车数据!$R$6:$R$1048576,"<"&A23+TIME(21,0,0)) -> 13963 | F23: 4949 | G23: 14447 | H23: 1 | I23: 2020巡查卸车区、文件标快、次晨达、挂特快、统一交接南环 | K23: =SUM(L23:T23) -> 19 | L23: 1 | M23: 8 | P23: 6 | Q23: 4 | W23: =SUM(X23:AD23) -> 30 | X23: 1 | Y23: 14 | Z23: 12 | AA23: 1 | AC23: 2 | AG23: =SUM(AH23:AO23) -> 26 | AH23: 1 | AI23: 6 | AJ23: 6 | AK23: 11 | AM23: 1 | AN23: 1 | AR23: =SUM(AS23:AZ23) -> 18 | AS23: 1 | AU23: 9 | AV23: 7 | AX23: 1 | BA23: 4 | BC23: =BD23+BE23 -> 3 | BD23: 3 | BF23: 1 | BH23: =BC23+BA23+AR23+AG23+W23+K23+H23 -> 101
A24: 46113 | B24: 2100-2200 | C24: 夜班 | D24: 出口 | E24: =SUMIFS(卸车数据!$J$6:$J$1048576,卸车数据!$R$6:$R$1048576,">="&A24+TIME(21,0,0),卸车数据!$R$6:$R$1048576,"<"&A24+TIME(22,0,0)) -> 2570 | F24: 5056 | G24: 15492 | H24: 1 | K24: =SUM(L24:T24) -> 19 | L24: 1 | M24: 8 | P24: 6 | Q24: 4 | W24: =SUM(X24:AD24) -> 30 | X24: 1 | Y24: 14 | Z24: 12 | AA24: 1 | AC24: 2 | AG24: =SUM(AH24:AO24) -> 26 | AH24: 1 | AI24: 6 | AJ24: 6 | AK24: 11 | AM24: 1 | AN24: 1 | AR24: =SUM(AS24:AZ24) -> 18 | AS24: 1 | AU24: 9 | AV24: 7 | AX24: 1 | BA24: 4 | BC24: =BD24+BE24 -> 3 | BD24: 3 | BF24: 1 | BH24: =BC24+BA24+AR24+AG24+W24+K24+H24 -> 101
A25: 46113 | B25: 2200-2300 | C25: 夜班 | D25: 出口 | E25: =SUMIFS(卸车数据!$J$6:$J$1048576,卸车数据!$R$6:$R$1048576,">="&A25+TIME(22,0,0),卸车数据!$R$6:$R$1048576,"<"&A25+TIME(23,0,0)) -> 6932 | F25: 1608 | G25: 4913 | H25: 1 | I25: 2215班清 2235切换进口大件落地，小件送集包区 | K25: =SUM(L25:T25) -> 19 | L25: 1 | M25: 8 | P25: 6 | Q25: 4 | W25: =SUM(X25:AD25) -> 30 | X25: 1 | Y25: 14 | Z25: 12 | AA25: 1 | AC25: 2 | AG25: =SUM(AH25:AO25) -> 26 | AH25: 1 | AI25: 6 | AJ25: 6 | AK25: 11 | AM25: 1 | AN25: 1 | AR25: =SUM(AS25:AZ25) -> 18 | AS25: 1 | AU25: 9 | AV25: 7 | AX25: 1 | BA25: 4 | BC25: =BD25+BE25 -> 3 | BD25: 3 | BF25: 1 | BH25: =BC25+BA25+AR25+AG25+W25+K25+H25 -> 101
A26: 46113 | B26: 2300-0000 | C26: 夜班 | D26: 清场 | E26: =SUMIFS(卸车数据!$J$6:$J$1048576,卸车数据!$R$6:$R$1048576,">="&A26+TIME(23,0,0),卸车数据!$R$6:$R$1048576,"<"&A26+TIME(0,0,0)) -> 0 | F26: 4959 | G26: 10612 | H26: 1 | I26: 2330中班下班 2组卸车 | K26: =SUM(L26:T26) -> 17 | L26: 1 | M26: 5 | N26: 2 | O26: 2 | P26: 4 | Q26: 1 | R26: 2 | U26: 2330中班下班 切换进口作业 | W26: =SUM(X26:AD26) -> 25 | X26: 1 | Y26: 12 | Z26: 9 | AA26: 1 | AC26: 2 | AE26: 2340转进口 2320齐河潍坊二干发车 | AG26: =SUM(AH26:AO26) -> 26 | AH26: 1 | AI26: 6 | AJ26: 6 | AK26: 11 | AM26: 1 | AN26: 1 | AR26: =SUM(AS26:AZ26) -> 19 | AS26: 1 | AU26: 11 | AV26: 5 | AX26: 1 | AY26: 1 | BA26: 4 | BC26: =BD26+BE26 -> 3 | BD26: 3 | BF26: 1 | BH26: =BC26+BA26+AR26+AG26+W26+K26+H26 -> 95 | BI26: 6 | BJ26: 中班下班
B27: 一、用工情况一览
B28: 2025/4/11写实 | N28: 0330视卸车到件情况场内减员 | Q28: 生产人员人数：167人
B29: 班组 | D29: 白班：人数65人 | I29: 夜班：人数96人
B31: 时间轴 | D31: 0700 | I31: 1800 | L31: 2330 | O31: 0700

Sheet 2
A1: 日期 | B1: 时段 | C1: 班次 | D1: 频次 | E1: 卸车量 | F1: 环线量 | G1: 集包量 | H1: 管理 | I1: 卸车网格 | U1: 集包网格 | AF1: 北环网格 | AP1: 南环网格 | BA1: 特快 | BB1: 其它 | BH1: 合计 | BI1: 25万
I2: 工作内容 | J2: 关注点 | K2: 小计 | L2: 网格长 | M2: 卸车 | N2: 翻面 | O2: 勾核 | P2: 粗分 | Q2: 疏堵 | R2: 拆包、整理 | S2: 问题邮件 | T2: 复用 | U2: 工作内容 | V2: 关注点 | W2: 小计 | X2: 网格长 | Y2: 供件（均件、疏堵） | Z2: 齐格/封包 | AA2: 处理问题件、预支袋牌 | AB2: 人工集包 | AC2: 人工上包、翻包、异形件盘剥、拆包 | AD2: 复用 | AE2: 工作内容 | AF2: 关注点 | AG2: 小计 | AH2: 网格长 | AI2: 分拣 | AJ2: 扫描 | AK2: 码货 | AL2: 封发车 | AM2: 回流 | AN2: 问题件处理 | AO2: 复用 | AP2: 工作内容 | AQ2: 关注点 | AR2: 小计 | AS2: 网格长 | AT2: 分拣 | AU2: 扫描 | AV2: 码货 | AW2: 封发车 | AX2: 回流 | AY2: 问题件处理 | AZ2: 复用 | BB2: 接挂信、报刊 | BC2: 小计 | BD2: 发验 | BE2: 客服 | BF2: 西场 | BG2: 门卫值班
A3: ='1'!A20+1 -> 46114 | B3: 0000-0100 | C3: 夜班 | D3: 进口 | E3: =SUMIFS(卸车数据!$J$6:$J$1048576,卸车数据!$R$6:$R$1048576,">="&A3+TIME(0,0,0),卸车数据!$R$6:$R$1048576,"<"&A3+TIME(1,0,0)) -> 15846 | F3: 1431 | G3: 4923 | H3: 1 | I3: 0050 济临4卸车，清理落地 破损发验 | K3: =SUM(L3:T3) -> 17 | L3: 1 | M3: 5 | N3: 2 | O3: 2 | P3: 4 | Q3: 1 | R3: 2 | W3: =SUM(X3:AD3) -> 25 | X3: 1 | Y3: 12 | Z3: 9 | AA3: 1 | AC3: 2 | AE3: 0030北京一干发车 0010广州一干发车 | AG3: =SUM(AH3:AO3) -> 26 | AH3: 1 | AI3: 6 | AJ3: 6 | AK3: 11 | AM3: 1 | AN3: 1 | AR3: =SUM(AS3:AZ3) -> 20 | AS3: 1 | AU3: 11 | AV3: 6 | AX3: 1 | AY3: 1 | BA3: 4 | BC3: =BD3+BE3 -> 3 | BD3: 3 | BF3: 1 | BH3: =BC3+BA3+AR3+AG3+W3+K3+H3 -> 96
A4: ='1'!A21+1 -> 46114 | B4: 0100-0200 | C4: 夜班 | D4: 进口 | E4: =SUMIFS(卸车数据!$J$6:$J$1048576,卸车数据!$R$6:$R$1048576,">="&A4+TIME(1,0,0),卸车数据!$R$6:$R$1048576,"<"&A4+TIME(2,0,0)) -> 0 | F4: 3938 | G4: 13433 | H4: 1 | K4: =SUM(L4:T4) -> 17 | L4: 1 | M4: 5 | N4: 2 | O4: 2 | P4: 4 | Q4: 1 | R4: 2 | W4: =SUM(X4:AD4) -> 25 | X4: 1 | Y4: 12 | Z4: 9 | AA4: 1 | AC4: 2 | AE4: 0200济加三收尾车发车 | AG4: =SUM(AH4:AO4) -> 26 | AH4: 1 | AI4: 6 | AJ4: 6 | AK4: 11 | AM4: 1 | AN4: 1 | AR4: =SUM(AS4:AZ4) -> 20 | AS4: 1 | AU4: 11 | AV4: 6 | AX4: 1 | AY4: 1 | BA4: 4 | BC4: =BD4+BE4 -> 3 | BD4: 3 | BF4: 1 | BH4: =BC4+BA4+AR4+AG4+W4+K4+H4 -> 96
A5: ='1'!A22+1 -> 46114 | B5: 0200-0300 | C5: 夜班 | D5: 进口 | E5: =SUMIFS(卸车数据!$J$6:$J$1048576,卸车数据!$R$6:$R$1048576,">="&A5+TIME(2,0,0),卸车数据!$R$6:$R$1048576,"<"&A5+TIME(3,0,0)) -> 0 | F5: 4248 | G5: 14370 | H5: 1 | I5: 济加1进局卸车 | K5: =SUM(L5:T5) -> 17 | L5: 1 | M5: 5 | N5: 2 | O5: 2 | P5: 4 | Q5: 1 | R5: 2 | U5: 0230分拣进行停机班清，同时处理退换件、轻薄异型件 | W5: =SUM(X5:AD5) -> 25 | X5: 1 | Y5: 12 | Z5: 9 | AA5: 1 | AC5: 2 | AG5: =SUM(AH5:AO5) -> 26 | AH5: 1 | AI5: 6 | AJ5: 6 | AK5: 11 | AM5: 1 | AN5: 1 | AR5: =SUM(AS5:AZ5) -> 20 | AS5: 1 | AU5: 11 | AV5: 6 | AX5: 1 | AY5: 1 | BA5: 4 | BC5: =BD5+BE5 -> 3 | BD5: 3 | BF5: 1 | BH5: =BC5+BA5+AR5+AG5+W5+K5+H5 -> 96
