Workbook

Sheet 6月日经营数据
A1: 2025年南京项目处理经营情况（6月）
A3: 科目 | C3: 45809 | D3: =C3+1 -> 45810 | E3: =D3+1 -> 45811 | F3: =E3+1 -> 45812 | G3: =F3+1 -> 45813 | H3: =G3+1 -> 45814 | I3: =H3+1 -> 45815 | J3: =I3+1 -> 45816 | K3: =J3+1 -> 45817 | ... AG3: =AF3+1 -> 45839 | AH3: 月度合计
C4: 进口处理 | D4: 进口处理 | E4: 进口处理 | F4: 进口处理 | G4: 进口处理 | H4: 进口处理 | I4: 进口处理 | J4: 进口处理 | K4: 进口处理 | L4: 进口处理 | M4: 进口处理 | N4: 进口处理 | O4: 进口处理 | P4: 进口处理 | Q4: 进口处理 | R4: 进口处理 | S4: 进口处理 | T4: 进口处理 | U4: 进口处理 | V4: 进口处理 | W4: 进口处理 | X4: 进口处理 | Y4: 进口处理 | Z4: 进口处理 | AA4: 进口处理 | AB4: 进口处理 | AC4: 进口处理 | AD4: 进口处理 | AE4: 进口处理 | AF4: 进口处理 | AG4: 进口处理 | AH4: 进口处理
A5: 1 | B5: 散件处理量 | C5: =SUMIFS('6月处理量'!$F:$F,'6月处理量'!$A:$A,C3) -> 626140 | D5: =SUMIFS('6月处理量'!$F:$F,'6月处理量'!$A:$A,D3) -> 612040 | E5: =SUMIFS('6月处理量'!$F:$F,'6月处理量'!$A:$A,E3) -> 700265 | F5: =SUMIFS('6月处理量'!$F:$F,'6月处理量'!$A:$A,F3) -> 743201 | G5: =SUMIFS('6月处理量'!$F:$F,'6月处理量'!$A:$A,G3) -> 790629 | H5: =SUMIFS('6月处理量'!$F:$F,'6月处理量'!$A:$A,H3) -> 770752 | I5: =SUMIFS('6月处理量'!$F:$F,'6月处理量'!$A:$A,I3) -> 758273 | J5: =SUMIFS('6月处理量'!$F:$F,'6月处理量'!$A:$A,J3) -> 749111 | ... AG5: =SUMIFS('6月处理量'!$F:$F,'6月处理量'!$A:$A,AG3) -> 0 | AH5: =SUM(C5:AG5) -> 22173981
A6: 2 | B6: 散件处理单价 | C6: 0.1667 | D6: 0.1667 | E6: 0.1667 | F6: 0.1667 | G6: 0.1667 | H6: 0.1667 | I6: 0.1667 | J6: 0.1667 | K6: 0.1667 | L6: 0.1667 | M6: 0.1667 | N6: 0.1667 | O6: 0.1667 | P6: 0.1667 | Q6: 0.1667 | R6: 0.1667 | S6: 0.1667 | T6: 0.1667 | U6: 0.1667 | V6: 0.1667 | W6: 0.1667 | X6: 0.1667 | Y6: 0.1667 | Z6: 0.1667 | AA6: 0.1667 | AB6: 0.1667 | AC6: 0.1667 | AD6: 0.1667 | AE6: 0.1667 | AF6: 0.1667 | AH6: 0.1667
A7: 3 | B7: 散件处理收入 | C7: 104377.54 | D7: 102027.07 | E7: 116734.18 | F7: 123891.61 | G7: 131797.85 | H7: 128484.36 | I7: 126404.11 | J7: 124876.8 | K7: 118175.8 | L7: 125769.65 | M7: 128137.29 | N7: 126079.71 | O7: 132056.24 | P7: 126895.37 | Q7: 120701.97 | R7: 124206.34 | S7: 125173.03 | T7: 126261.08 | U7: 133446.52 | V7: 131387.61 | W7: 135726.47 | X7: 131644.32 | Y7: 123039.94 | Z7: 119158.16 | AA7: 123127.95 | AB7: 116612.98 | AC7: 118228.64 | AD7: 116579.98 | AE7: 119867.14 | AF7: 115532.94 | AH7: =SUM(C7:AG7) -> 3696402.6
A8: 4 | B8: 考核扣款 | C8: 3000 | D8: 3000 | E8: 3000 | F8: 3000 | G8: 3000 | H8: 3000 | I8: 3000 | J8: 3000 | K8: 3000 | L8: 3000 | M8: 3000 | N8: 3000 | O8: 3000 | P8: 3000 | Q8: 3000 | R8: 3000 | S8: 3000 | T8: 3000 | U8: 3000 | V8: 3000 | W8: 3000 | X8: 3000 | Y8: 3000 | Z8: 3000 | AA8: 3000 | AB8: 3000 | AC8: 3000 | AD8: 3000 | AE8: 3000 | AF8: 3000 | AH8: =SUM(C8:AG8) -> 90000
A9: 5 | B9: 补贴费用 | AH9: =SUM(C9:AG9) -> 0
A10: 6 | B10: 开票金额 | C10: 101377.54 | D10: 99027.07 | E10: 113734.18 | F10: 120891.61 | G10: 128797.85 | H10: 125484.36 | I10: 123404.11 | J10: 121876.8 | K10: 115175.8 | L10: 122769.65 | M10: 125137.29 | N10: 123079.71 | O10: 129056.24 | P10: 123895.37 | Q10: 117701.97 | R10: 121206.34 | S10: 122173.03 | T10: 123261.08 | U10: 130446.52 | V10: 128387.61 | W10: 132726.47 | X10: 128644.32 | Y10: 120039.94 | Z10: 116158.16 | AA10: 120127.95 | AB10: 113612.98 | AC10: 115228.64 | AD10: 113579.98 | AE10: 116867.14 | AF10: 112532.94 | AH10: =SUM(C10:AG10) -> 3606402.6
A11: 一、主营业务收入总计 | C11: 95639.19 | D11: 93421.76 | E11: 107296.4 | F11: 114048.69 | G11: 121507.41 | H11: 118381.47 | I11: 116418.97 | J11: 114978.11 | K11: 108656.42 | L11: 115820.42 | M11: 118054.05 | N11: 116112.93 | O11: 121751.17 | P11: 116882.42 | Q11: 111039.59 | R11: 114345.6 | S11: 115257.58 | T11: 116284.04 | U11: 123062.75 | V11: 121120.39 | W11: 125213.65 | X11: 121362.57 | Y11: 113245.23 | Z11: 109583.17 | AA11: 113328.25 | AB11: 107182.06 | AC11: 108706.26 | AD11: 107150.92 | AE11: 110252.02 | AF11: 106163.15 | AH11: =SUM(C11:AG11) -> 3402266.6
A12: 1 | B12: 管理人员数量 | C12: 20 | D12: 19 | E12: 22 | F12: 21 | G12: 22 | H12: 22 | I12: 21 | J12: 18 | K12: 22 | L12: 23 | M12: 22 | N12: 21 | O12: 20 | P12: 17 | Q12: 18 | R12: 19 | S12: 20 | T12: 22 | U12: 22 | V12: 22 | W12: 22 | X12: 17 | Y12: 20 | Z12: 20 | AA12: 19 | AB12: 19 | AC12: 23 | AD12: 20 | AE12: 22 | AF12: 22 | AH12: =SUM(C12:AG12) -> 617
A13: 2 | B13: 自有员工数量 | C13: 291 | D13: 299 | E13: 293 | F13: 302 | G13: 310 | H13: 297 | I13: 302 | J13: 309 | K13: 295 | L13: 299 | M13: 302 | N13: 301 | O13: 316 | P13: 315 | Q13: 312 | R13: 307 | S13: 312 | T13: 309 | U13: 319 | V13: 311 | W13: 309 | X13: 318 | Y13: 307 | Z13: 320 | AA13: 316 | AB13: 317 | AC13: 314 | AD13: 318 | AE13: 324 | AF13: 301 | AH13: =SUM(C13:AG13) -> 9245
A14: 3 | B14: 劳务人员数量 | C14: 58 | D14: 49 | E14: 49 | F14: 50 | G14: 49 | H14: 58 | I14: 56 | J14: 48 | K14: 48 | L14: 47 | M14: 46 | N14: 53 | O14: 48 | P14: 46 | Q14: 46 | R14: 45 | S14: 45 | T14: 48 | U14: 46 | V14: 50 | W14: 47 | X14: 50 | Y14: 50 | Z14: 49 | AA14: 46 | AB14: 44 | AC14: 49 | AD14: 51 | AE14: 40 | AF14: 52 | AH14: =SUM(C14:AG14) -> 1463
A15: 4 | B15: 总人数 | C15: 369 | D15: 367 | E15: 364 | F15: 373 | G15: 381 | H15: 377 | I15: 379 | J15: 375 | K15: 365 | L15: 369 | M15: 370 | N15: 375 | O15: 384 | P15: 378 | Q15: 376 | R15: 371 | S15: 377 | T15: 379 | U15: 387 | V15: 383 | W15: 378 | X15: 385 | Y15: 377 | Z15: 389 | AA15: 381 | AB15: 380 | AC15: 386 | AD15: 389 | AE15: 386 | AF15: 375 | AH15: =SUM(C15:AG15) -> 11325
A16: 5 | B16: 总工时 | C16: 3960 | D16: 3912 | E16: 3872 | F16: 4000.5 | G16: 4087.5 | H16: 4042 | I16: 4066.5 | J16: 4046.5 | K16: 3897 | L16: 3926 | M16: 3962 | N16: 4023.5 | O16: 4124.5 | P16: 4100.5 | Q16: 4059.5 | R16: 3997.5 | S16: 4072.5 | T16: 4067 | U16: 4151 | V16: 4165 | W16: 4104.5 | X16: 4212.5 | Y16: 4105 | Z16: 4197.5 | AA16: 4109 | AB16: 4110 | AC16: 4120.5 | AD16: 4251.5 | AE16: 4148.5 | AF16: 4008.5 | AH16: =SUM(C16:AG16) -> 121900.5
A17: 人均效能 | C17: 1696.8564 | D17: 1667.6839 | E17: 1923.8049 | F17: 1992.496 | G17: 2075.1417 | H17: 2044.435 | I17: 2000.7203 | J17: 1997.6293 | K17: 1942.2274 | L17: 2044.626 | M17: 2077.4865 | N17: 2016.872 | O17: 2062.9661 | P17: 2013.8095 | Q17: 1925.7101 | R17: 2008.3261 | S17: 1991.7454 | T17: 1998.4565 | U17: 2068.5245 | V17: 2057.8799 | W17: 2153.9577 | X17: 2051.1896 | Y17: 1957.8037 | Z17: 1837.5476 | AA17: 1938.6352 | AB17: 1840.8895 | AC17: 1837.3834 | AD17: 1797.7892 | AE17: 1862.8472 | AF17: 1848.1573 | AH17: =AH5/AH15 -> 1957.9674
A18: 人均小时效能 | C18: 158.11616 | D18: 156.45194 | E18: 180.85356 | F18: 185.77703 | G18: 193.42606 | H18: 190.6858 | I18: 186.46822 | J18: 185.12566 | K18: 181.9125 | L18: 192.17193 | M18: 194.0106 | N18: 187.97738 | O18: 192.06667 | P18: 185.64078 | Q18: 178.36359 | R18: 186.38874 | S18: 184.38011 | T18: 186.23433 | U18: 192.84967 | V18: 189.23601 | W18: 198.36667 | X18: 187.46777 | Y18: 179.80317 | Z18: 170.29327 | AA18: 179.75663 | AB18: 170.20389 | AC18: 172.12232 | AD18: 164.49253 | AE18: 173.32988 | AF18: 172.89734 | AH18: =AH5/AH16 -> 181.9023
A19: 1 | B19: 自有员工工资 | C19: 60248.65 | D19: 61254 | E19: 60570.8 | F19: 62686.4 | G19: 64468.95 | H19: 61740.9 | I19: 62593.2 | J19: 63935.65 | K19: 61121.2 | L19: 61811.85 | M19: 62784.15 | N19: 62371.95 | O19: 65352.05 | P19: 65427 | Q19: 64642.45 | R19: 63669 | S19: 64907 | T19: 64421.45 | U19: 66377.45 | V19: 65733.75 | W19: 65175.1 | X19: 66610.45 | Y19: 64661.2 | Z19: 66581.6 | AA19: 65567.8 | AB19: 65999.55 | AC19: 65179.6 | AD19: 67151.85 | AE19: 67601.45 | AF19: 62408.05 | AH19: =SUM(C19:AG19) -> 1923054.5
A20: 2 | B20: 员工宿舍费 | C20: 1300 | D20: 1300 | E20: 1300 | F20: 1300 | G20: 1300 | H20: 1300 | I20: 1300 | J20: 1300 | K20: 1300 | L20: 1300 | M20: 1300 | N20: 1300 | O20: 1300 | P20: 1300 | Q20: 1300 | R20: 1300 | S20: 1300 | T20: 1300 | U20: 1300 | V20: 1300 | W20: 1300 | X20: 1300 | Y20: 1300 | Z20: 1300 | AA20: 1300 | AB20: 1300 | AC20: 1300 | AD20: 1300 | AE20: 1300 | AF20: 1300 | AH20: =SUM(C20:AG20) -> 39000
A21: 3 | B21: 意外险 | C21: 282.92 | D21: 290.69 | E21: 284.86 | F21: 293.61 | G21: 301.39 | H21: 288.75 | I21: 293.61 | J21: 300.42 | K21: 286.81 | L21: 290.69 | M21: 293.61 | N21: 292.64 | O21: 307.22 | P21: 306.25 | Q21: 303.33 | R21: 298.47 | S21: 303.33 | T21: 300.42 | U21: 310.14 | V21: 302.36 | W21: 300.42 | X21: 309.17 | Y21: 298.47 | Z21: 311.11 | AA21: 307.22 | AB21: 308.19 | AC21: 305.28 | AD21: 309.17 | AE21: 315 | AF21: 292.64 | AH21: =SUM(C21:AG21) -> 8988.19
A22: 4 | B22: 雇主险 | C22: 331.42 | D22: 340.53 | E22: 333.69 | F22: 343.94 | G22: 353.06 | H22: 338.25 | I22: 343.94 | J22: 351.92 | K22: 335.97 | L22: 340.53 | M22: 343.94 | N22: 342.81 | O22: 359.89 | P22: 358.75 | Q22: 355.33 | R22: 349.64 | S22: 355.33 | T22: 351.92 | U22: 363.31 | V22: 354.19 | W22: 351.92 | X22: 362.17 | Y22: 349.64 | Z22: 364.44 | AA22: 359.89 | AB22: 361.03 | AC22: 357.61 | AD22: 362.17 | AE22: 369 | AF22: 342.81 | AH22: =SUM(C22:AG22) -> 10529.04
A23: 5 | B23: 员工餐费 | C23: 2488 | D23: 2544 | E23: 2520 | F23: 2584 | G23: 2656 | H23: 2552 | I23: 2584 | J23: 2616 | K23: 2536 | L23: 2576 | M23: 2592 | N23: 2576 | O23: 2688 | P23: 2656 | Q23: 2640 | R23: 2608 | S23: 2656 | T23: 2648 | U23: 2728 | V23: 2664 | W23: 2648 | X23: 2680 | Y23: 2616 | Z23: 2720 | AA23: 2680 | AB23: 2688 | AC23: 2696 | AD23: 2704 | AE23: 2768 | AF23: 2584 | AH23: =SUM(C23:AG23) -> 78896
A24: 6 | B24: 高温福利费用 | F24: 4500 | AH24: =SUM(C24:AG24) -> 4500
A25: 7 | B25: 劳务人员工资 | C25: 15295 | D25: 12960.5 | E25: 12960.5 | F25: 13225 | G25: 12960.5 | H25: 15341 | I25: 14812 | J25: 12696 | K25: 12696 | L25: 12431.5 | M25: 12167 | N25: 14018.5 | O25: 12696 | P25: 12167 | Q25: 12167 | R25: 11902.5 | S25: 12167 | T25: 12696 | U25: 12167 | V25: 13225 | W25: 12431.5 | X25: 13225 | Y25: 13225 | Z25: 12880 | AA25: 12167 | AB25: 11638 | AC25: 12960.5 | AD25: 13489.5 | AE25: 10580 | AF25: 13754 | AH25: =SUM(C25:AG25) -> 387101.5
A26: 8 | B26: 物料采购 | C26: 1560 | D26: 1560 | E26: 1560 | F26: 1560 | G26: 1560 | H26: 1560 | I26: 1560 | J26: 1560 | K26: 1560 | L26: 1560 | M26: 1489.28 | AH26: =SUM(C26:AG26) -> 17089.28
A27: 9 | B27: 工单赔付 | C27: 3333.33 | D27: 3333.33 | E27: 3333.33 | F27: 3333.33 | G27: 3333.33 | H27: 3333.33 | I27: 3333.33 | J27: 3333.33 | K27: 3333.33 | L27: 3333.33 | M27: 3333.33 | N27: 3333.33 | O27: 3333.33 | P27: 3333.33 | Q27: 3333.33 | R27: 3333.33 | S27: 3333.33 | T27: 3333.33 | U27: 3333.33 | V27: 3333.33 | W27: 3333.33 | X27: 3333.33 | Y27: 3333.33 | Z27: 3333.33 | AA27: 3333.33 | AB27: 3333.33 | AC27: 3333.33 | AD27: 3333.33 | AE27: 3333.33 | AF27: 3333.33 | AH27: =SUM(C27:AG27) -> 99999.9
A28: 10 | B28: 设备成本摊销 | C28: 35089.62 | D28: 35089.62 | E28: 35089.62 | F28: 35089.62 | G28: 35089.62 | H28: 35089.62 | I28: 35089.62 | J28: 35089.62 | K28: 35089.62 | L28: 35089.62 | M28: 35089.62 | N28: 35089.62 | O28: 35089.62 | P28: 35089.62 | Q28: 35089.62 | R28: 35089.62 | S28: 35089.62 | T28: 35089.62 | U28: 35089.62 | V28: 35089.62 | W28: 35089.62 | X28: 35089.62 | Y28: 35089.62 | Z28: 35089.62 | AA28: 35089.62 | AB28: 35089.62 | AC28: 35089.62 | AD28: 35089.62 | AE28: 35089.62 | AF28: 35089.62 | AH28: =SUM(C28:AG28) -> 1052688.6
A29: 二、主营业务成本总计 | C29: 119928.94 | D29: 118672.67 | E29: 117952.8 | F29: 124915.9 | G29: 122022.85 | H29: 121543.85 | I29: 121909.7 | J29: 121182.94 | K29: 118258.93 | L29: 118733.52 | M29: 119392.93 | N29: 119324.85 | O29: 121126.11 | P29: 120637.95 | Q29: 119831.06 | R29: 118550.56 | S29: 120111.61 | T29: 120140.74 | U29: 121668.85 | V29: 122002.25 | W29: 120629.89 | X29: 122909.74 | Y29: 120873.26 | Z29: 122580.1 | AA29: 120804.86 | AB29: 120717.72 | AC29: 121221.94 | AD29: 123739.64 | AE29: 121356.4 | AF29: 119104.45 | AH29: =SUM(AH19:AH28) -> 3621847
A30: 主营业务税金及附加 | C30: 688.6 | D30: 672.64 | E30: 772.53 | F30: 821.15 | G30: 874.85 | H30: 852.35 | I30: 838.22 | J30: 827.84 | K30: 782.33 | L30: 833.91 | M30: 849.99 | N30: 836.01 | O30: 876.61 | P30: 841.55 | Q30: 799.49 | R30: 823.29 | S30: 829.85 | T30: 837.25 | U30: 886.05 | V30: 872.07 | W30: 901.54 | X30: 873.81 | Y30: 815.37 | Z30: 789 | AA30: 815.96 | AB30: 771.71 | AC30: 782.69 | AD30: 771.49 | AE30: 793.81 | AF30: 764.37 | AH30: =SUM(C30:AG30) -> 24496.33
A31: 三、主营业务利润（亏损以“-”号填列) | C31: -24978.35 | D31: -25923.55 | E31: -11428.93 | F31: -11688.36 | G31: -1390.29 | H31: -4014.73 | I31: -6328.95 | J31: -7032.67 | K31: -10384.84 | L31: -3747.01 | M31: -2188.87 | N31: -4047.93 | O31: -251.55 | P31: -4597.08 | Q31: -9590.96 | R31: -5028.25 | S31: -5683.88 | T31: -4693.95 | U31: 507.85 | V31: -1753.93 | W31: 3682.22 | X31: -2420.98 | Y31: -8443.4 | Z31: -13785.93 | AA31: -8292.57 | AB31: -14307.37 | AC31: -13298.37 | AD31: -17360.21 | AE31: -11898.19 | AF31: -13705.67 | AH31: =AH11-AH29-AH30 -> -244076.7
A32: 1 | B32: 管理人员工资 | C32: 10268.93 | D32: 10268.93 | E32: 10268.93 | F32: 10268.93 | G32: 10268.93 | H32: 10268.93 | I32: 10268.93 | J32: 10268.93 | K32: 10268.93 | L32: 10268.93 | M32: 10268.93 | N32: 10268.93 | O32: 10268.93 | P32: 10268.93 | Q32: 10268.93 | R32: 10268.93 | S32: 10268.93 | T32: 10268.93 | U32: 10268.93 | V32: 10268.93 | W32: 10268.93 | X32: 10268.93 | Y32: 10268.93 | Z32: 10268.93 | AA32: 10268.93 | AB32: 10268.93 | AC32: 10268.93 | AD32: 10268.93 | AE32: 10268.93 | AF32: 10268.93 | AH32: =SUM(C32:AG32) -> 308067.9
A33: 2 | B33: 人事工资 | C33: 700 | D33: 700 | E33: 700 | F33: 700 | G33: 700 | H33: 700 | I33: 700 | J33: 700 | K33: 700 | L33: 700 | M33: 700 | N33: 700 | O33: 700 | P33: 700 | Q33: 700 | R33: 700 | S33: 700 | T33: 700 | U33: 700 | V33: 700 | W33: 700 | X33: 700 | Y33: 700 | Z33: 700 | AA33: 700 | AB33: 700 | AC33: 700 | AD33: 700 | AE33: 700 | AF33: 700 | AH33: =SUM(C33:AG33) -> 21000
A34: 3 | B34: 社会保险费 | C34: 1350 | D34: 1350 | E34: 1350 | F34: 1350 | G34: 1350 | H34: 1350 | I34: 1350 | J34: 1350 | K34: 1350 | L34: 1350 | M34: 1350 | N34: 1350 | O34: 1350 | P34: 1350 | Q34: 1350 | R34: 1350 | S34: 1350 | T34: 1350 | U34: 1350 | V34: 1350 | W34: 1350 | X34: 1350 | Y34: 1350 | Z34: 1350 | AA34: 1350 | AB34: 1350 | AC34: 1350 | AD34: 1350 | AE34: 1350 | AF34: 1350 | AH34: =SUM(C34:AG34) -> 40500
A35: 4 | B35: 意外险 | C35: 29.17 | D35: 29.17 | E35: 29.17 | F35: 29.17 | G35: 29.17 | H35: 29.17 | I35: 29.17 | J35: 29.17 | K35: 29.17 | L35: 29.17 | M35: 29.17 | N35: 29.17 | O35: 29.17 | P35: 29.17 | Q35: 29.17 | R35: 29.17 | S35: 29.17 | T35: 29.17 | U35: 29.17 | V35: 29.17 | W35: 29.17 | X35: 29.17 | Y35: 29.17 | Z35: 29.17 | AA35: 29.17 | AB35: 29.17 | AC35: 29.17 | AD35: 29.17 | AE35: 29.17 | AF35: 29.17 | AH35: =SUM(C35:AG35) -> 875.1
A36: 5 | B36: 雇主险 | C36: 34.17 | D36: 34.17 | E36: 34.17 | F36: 34.17 | G36: 34.17 | H36: 34.17 | I36: 34.17 | J36: 34.17 | K36: 34.17 | L36: 34.17 | M36: 34.17 | N36: 34.17 | O36: 34.17 | P36: 34.17 | Q36: 34.17 | R36: 34.17 | S36: 34.17 | T36: 34.17 | U36: 34.17 | V36: 34.17 | W36: 34.17 | X36: 34.17 | Y36: 34.17 | Z36: 34.17 | AA36: 34.17 | AB36: 34.17 | AC36: 34.17 | AD36: 34.17 | AE36: 34.17 | AF36: 34.17 | AH36: =SUM(C36:AG36) -> 1025.1
A37: 6 | B37: 福利费 | AH37: =SUM(C37:AG37) -> 0
A38: 7 | B38: 招聘费 | D38: 80 | E38: 100 | F38: 140 | G38: 220 | H38: 100 | I38: 180 | J38: 280 | K38: 280 | L38: 240 | M38: 220 | N38: 160 | O38: 220 | P38: 220 | Q38: 300 | R38: 400 | S38: 300 | T38: 180 | U38: 340 | V38: 360 | W38: 420 | X38: 340 | Y38: 340 | Z38: 420 | AA38: 420 | AB38: 480 | AC38: 500 | AD38: 440 | AE38: 600 | AF38: 600 | AH38: =SUM(C38:AG38) -> 8880
A39: 8 | B39: 招标代理费 | AH39: =SUM(C39:AG39) -> 0
A40: 9 | B40: 其他 | AH40: =SUM(C40:AG40) -> 0
A41: 10 | B41: 设备维修费 | L41: 330 | AH41: =SUM(C41:AG41) -> 330
...

Sheet 6月处理量
A1: 日 | B1: 新一代查询业务量 （散件外走） | C1: 新一代查询业务量 （分拣封发） | D1: 新一代查询业务量 （总包经转） | E1: 平刷件量(剔除） | F1: 合计
A2: 45809 | B2: 256690 | C2: 522646 | D2: 19473 | E2: 172669 | F2: =SUM(B2:D2)-E2 -> 626140
A3: =A2+1 -> 45810 | B3: 218158 | C3: 473152 | D3: 18667 | E3: 97937 | F3: =SUM(B3:D3)-E3 -> 612040
A4: =A3+1 -> 45811 | B4: 267556 | C4: 436925 | D4: 25058 | E4: 29274 | F4: =SUM(B4:D4)-E4 -> 700265
A5: =A4+1 -> 45812 | B5: 297968 | C5: 472805 | D5: 29548 | E5: 57120 | F5: =SUM(B5:D5)-E5 -> 743201
A6: =A5+1 -> 45813 | B6: 299810 | C6: 512419 | D6: 30641 | E6: 52241 | F6: =SUM(B6:D6)-E6 -> 790629
A7: =A6+1 -> 45814 | B7: 300884 | C7: 511750 | D7: 32255 | E7: 74137 | F7: =SUM(B7:D7)-E7 -> 770752
A8: =A7+1 -> 45815 | B8: 288774 | C8: 642639 | D8: 27851 | E8: 200991 | F8: =SUM(B8:D8)-E8 -> 758273
A9: =A8+1 -> 45816 | B9: 292802 | C9: 590922 | D9: 27227 | E9: 161840 | F9: =SUM(B9:D9)-E9 -> 749111
A10: =A9+1 -> 45817 | B10: 273151 | C10: 495061 | D10: 26143 | E10: 85442 | F10: =SUM(B10:D10)-E10 -> 708913
A11: =A10+1 -> 45818 | B11: 304463 | C11: 487423 | D11: 30054 | E11: 67473 | F11: =SUM(B11:D11)-E11 -> 754467
A12: =A11+1 -> 45819 | B12: 306613 | C12: 510775 | D12: 30774 | E12: 79492 | F12: =SUM(B12:D12)-E12 -> 768670
A13: =A12+1 -> 45820 | B13: 293214 | C13: 495303 | D13: 29333 | E13: 61523 | F13: =SUM(B13:D13)-E13 -> 756327
A14: =A13+1 -> 45821 | B14: 310592 | C14: 513480 | D14: 32843 | E14: 64736 | F14: =SUM(B14:D14)-E14 -> 792179
... A31: =A30+1 -> 45838 | B31: 275507 | C31: 445495 | D31: 28344 | E31: 56287 | F31: =SUM(B31:D31)-E31 -> 693059
A32: =A31+1 -> 45839 | F32: =SUM(B32:D32)-E32 -> 0
A33: 合计 | B33: =SUM(B2:B32) -> 8625514 | C33: =SUM(C2:C32) -> 15406222 | D33: =SUM(D2:D32) -> 838428 | E33: =SUM(E2:E32) -> 2696183 | F33: =SUM(F2:F32) -> 22173981

Sheet 7月日经营数据
A1: 2025年南京项目处理经营情况（7月）
A3: 科目 | C3: 45839 | D3: =C3+1 -> 45840 | E3: =D3+1 -> 45841 | F3: =E3+1 -> 45842 | G3: =F3+1 -> 45843 | H3: =G3+1 -> 45844 | I3: =H3+1 -> 45845 | J3: =I3+1 -> 45846 | K3: =J3+1 -> 45847 | ... AG3: =AF3+1 -> 45869 | AH3: 月度合计
C4: 进口处理 | D4: 进口处理 | E4: 进口处理 | F4: 进口处理 | G4: 进口处理 | H4: 进口处理 | I4: 进口处理 | J4: 进口处理 | K4: 进口处理 | L4: 进口处理 | M4: 进口处理 | N4: 进口处理 | O4: 进口处理 | P4: 进口处理 | Q4: 进口处理 | R4: 进口处理 | S4: 进口处理 | T4: 进口处理 | U4: 进口处理 | V4: 进口处理 | W4: 进口处理 | X4: 进口处理 | Y4: 进口处理 | Z4: 进口处理 | AA4: 进口处理 | AB4: 进口处理 | AC4: 进口处理 | AD4: 进口处理 | AE4: 进口处理 | AF4: 进口处理 | AG4: 进口处理 | AH4: 进口处理
A5: 1 | B5: 散件处理量 | C5: =SUMIFS('7月处理量'!$F:$F,'7月处理量'!$A:$A,C3) -> 683425 | D5: =SUMIFS('7月处理量'!$F:$F,'7月处理量'!$A:$A,D3) -> 703537 | E5: =SUMIFS('7月处理量'!$F:$F,'7月处理量'!$A:$A,E3) -> 690093 | F5: =SUMIFS('7月处理量'!$F:$F,'7月处理量'!$A:$A,F3) -> 729987 | G5: =SUMIFS('7月处理量'!$F:$F,'7月处理量'!$A:$A,G3) -> 749412 | H5: =SUMIFS('7月处理量'!$F:$F,'7月处理量'!$A:$A,H3) -> 708683 | I5: =SUMIFS('7月处理量'!$F:$F,'7月处理量'!$A:$A,I3) -> 702077 | J5: =SUMIFS('7月处理量'!$F:$F,'7月处理量'!$A:$A,J3) -> 734319 | ... AG5: =SUMIFS('7月处理量'!$F:$F,'7月处理量'!$A:$A,AG3) -> 664209 | AH5: =SUM(C5:AG5) -> 21618238
A6: 2 | B6: 散件处理单价 | C6: 0.1667 | D6: 0.1667 | E6: 0.1667 | F6: 0.1667 | G6: 0.1667 | H6: 0.1667 | I6: 0.1667 | J6: 0.1667 | K6: 0.1667 | L6: 0.1667 | M6: 0.1667 | N6: 0.1667 | O6: 0.1667 | P6: 0.1667 | Q6: 0.1667 | R6: 0.1667 | S6: 0.1667 | T6: 0.1667 | U6: 0.1667 | V6: 0.1667 | W6: 0.1667 | X6: 0.1667 | Y6: 0.1667 | Z6: 0.1667 | AA6: 0.1667 | AB6: 0.1667 | AC6: 0.1667 | AD6: 0.1667 | AE6: 0.1667 | AF6: 0.1667 | AG6: 0.1667 | AH6: 0.1667
A7: 3 | B7: 散件处理收入 | C7: 113926.95 | D7: 117279.62 | E7: 115038.5 | F7: 121688.83 | G7: 124926.98 | H7: 118137.46 | I7: 117036.24 | J7: 122410.98 | K7: 125209.7 | L7: 119321.86 | M7: 119553.41 | N7: 118702.9 | O7: 111158.56 | P7: 111273.08 | Q7: 118609.55 | R7: 116172.9 | S7: 120600.78 | T7: 118809.76 | U7: 119655.59 | V7: 116620.15 | W7: 114463.89 | X7: 113714.74 | Y7: 122272.62 | Z7: 116046.87 | AA7: 115470.76 | AB7: 110254.71 | AC7: 110821.33 | AD7: 106690.5 | AE7: 108532.04 | AF7: 108635.39 | AG7: 110723.64 | AH7: =SUM(C7:AG7) -> 3603760.3
A8: 4 | B8: 考核扣款 | C8: 3000 | D8: 3000 | E8: 3000 | F8: 3000 | G8: 3000 | H8: 3000 | I8: 3000 | J8: 3000 | K8: 3000 | L8: 3000 | M8: 3000 | N8: 3000 | O8: 3000 | P8: 3000 | Q8: 3000 | R8: 3000 | S8: 3000 | T8: 3000 | U8: 3000 | V8: 3000 | W8: 3000 | X8: 3000 | Y8: 3000 | Z8: 3000 | AA8: 3000 | AB8: 3000 | AC8: 3000 | AD8: 3000 | AE8: 3000 | AF8: 3000 | AG8: 3000 | AH8: =SUM(C8:AG8) -> 93000
A9: 5 | B9: 补贴费用 | AH9: =SUM(C9:AG9) -> 0
A10: 6 | B10: 开票金额 | C10: 110926.95 | D10: 114279.62 | E10: 112038.5 | F10: 118688.83 | G10: 121926.98 | H10: 115137.46 | I10: 114036.24 | J10: 119410.98 | K10: 122209.7 | L10: 116321.86 | M10: 116553.41 | N10: 115702.9 | O10: 108158.56 | P10: 108273.08 | Q10: 115609.55 | R10: 113172.9 | S10: 117600.78 | T10: 115809.76 | U10: 116655.59 | V10: 113620.15 | W10: 111463.89 | X10: 110714.74 | Y10: 119272.62 | Z10: 113046.87 | AA10: 112470.76 | AB10: 107254.71 | AC10: 107821.33 | AD10: 103690.5 | AE10: 105532.04 | AF10: 105635.39 | AG10: 107723.64 | AH10: =SUM(C10:AG10) -> 3510760.3
A11: 一、主营业务收入总计 | C11: 104648.07 | D11: 107810.96 | E11: 105696.7 | F11: 111970.59 | G11: 115025.45 | H11: 108620.25 | I11: 107581.36 | J11: 112651.87 | K11: 115292.17 | L11: 109737.6 | M11: 109956.05 | N11: 109153.68 | O11: 102036.38 | P11: 102144.42 | Q11: 109065.61 | R11: 106766.89 | S11: 110944.13 | T11: 109254.49 | U11: 110052.44 | V11: 107188.82 | W11: 105154.61 | X11: 104447.87 | Y11: 112521.34 | Z11: 106647.99 | AA11: 106104.49 | AB11: 101183.69 | AC11: 101718.24 | AD11: 97821.23 | AE11: 99558.53 | AF11: 99656.03 | AG11: 101626.08 | AH11: =SUM(C11:AG11) -> 3312038
A12: 1 | B12: 管理人员数量 | C12: 21 | D12: 22 | E12: 20 | F12: 24 | G12: 22 | H12: 22 | I12: 20 | J12: 21 | K12: 21 | L12: 23 | M12: 23 | N12: 24 | O12: 20 | P12: 21 | Q12: 21 | R12: 19 | S12: 21 | T12: 21 | U12: 22 | V12: 22 | W12: 20 | X12: 21 | Y12: 20 | Z12: 20 | AA12: 21 | AB12: 20 | AC12: 21 | AD12: 21 | AE12: 21 | AF12: 23 | AG12: 24 | AH12: =SUM(C12:AG12) -> 662
A13: 2 | B13: 自有员工数量 | C13: 286 | D13: 293 | E13: 285 | F13: 270 | G13: 269 | H13: 278 | I13: 265 | J13: 278 | K13: 277 | L13: 288 | M13: 291 | N13: 281 | O13: 287 | P13: 279 | Q13: 285 | R13: 268 | S13: 283 | T13: 276 | U13: 286 | V13: 284 | W13: 280 | X13: 286 | Y13: 292 | Z13: 290 | AA13: 293 | AB13: 297 | AC13: 301 | AD13: 296 | AE13: 302 | AF13: 301 | AG13: 306 | AH13: =SUM(C13:AG13) -> 8853
A14: 3 | B14: 劳务人员数量 | C14: 55 | D14: 64 | E14: 77 | F14: 95 | G14: 93 | H14: 86 | I14: 79 | J14: 118 | K14: 114 | L14: 105 | M14: 96 | N14: 84 | O14: 90 | P14: 78 | Q14: 84 | R14: 94 | S14: 94 | T14: 94 | U14: 93 | V14: 89 | W14: 84 | X14: 88 | Y14: 89 | Z14: 86 | AA14: 85 | AB14: 76 | AC14: 65 | AD14: 65 | AE14: 64 | AF14: 60 | AG14: 57 | AH14: =SUM(C14:AG14) -> 2601
A15: 4 | B15: 总人数 | C15: 362 | D15: 379 | E15: 382 | F15: 389 | G15: 384 | H15: 386 | I15: 364 | J15: 417 | K15: 412 | L15: 416 | M15: 410 | N15: 389 | O15: 397 | P15: 378 | Q15: 390 | R15: 381 | S15: 398 | T15: 391 | U15: 401 | V15: 395 | W15: 384 | X15: 395 | Y15: 401 | Z15: 396 | AA15: 399 | AB15: 393 | AC15: 387 | AD15: 382 | AE15: 387 | AF15: 384 | AG15: 387 | AH15: =SUM(C15:AG15) -> 12116
A16: 5 | B16: 总工时 | C16: 3895 | D16: 4096.5 | E16: 4160 | F16: 4172 | G16: 4148 | H16: 4179.5 | I16: 3942 | J16: 4632 | K16: 4475.5 | L16: 4497.5 | M16: 4408.5 | N16: 4136 | O16: 4266.5 | P16: 4034 | Q16: 4195.5 | R16: 4110.5 | S16: 4294.5 | T16: 4200.5 | U16: 4323 | V16: 4104 | W16: 4158 | X16: 4257.5 | Y16: 4326 | Z16: 4286 | AA16: 4282.5 | AB16: 4153 | AC16: 4125 | AD16: 4046 | AE16: 4056 | AF16: 4054.5 | AG16: 4105 | AH16: =SUM(C16:AG16) -> 130120.5
A17: 人均效能 | C17: 1887.9144 | D17: 1856.2982 | E17: 1806.5262 | F17: 1876.5733 | G17: 1951.5938 | H17: 1835.9663 | I17: 1928.783 | J17: 1760.9568 | K17: 1823.0777 | L17: 1720.6442 | M17: 1749.2122 | N17: 1830.527 | O17: 1679.6423 | P17: 1765.8862 | Q17: 1824.3974 | R17: 1829.1286 | S17: 1817.7387 | T17: 1822.8031 | U17: 1790 | V17: 1771.0911 | W17: 1788.1406 | X17: 1726.9671 | Y17: 1829.1496 | Z17: 1757.9343 | AA17: 1736.0551 | AB17: 1682.9415 | AC17: 1717.8165 | AD17: 1675.4319 | AE17: 1682.3307 | AF17: 1697.0885 | AG17: 1716.3023 | AH17: =AH5/AH15 -> 1784.2719
A18: 人均小时效能 | C18: 175.46213 | D18: 171.741 | E18: 165.88774 | F18: 174.97291 | G18: 180.66827 | H18: 169.56167 | I18: 178.10173 | J18: 158.53174 | K18: 167.82661 | L18: 159.15242 | M18: 162.6805 | N18: 172.16514 | O18: 156.29157 | P18: 165.46976 | Q18: 169.59004 | R18: 169.54093 | S18: 168.46199 | T18: 169.67409 | U18: 166.03979 | V18: 170.46321 | W18: 165.13853 | X18: 160.22361 | Y18: 169.55363 | Z18: 162.42231 | AA18: 161.74804 | AB18: 159.2574 | AC18: 161.16242 | AD18: 158.18463 | AE18: 160.51824 | AF18: 160.73055 | AG18: 161.80487 | AH18: =AH5/AH16 -> 166.14014
A19: 1 | B19: 自有员工工资 | C19: 59652.25 | D19: 61528.1 | E19: 59889.45 | F19: 56227.95 | G19: 56326.8 | H19: 58400.05 | I19: 55526.75 | J19: 59850 | K19: 57844 | L19: 60315.2 | M19: 60539.65 | N19: 57976.4 | O19: 59176.25 | P19: 57453.45 | Q19: 59159.25 | R19: 55455.9 | S19: 58798.8 | T19: 57169.45 | U19: 59593.7 | V19: 56528.35 | W19: 58453.15 | X19: 59473.7 | Y19: 60504.75 | Z19: 60355.8 | AA19: 60560.05 | AB19: 60111.8 | AC19: 61955.05 | AD19: 60504.75 | AE19: 60909.25 | AF19: 61667.45 | AG19: 63222.15 | AH19: =SUM(C19:AG19) -> 1835129.6
A20: 2 | B20: 员工宿舍费 | C20: 19500 | AH20: =SUM(C20:AG20) -> 19500
A21: 3 | B21: 意外险 | C21: 278.06 | D21: 284.86 | E21: 277.08 | F21: 262.5 | G21: 261.53 | H21: 270.28 | I21: 257.64 | J21: 270.28 | K21: 269.31 | L21: 280 | M21: 282.92 | N21: 273.19 | O21: 279.03 | P21: 271.25 | Q21: 277.08 | R21: 260.56 | S21: 275.14 | T21: 268.33 | U21: 278.06 | V21: 276.11 | W21: 272.22 | X21: 278.06 | Y21: 283.89 | Z21: 281.94 | AA21: 284.86 | AB21: 288.75 | AC21: 292.64 | AD21: 287.78 | AE21: 293.61 | AF21: 292.64 | AG21: 297.5 | AH21: =SUM(C21:AG21) -> 8607.1
A22: 4 | B22: 雇主险 | C22: 325.72 | D22: 333.69 | E22: 324.58 | F22: 307.5 | G22: 306.36 | H22: 316.61 | I22: 301.81 | J22: 316.61 | K22: 315.47 | L22: 328 | M22: 331.42 | N22: 320.03 | O22: 326.86 | P22: 317.75 | Q22: 324.58 | R22: 305.22 | S22: 322.31 | T22: 314.33 | U22: 325.72 | V22: 323.44 | W22: 318.89 | X22: 325.72 | Y22: 332.56 | Z22: 330.28 | AA22: 333.69 | AB22: 338.25 | AC22: 342.81 | AD22: 337.11 | AE22: 343.94 | AF22: 342.81 | AG22: 348.5 | AH22: =SUM(C22:AG22) -> 10082.57
A23: 5 | B23: 员工餐费 | C23: 2456 | D23: 2520 | E23: 2440 | F23: 2352 | G23: 2328 | H23: 2400 | I23: 2280 | J23: 2392 | K23: 2384 | L23: 2488 | M23: 2512 | N23: 2440 | O23: 2456 | P23: 2400 | Q23: 2448 | R23: 2296 | S23: 2432 | T23: 2376 | U23: 2464 | V23: 2448 | W23: 2400 | X23: 2456 | Y23: 2496 | Z23: 2480 | AA23: 2512 | AB23: 2536 | AC23: 2576 | AD23: 2536 | AE23: 2584 | AF23: 2592 | AG23: 2640 | AH23: =SUM(C23:AG23) -> 76120
A24: 6 | B24: 高温福利费用 | D24: 1200 | E24: 5114 | F24: 12120 | G24: 1120 | H24: 1120 | I24: 1120 | J24: 1120 | K24: 1120 | L24: 1120 | M24: 560 | P24: 1120 | Q24: 1120 | R24: 1120 | S24: 1120 | T24: 1120 | U24: 1120 | V24: 1120 | W24: 1120 | Y24: 1120 | Z24: 1120 | AA24: 1120 | AB24: 1120 | AC24: 1120 | AD24: 1120 | AE24: 1120 | AF24: 560 | AH24: =SUM(C24:AG24) -> 43074
A25: 7 | B25: 劳务人员工资 | C25: 14536 | D25: 16916.5 | E25: 20355 | F25: 25012.5 | G25: 24495 | H25: 22563 | I25: 20792 | J25: 30958 | K25: 29865.5 | L25: 27577 | M25: 25277 | N25: 22126 | O25: 23701.5 | P25: 20516 | Q25: 22103 | R25: 24679 | S25: 24713.5 | T25: 24656 | U25: 24414.5 | V25: 23402.5 | W25: 22091.5 | X25: 23161 | Y25: 23402.5 | Z25: 22620.5 | AA25: 22321.5 | AB25: 20033 | AC25: 17192.5 | AD25: 17192.5 | AE25: 16928 | AF25: 15870 | AG25: 15076.5 | AH25: =SUM(C25:AG25) -> 684549
A26: 8 | B26: 物料采购 | C26: 1964.06 | D26: 27100 | P26: 1777.2 | V26: 466 | AA26: 1020 | AC26: 4860 | AH26: =SUM(C26:AG26) -> 37187.26
A27: 9 | B27: 工单赔付 | C27: 3225.81 | D27: 3225.81 | E27: 3225.81 | F27: 3225.81 | G27: 3225.81 | H27: 3225.81 | I27: 3225.81 | J27: 3225.81 | K27: 3225.81 | L27: 3225.81 | M27: 3225.81 | N27: 3225.81 | O27: 3225.81 | P27: 3225.81 | Q27: 3225.81 | R27: 3225.81 | S27: 3225.81 | T27: 3225.81 | U27: 3225.81 | V27: 3225.81 | W27: 3225.81 | X27: 3225.81 | Y27: 3225.81 | Z27: 3225.81 | AA27: 3225.81 | AB27: 3225.81 | AC27: 3225.81 | AD27: 3225.81 | AE27: 3225.81 | AF27: 3225.81 | AG27: 3225.81 | AH27: =SUM(C27:AG27) -> 100000.11
A28: 10 | B28: 设备成本摊销 | C28: 33957.7 | D28: 33957.7 | E28: 33957.7 | F28: 33957.7 | G28: 33957.7 | H28: 33957.7 | I28: 33957.7 | J28: 33957.7 | K28: 33957.7 | L28: 33957.7 | M28: 33957.7 | N28: 33957.7 | O28: 33957.7 | P28: 33957.7 | Q28: 33957.7 | R28: 33957.7 | S28: 33957.7 | T28: 33957.7 | U28: 33957.7 | V28: 33957.7 | W28: 33957.7 | X28: 33957.7 | Y28: 33957.7 | Z28: 33957.7 | AA28: 33957.7 | AB28: 33957.7 | AC28: 33957.7 | AD28: 33957.7 | AE28: 33957.7 | AF28: 33957.7 | AG28: 33957.7 | AH28: =SUM(C28:AG28) -> 1052688.7
A29: 二、主营业务成本总计 | C29: 135895.6 | D29: 147066.66 | E29: 125583.62 | F29: 133465.96 | G29: 122021.2 | H29: 122253.45 | I29: 117461.71 | J29: 132090.4 | K29: 128981.79 | L29: 129291.71 | M29: 126686.5 | N29: 120319.13 | O29: 123123.15 | P29: 121039.16 | Q29: 122615.42 | R29: 121300.19 | S29: 124845.26 | T29: 123087.62 | U29: 125379.49 | V29: 121747.91 | W29: 121839.27 | X29: 122877.99 | Y29: 125323.21 | Z29: 124372.03 | AA29: 125335.61 | AB29: 121611.31 | AC29: 125522.51 | AD29: 119161.65 | AE29: 119362.31 | AF29: 118508.41 | AG29: 118768.16 | AH29: =SUM(AH19:AH28) -> 3866938.4
A30: 主营业务税金及附加 | C30: 753.47 | D30: 776.24 | E30: 761.02 | F30: 806.19 | G30: 828.18 | H30: 782.07 | I30: 774.59 | J30: 811.09 | K30: 830.1 | L30: 790.11 | M30: 791.68 | N30: 785.91 | O30: 734.66 | P30: 735.44 | Q30: 785.27 | R30: 768.72 | S30: 798.8 | T30: 786.63 | U30: 792.38 | V30: 771.76 | W30: 757.11 | X30: 752.02 | Y30: 810.15 | Z30: 767.87 | AA30: 763.95 | AB30: 728.52 | AC30: 732.37 | AD30: 704.31 | AE30: 716.82 | AF30: 717.52 | AG30: 731.71 | AH30: =SUM(C30:AG30) -> 23846.66
A31: 三、主营业务利润（亏损以“-”号填列) | C31: -32001 | D31: -40031.94 | E31: -20647.94 | F31: -22301.56 | G31: -7823.93 | H31: -14415.27 | I31: -10654.94 | J31: -20249.62 | K31: -14519.72 | L31: -20344.22 | M31: -17522.13 | N31: -11951.36 | O31: -21821.43 | P31: -19630.18 | Q31: -14335.08 | R31: -15302.02 | S31: -14699.93 | T31: -14619.76 | U31: -16119.43 | V31: -15330.85 | W31: -17441.77 | X31: -19182.14 | Y31: -13612.02 | Z31: -18491.91 | AA31: -19995.07 | AB31: -21156.14 | AC31: -24536.64 | AD31: -22044.73 | AE31: -20520.6 | AF31: -19569.9 | AG31: -17873.79 | AH31: =AH11-AH29-AH30 -> -578747.02
A32: 1 | B32: 管理人员工资 | C32: 9937.68 | D32: 9937.68 | E32: 9937.68 | F32: 9937.68 | G32: 9937.68 | H32: 9937.68 | I32: 9937.68 | J32: 9937.68 | K32: 9937.68 | L32: 9937.68 | M32: 9937.68 | N32: 9937.68 | O32: 9937.68 | P32: 9937.68 | Q32: 9937.68 | R32: 9937.68 | S32: 9937.68 | T32: 9937.68 | U32: 9937.68 | V32: 9937.68 | W32: 9937.68 | X32: 9937.68 | Y32: 9937.68 | Z32: 9937.68 | AA32: 9937.68 | AB32: 9937.68 | AC32: 9937.68 | AD32: 9937.68 | AE32: 9937.68 | AF32: 9937.68 | AG32: 9937.68 | AH32: =SUM(C32:AG32) -> 308068.08
A33: 2 | B33: 人事工资 | C33: 677.42 | D33: 677.42 | E33: 677.42 | F33: 677.42 | G33: 677.42 | H33: 677.42 | I33: 677.42 | J33: 677.42 | K33: 677.42 | L33: 677.42 | M33: 677.42 | N33: 677.42 | O33: 677.42 | P33: 677.42 | Q33: 677.42 | R33: 677.42 | S33: 677.42 | T33: 677.42 | U33: 677.42 | V33: 677.42 | W33: 677.42 | X33: 677.42 | Y33: 677.42 | Z33: 677.42 | AA33: 677.42 | AB33: 677.42 | AC33: 677.42 | AD33: 677.42 | AE33: 677.42 | AF33: 677.42 | AG33: 677.42 | AH33: =SUM(C33:AG33) -> 21000.02
A34: 3 | B34: 社会保险费 | C34: 1306.4516 | D34: 1306.4516 | E34: 1306.4516 | F34: 1306.4516 | G34: 1306.4516 | H34: 1306.4516 | I34: 1306.4516 | J34: 1306.4516 | K34: 1306.4516 | L34: 1306.4516 | M34: 1306.4516 | N34: 1306.4516 | O34: 1306.4516 | P34: 1306.4516 | Q34: 1306.4516 | R34: 1306.4516 | S34: 1306.4516 | T34: 1306.4516 | U34: 1306.4516 | V34: 1306.4516 | W34: 1306.4516 | X34: 1306.4516 | Y34: 1306.4516 | Z34: 1306.4516 | AA34: 1306.4516 | AB34: 1306.4516 | AC34: 1306.4516 | AD34: 1306.4516 | AE34: 1306.4516 | AF34: 1306.4516 | AG34: 1306.4516 | AH34: =SUM(C34:AG34) -> 40500
A35: 4 | B35: 意外险 | C35: 29.17 | D35: 29.17 | E35: 29.17 | F35: 29.17 | G35: 29.17 | H35: 29.17 | I35: 29.17 | J35: 29.17 | K35: 29.17 | L35: 29.17 | M35: 29.17 | N35: 29.17 | O35: 29.17 | P35: 29.17 | Q35: 29.17 | R35: 29.17 | S35: 29.17 | T35: 29.17 | U35: 29.17 | V35: 29.17 | W35: 29.17 | X35: 29.17 | Y35: 29.17 | Z35: 29.17 | AA35: 29.17 | AB35: 29.17 | AC35: 29.17 | AD35: 29.17 | AE35: 29.17 | AF35: 29.17 | AG35: 29.17 | AH35: =SUM(C35:AG35) -> 904.27
A36: 5 | B36: 雇主险 | C36: 34.17 | D36: 34.17 | E36: 34.17 | F36: 34.17 | G36: 34.17 | H36: 34.17 | I36: 34.17 | J36: 34.17 | K36: 34.17 | L36: 34.17 | M36: 34.17 | N36: 34.17 | O36: 34.17 | P36: 34.17 | Q36: 34.17 | R36: 34.17 | S36: 34.17 | T36: 34.17 | U36: 34.17 | V36: 34.17 | W36: 34.17 | X36: 34.17 | Y36: 34.17 | Z36: 34.17 | AA36: 34.17 | AB36: 34.17 | AC36: 34.17 | AD36: 34.17 | AE36: 34.17 | AF36: 34.17 | AG36: 34.17 | AH36: =SUM(C36:AG36) -> 1059.27
A37: 6 | B37: 福利费 | AH37: =SUM(C37:AG37) -> 0
A38: 7 | B38: 招聘费 | C38: 204880 | D38: 460 | E38: 440 | F38: 360 | G38: 340 | H38: 380 | I38: 340 | J38: 420 | K38: 380 | L38: 380 | M38: 300 | N38: 420 | O38: 300 | P38: 300 | Q38: 400 | R38: 360 | S38: 320 | T38: 280 | U38: 320 | V38: 280 | W38: 360 | X38: 340 | Y38: 420 | Z38: 340 | AA38: 360 | AB38: 380 | AC38: 380 | AD38: 340 | AE38: 360 | AF38: 380 | AG38: 360 | AH38: =SUM(C38:AG38) -> 215680
A39: 8 | B39: 招标代理费 | AH39: =SUM(C39:AG39) -> 0
A40: 9 | B40: 其他 | AH40: =SUM(C40:AG40) -> 0
A41: 10 | B41: 设备维修费 | AH41: =SUM(C41:AG41) -> 0
...

Sheet 7月处理量
A1: 日 | B1: 新一代查询业务量 （散件外走） | C1: 新一代查询业务量 （分拣封发） | D1: 新一代查询业务量 （总包经转） | E1: 平刷件量(剔除） | F1: 合计
A2: 45839 | B2: 273309 | C2: 434710 | D2: 29670 | E2: 54264 | F2: =SUM(B2:D2)-E2 -> 683425
A3: =A2+1 -> 45840 | B3: 272222 | C3: 452733 | D3: 29157 | E3: 50575 | F3: =SUM(B3:D3)-E3 -> 703537
A4: =A3+1 -> 45841 | B4: 257205 | C4: 461131 | D4: 27925 | E4: 56168 | F4: =SUM(B4:D4)-E4 -> 690093
A5: =A4+1 -> 45842 | B5: 276720 | C5: 488345 | D5: 30491 | E5: 65569 | F5: =SUM(B5:D5)-E5 -> 729987
A6: =A5+1 -> 45843 | B6: 285230 | C6: 484235 | D6: 27547 | E6: 47600 | F6: =SUM(B6:D6)-E6 -> 749412
A7: =A6+1 -> 45844 | B7: 292697 | C7: 477917 | D7: 21964 | E7: 83895 | F7: =SUM(B7:D7)-E7 -> 708683
A8: =A7+1 -> 45845 | B8: 272889 | C8: 460241 | D8: 24996 | E8: 56049 | F8: =SUM(B8:D8)-E8 -> 702077
A9: =A8+1 -> 45846 | B9: 281580 | C9: 492283 | D9: 28167 | E9: 67711 | F9: =SUM(B9:D9)-E9 -> 734319
A10: =A9+1 -> 45847 | B10: 292358 | C10: 499517 | D10: 28253 | E10: 69020 | F10: =SUM(B10:D10)-E10 -> 751108
A11: =A10+1 -> 45848 | B11: 277205 | C11: 483220 | D11: 28072 | E11: 72709 | F11: =SUM(B11:D11)-E11 -> 715788
A12: =A11+1 -> 45849 | B12: 294003 | C12: 477121 | D12: 30543 | E12: 84490 | F12: =SUM(B12:D12)-E12 -> 717177
A13: =A12+1 -> 45850 | B13: 289464 | C13: 471614 | D13: 24777 | E13: 73780 | F13: =SUM(B13:D13)-E13 -> 712075
A14: =A13+1 -> 45851 | B14: 272432 | C14: 440130 | D14: 20896 | E14: 66640 | F14: =SUM(B14:D14)-E14 -> 666818
... A32: =A31+1 -> 45869 | B32: 273807 | C32: 420393 | D32: 27367 | E32: 57358 | F32: =SUM(B32:D32)-E32 -> 664209
A33: 合计 | B33: =SUM(B2:B32) -> 8798741 | C33: =SUM(C2:C32) -> 13962355 | D33: =SUM(D2:D32) -> 837421 | E33: =SUM(E2:E32) -> 1980279 | F33: =SUM(F2:F32) -> 21618238

Sheet 8月日经营数据
A1: 2025年南京项目处理经营情况（8月）
A3: 科目 | C3: 45870 | D3: =C3+1 -> 45871 | E3: =D3+1 -> 45872 | F3: =E3+1 -> 45873 | G3: =F3+1 -> 45874 | H3: =G3+1 -> 45875 | I3: =H3+1 -> 45876 | J3: =I3+1 -> 45877 | K3: =J3+1 -> 45878 | ... AG3: =AF3+1 -> 45900 | AH3: 月度合计
C4: 进口处理 | D4: 进口处理 | E4: 进口处理 | F4: 进口处理 | G4: 进口处理 | H4: 进口处理 | I4: 进口处理 | J4: 进口处理 | K4: 进口处理 | L4: 进口处理 | M4: 进口处理 | N4: 进口处理 | O4: 进口处理 | P4: 进口处理 | Q4: 进口处理 | R4: 进口处理 | S4: 进口处理 | T4: 进口处理 | U4: 进口处理 | V4: 进口处理 | W4: 进口处理 | X4: 进口处理 | Y4: 进口处理 | Z4: 进口处理 | AA4: 进口处理 | AB4: 进口处理 | AC4: 进口处理 | AD4: 进口处理 | AE4: 进口处理 | AF4: 进口处理 | AG4: 进口处理 | AH4: 进口处理
A5: 1 | B5: 散件处理量 | C5: =SUMIFS('8月处理量'!$F:$F,'8月处理量'!$A:$A,C3) -> 650583 | D5: =SUMIFS('8月处理量'!$F:$F,'8月处理量'!$A:$A,D3) -> 676353 | E5: =SUMIFS('8月处理量'!$F:$F,'8月处理量'!$A:$A,E3) -> 672508 | F5: =SUMIFS('8月处理量'!$F:$F,'8月处理量'!$A:$A,F3) -> 650310 | G5: =SUMIFS('8月处理量'!$F:$F,'8月处理量'!$A:$A,G3) -> 665521 | H5: =SUMIFS('8月处理量'!$F:$F,'8月处理量'!$A:$A,H3) -> 673181 | I5: =SUMIFS('8月处理量'!$F:$F,'8月处理量'!$A:$A,I3) -> 696859 | J5: =SUMIFS('8月处理量'!$F:$F,'8月处理量'!$A:$A,J3) -> 719725 | ... AG5: =SUMIFS('8月处理量'!$F:$F,'8月处理量'!$A:$A,AG3) -> 814355 | AH5: =SUM(C5:AG5) -> 23084927
A6: 2 | B6: 散件处理单价 | C6: 0.1667 | D6: 0.1667 | E6: 0.1667 | F6: 0.1667 | G6: 0.1667 | H6: 0.1667 | I6: 0.1667 | J6: 0.1667 | K6: 0.1667 | L6: 0.1667 | M6: 0.1667 | N6: 0.1667 | O6: 0.1667 | P6: 0.1667 | Q6: 0.1667 | R6: 0.1667 | S6: 0.1667 | T6: 0.1667 | U6: 0.1667 | V6: 0.1667 | W6: 0.1667 | X6: 0.1667 | Y6: 0.1667 | Z6: 0.1667 | AA6: 0.1667 | AB6: 0.1667 | AC6: 0.1667 | AD6: 0.1667 | AE6: 0.1667 | AF6: 0.1667 | AG6: 0.1667 | AH6: 0.1667
A7: 3 | B7: 散件处理收入 | C7: 108452.19 | D7: 112748.05 | E7: 112107.08 | F7: 108406.68 | G7: 110942.35 | H7: 112219.27 | I7: 116166.4 | J7: 119978.16 | K7: 121927.05 | L7: 120215.54 | M7: 116337.1 | N7: 124153.66 | O7: 126516.8 | P7: 125182.36 | Q7: 129195.33 | R7: 123420.01 | S7: 122304.12 | T7: 120253.71 | U7: 120605.12 | V7: 129143.66 | W7: 129437.72 | X7: 128388.01 | Y7: 134371.7 | Z7: 131346.6 | AA7: 125043.5 | AB7: 133961.79 | AC7: 134925.48 | AD7: 138534.7 | AE7: 138236.64 | AF7: 137983.59 | AG7: 135752.98 | AH7: =SUM(C7:AG7) -> 3848257.4
A8: 4 | B8: 考核扣款 | C8: 3000 | D8: 3000 | E8: 3000 | F8: 3000 | G8: 3000 | H8: 3000 | I8: 3000 | J8: 3000 | K8: 3000 | L8: 3000 | M8: 3000 | N8: 3000 | O8: 3000 | P8: 3000 | Q8: 3000 | R8: 3000 | S8: 3000 | T8: 3000 | U8: 3000 | V8: 3000 | W8: 3000 | X8: 3000 | Y8: 3000 | Z8: 3000 | AA8: 3000 | AB8: 3000 | AC8: 3000 | AD8: 3000 | AE8: 3000 | AF8: 3000 | AG8: 3000 | AH8: =SUM(C8:AG8) -> 93000
A9: 5 | B9: 补贴费用 | AH9: =SUM(C9:AG9) -> 0
A10: 6 | B10: 开票金额 | C10: 105452.19 | D10: 109748.05 | E10: 109107.08 | F10: 105406.68 | G10: 107942.35 | H10: 109219.27 | I10: 113166.4 | J10: 116978.16 | K10: 118927.05 | L10: 117215.54 | M10: 113337.1 | N10: 121153.66 | O10: 123516.8 | P10: 122182.36 | Q10: 126195.33 | R10: 120420.01 | S10: 119304.12 | T10: 117253.71 | U10: 117605.12 | V10: 126143.66 | W10: 126437.72 | X10: 125388.01 | Y10: 131371.7 | Z10: 128346.6 | AA10: 122043.5 | AB10: 130961.79 | AC10: 131925.48 | AD10: 135534.7 | AE10: 135236.64 | AF10: 134983.59 | AG10: 132752.98 | AH10: =SUM(C10:AG10) -> 3755257.4
A11: 一、主营业务收入总计 | C11: 99483.2 | D11: 103535.9 | E11: 102931.21 | F11: 99440.26 | G11: 101832.41 | H11: 103037.05 | I11: 106760.75 | J11: 110356.75 | K11: 112195.33 | L11: 110580.7 | M11: 106921.79 | N11: 114295.91 | O11: 116525.28 | P11: 115266.38 | Q11: 119052.2 | R11: 113603.78 | S11: 112551.06 | T11: 110616.71 | U11: 110948.23 | V11: 119003.45 | W11: 119280.87 | X11: 118290.58 | Y11: 123935.57 | Z11: 121081.7 | AA11: 115135.38 | AB11: 123548.86 | AC11: 124458 | AD11: 127862.92 | AE11: 127581.74 | AF11: 127343.01 | AG11: 125238.66 | AH11: =SUM(C11:AG11) -> 3542695.6
A12: 1 | B12: 管理人员数量 | C12: 23 | D12: 23 | E12: 23 | F12: 23 | G12: 20 | H12: 22 | I12: 22 | J12: 23 | K12: 22 | L12: 24 | M12: 21 | N12: 20 | O12: 20 | P12: 21 | Q12: 21 | R12: 23 | S12: 24 | T12: 25 | U12: 25 | V12: 21 | W12: 21 | X12: 23 | Y12: 22 | Z12: 19 | AA12: 19 | AB12: 22 | AC12: 20 | AD12: 21 | AE12: 21 | AF12: 22 | AG12: 23 | AH12: =SUM(C12:AG12) -> 679
A13: 2 | B13: 自有员工数量 | C13: 296 | D13: 294 | E13: 294 | F13: 291 | G13: 299 | H13: 292 | I13: 290 | J13: 300 | K13: 299 | L13: 291 | M13: 301 | N13: 304 | O13: 308 | P13: 298 | Q13: 294 | R13: 283 | S13: 290 | T13: 287 | U13: 293 | V13: 294 | W13: 292 | X13: 283 | Y13: 292 | Z13: 283 | AA13: 284 | AB13: 295 | AC13: 300 | AD13: 305 | AE13: 290 | AF13: 289 | AG13: 281 | AH13: =SUM(C13:AG13) -> 9092
A14: 3 | B14: 劳务人员数量 | C14: 63 | D14: 65 | E14: 64 | F14: 65 | G14: 63 | H14: 57 | I14: 64 | J14: 58 | K14: 61 | L14: 58 | M14: 60 | N14: 63 | O14: 60 | P14: 65 | Q14: 65 | R14: 63 | S14: 63 | T14: 71 | U14: 67 | V14: 67 | W14: 61 | X14: 58 | Y14: 80 | Z14: 86 | AA14: 76 | AB14: 74 | AC14: 66 | AD14: 70 | AE14: 74 | AF14: 69 | AG14: 75 | AH14: =SUM(C14:AG14) -> 2051
A15: 4 | B15: 总人数 | C15: 382 | D15: 382 | E15: 381 | F15: 379 | G15: 382 | H15: 371 | I15: 376 | J15: 381 | K15: 382 | L15: 373 | M15: 382 | N15: 387 | O15: 388 | P15: 384 | Q15: 380 | R15: 369 | S15: 377 | T15: 383 | U15: 385 | V15: 382 | W15: 374 | X15: 364 | Y15: 394 | Z15: 388 | AA15: 379 | AB15: 391 | AC15: 386 | AD15: 396 | AE15: 385 | AF15: 380 | AG15: 379 | AH15: =SUM(C15:AG15) -> 11822
A16: 5 | B16: 总工时 | C16: 3975.5 | D16: 3991 | E16: 3950.5 | F16: 3928.5 | G16: 4008.5 | H16: 3875.5 | I16: 3912 | J16: 3986 | K16: 3999 | L16: 3868.5 | M16: 4008.5 | N16: 4071.5 | O16: 4115.5 | P16: 4032 | Q16: 3988 | R16: 3840.5 | S16: 3951.5 | T16: 3971.5 | U16: 4053.5 | V16: 4032.5 | W16: 3956.5 | X16: 3834 | Y16: 4174.5 | Z16: 4150.5 | AA16: 4062 | AB16: 4156 | AC16: 4099.5 | AD16: 4190.5 | AE16: 4084.5 | AF16: 4058 | AG16: 4049 | AH16: =SUM(C16:AG16) -> 124375
A17: 人均效能 | C17: 1703.0969 | D17: 1770.5576 | E17: 1765.1129 | F17: 1715.8575 | G17: 1742.2016 | H17: 1814.504 | I17: 1853.3484 | J17: 1889.042 | K17: 1914.7016 | L17: 1933.3753 | M17: 1826.9188 | N17: 1924.478 | O17: 1956.0541 | P17: 1955.5833 | Q17: 2039.5184 | R17: 2006.4282 | S17: 1946.0955 | T17: 1883.4935 | U17: 1879.1844 | V17: 2028.0288 | W17: 2076.1257 | X17: 2115.8626 | Y17: 2045.8604 | Z17: 2030.7268 | AA17: 1979.1847 | AB17: 2055.2685 | AC17: 2096.8679 | AD17: 2098.5909 | AE17: 2153.9065 | AF17: 2178.2526 | AG17: 2148.6939 | AH17: =AH5/AH15 -> 1952.7091
A18: 人均小时效能 | C18: 163.64809 | D18: 169.46956 | E18: 170.23364 | F18: 165.53646 | G18: 166.02744 | H18: 173.70172 | I18: 178.13369 | J18: 180.56322 | K18: 182.89972 | L18: 186.41566 | M18: 174.10079 | N18: 182.92349 | O18: 184.41234 | P18: 186.24603 | Q18: 194.33726 | R18: 192.78011 | S18: 185.67076 | T18: 181.63868 | U18: 178.48427 | V18: 192.11581 | W18: 196.25199 | X18: 200.88002 | Y18: 193.09354 | Z18: 189.83785 | AA18: 184.66544 | AB18: 193.36141 | AC18: 197.43652 | AD18: 198.31571 | AE18: 203.02461 | AF18: 203.97634 | AG18: 201.12497 | AH18: =AH5/AH16 -> 185.60745
A19: 1 | B19: 自有员工工资 | C19: 59439.6 | D19: 59480.7 | E19: 59509.1 | F19: 58681.75 | G19: 60596.55 | H19: 59274.5 | I19: 58584.85 | J19: 61183.55 | K19: 60814.5 | L19: 58973.7 | M19: 61263.3 | N19: 61787.65 | O19: 63130.85 | P19: 60574 | Q19: 59685 | R19: 57288.45 | S19: 59408.75 | T19: 58230.25 | U19: 60568.2 | V19: 60085.75 | W19: 60023.25 | X19: 58364.55 | Y19: 59934.5 | Z19: 58262.6 | AA19: 58803.7 | AB19: 60932.65 | AC19: 61615.4 | AD19: 62458.45 | AE19: 59526.9 | AF19: 60064.65 | AG19: 58731.15 | AH19: =SUM(C19:AG19) -> 1857278.8
A20: 2 | B20: 员工宿舍费 | AH20: =SUM(C20:AG20) -> 0
A21: 3 | B21: 意外险 | C21: 287.78 | D21: 285.83 | E21: 285.83 | F21: 282.92 | G21: 290.69 | H21: 283.89 | I21: 281.94 | J21: 291.67 | K21: 290.69 | L21: 282.92 | M21: 292.64 | N21: 295.56 | O21: 299.44 | P21: 289.72 | Q21: 285.83 | R21: 275.14 | S21: 281.94 | T21: 279.03 | U21: 284.86 | V21: 285.83 | W21: 283.89 | X21: 275.14 | Y21: 283.89 | Z21: 275.14 | AA21: 276.11 | AB21: 286.81 | AC21: 291.67 | AD21: 296.53 | AE21: 281.94 | AF21: 280.97 | AG21: 273.19 | AH21: =SUM(C21:AG21) -> 8839.43
A22: 4 | B22: 雇主险 | C22: 337.11 | D22: 334.83 | E22: 334.83 | F22: 331.42 | G22: 340.53 | H22: 332.56 | I22: 330.28 | J22: 341.67 | K22: 340.53 | L22: 331.42 | M22: 342.81 | N22: 346.22 | O22: 350.78 | P22: 339.39 | Q22: 334.83 | R22: 322.31 | S22: 330.28 | T22: 326.86 | U22: 333.69 | V22: 334.83 | W22: 332.56 | X22: 322.31 | Y22: 332.56 | Z22: 322.31 | AA22: 323.44 | AB22: 335.97 | AC22: 341.67 | AD22: 347.36 | AE22: 330.28 | AF22: 329.14 | AG22: 320.03 | AH22: =SUM(C22:AG22) -> 10354.81
A23: 5 | B23: 员工餐费 | C23: 2576 | D23: 2560 | E23: 2560 | F23: 2536 | G23: 2576 | H23: 2536 | I23: 2520 | J23: 2608 | K23: 2592 | L23: 2544 | M23: 2600 | N23: 2616 | O23: 2648 | P23: 2576 | Q23: 2544 | R23: 2472 | S23: 2536 | T23: 2520 | U23: 2568 | V23: 2544 | W23: 2528 | X23: 2472 | Y23: 2536 | Z23: 2440 | AA23: 2448 | AB23: 2560 | AC23: 2584 | AD23: 2632 | AE23: 2512 | AF23: 2512 | AG23: 2456 | AH23: =SUM(C23:AG23) -> 78912
A24: 6 | B24: 高温福利费用 | F24: 575 | G24: 575 | H24: 575 | I24: 575 | J24: 575 | K24: 575 | L24: 575 | M24: 575 | N24: 575 | O24: 575 | T24: 560 | U24: 1120 | V24: 1120 | W24: 1120 | X24: 1120 | Y24: 1120 | Z24: 1120 | AA24: 560 | AB24: 1120 | AC24: 1120 | AD24: 1120 | AE24: 1120 | AF24: 1120 | AH24: =SUM(C24:AG24) -> 19190
A25: 7 | B25: 劳务人员工资 | C25: 16893.5 | D25: 17388 | E25: 16617.5 | F25: 17192.5 | G25: 16617.5 | H25: 15030.5 | I25: 16882 | J25: 15295 | K25: 16088.5 | L25: 15295 | M25: 15824 | N25: 16617.5 | O25: 15824 | P25: 17146.5 | Q25: 17146.5 | R25: 16617.5 | S25: 16617.5 | T25: 18710.5 | U25: 17641 | V25: 17652.5 | W25: 16065.5 | X25: 15272 | Y25: 21079.5 | Z25: 22609 | AA25: 19975.5 | AB25: 19458 | AC25: 17376.5 | AD25: 18434.5 | AE25: 19538.5 | AF25: 18216 | AG25: 19803 | AH25: =SUM(C25:AG25) -> 540925.5
A26: 8 | B26: 物料采购 | C26: 3110.4 | D26: 3110.4 | E26: 3110.4 | F26: 3110.4 | G26: 3110.4 | H26: 3110.4 | I26: 3110.4 | J26: 3110.4 | K26: 3110.4 | L26: 3110.4 | M26: 49700 | AH26: =SUM(C26:AG26) -> 80804
A27: 9 | B27: 工单赔付 | C27: 2096.77 | D27: 2096.77 | E27: 2096.77 | F27: 2096.77 | G27: 2096.77 | H27: 2096.77 | I27: 2096.77 | J27: 2096.77 | K27: 2096.77 | L27: 2096.77 | M27: 2096.77 | N27: 2096.77 | O27: 2096.77 | P27: 2096.77 | Q27: 2096.77 | R27: 2096.77 | S27: 2096.77 | T27: 2096.77 | U27: 2096.77 | V27: 2096.77 | W27: 2096.77 | X27: 2096.77 | Y27: 2096.77 | Z27: 2096.77 | AA27: 2096.77 | AB27: 2096.77 | AC27: 2096.77 | AD27: 2096.77 | AE27: 2096.77 | AF27: 2096.77 | AG27: 2096.77 | AH27: =SUM(C27:AG27) -> 64999.87
A28: 10 | B28: 设备成本摊销 | C28: 33651.84 | D28: 33651.84 | E28: 33651.84 | F28: 33651.84 | G28: 33651.84 | H28: 33651.84 | I28: 33651.84 | J28: 33651.84 | K28: 33651.84 | L28: 33651.84 | M28: 33651.84 | N28: 33651.84 | O28: 33651.84 | P28: 33651.84 | Q28: 33651.84 | R28: 33651.84 | S28: 33651.84 | T28: 33651.84 | U28: 33651.84 | V28: 33651.84 | W28: 33651.84 | X28: 33651.84 | Y28: 33651.84 | Z28: 33651.84 | AA28: 33651.84 | AB28: 33651.84 | AC28: 33651.84 | AD28: 33651.84 | AE28: 33651.84 | AF28: 33651.84 | AG28: 33651.84 | AH28: =SUM(C28:AG28) -> 1043207
A29: 二、主营业务成本总计 | C29: 118393 | D29: 118908.37 | E29: 118166.27 | F29: 118458.6 | G29: 119855.28 | H29: 116891.46 | I29: 118033.08 | J29: 119153.9 | K29: 119560.23 | L29: 116861.05 | M29: 166346.36 | N29: 117986.54 | O29: 118576.68 | P29: 116674.22 | Q29: 115744.77 | R29: 112724.01 | S29: 114923.08 | T29: 116375.25 | U29: 118264.36 | V29: 117771.52 | W29: 116101.81 | X29: 113574.61 | Y29: 121035.06 | Z29: 120777.66 | AA29: 118135.36 | AB29: 120442.04 | AC29: 119077.85 | AD29: 121037.45 | AE29: 119058.23 | AF29: 118271.37 | AG29: 117331.98 | AH29: =SUM(AH19:AH28) -> 3704511.5
A30: 主营业务税金及附加 | C30: 716.28 | D30: 745.46 | E30: 741.1 | F30: 715.97 | G30: 733.19 | H30: 741.87 | I30: 768.68 | J30: 794.57 | K30: 807.81 | L30: 796.18 | M30: 769.84 | N30: 822.93 | O30: 838.98 | P30: 829.92 | Q30: 857.18 | R30: 817.95 | S30: 810.37 | T30: 796.44 | U30: 798.83 | V30: 856.82 | W30: 858.82 | X30: 851.69 | Y30: 892.34 | Z30: 871.79 | AA30: 828.97 | AB30: 889.55 | AC30: 896.1 | AD30: 920.61 | AE30: 918.59 | AF30: 916.87 | AG30: 901.72 | AH30: =SUM(C30:AG30) -> 25507.42
A31: 三、主营业务利润（亏损以“-”号填列) | C31: -19626.08 | D31: -16117.93 | E31: -15976.16 | F31: -19734.31 | G31: -18756.06 | H31: -14596.28 | I31: -12041.01 | J31: -9591.72 | K31: -8172.71 | L31: -7076.53 | M31: -60194.41 | N31: -4513.56 | O31: -2890.38 | P31: -2237.76 | Q31: 2450.25 | R31: 61.82 | S31: -3182.39 | T31: -6554.98 | U31: -8114.96 | V31: 375.11 | W31: 2320.24 | X31: 3864.28 | Y31: 2008.17 | Z31: -567.75 | AA31: -3828.95 | AB31: 2217.27 | AC31: 4484.05 | AD31: 5904.86 | AE31: 7604.92 | AF31: 8154.77 | AG31: 7004.96 | AH31: =AH11-AH29-AH30 -> -187323.23
A32: 1 | B32: 管理人员工资 | C32: 10686.37 | D32: 10686.37 | E32: 10686.37 | F32: 10686.37 | G32: 10686.37 | H32: 10686.37 | I32: 10686.37 | J32: 10686.37 | K32: 10686.37 | L32: 10686.37 | M32: 10686.37 | N32: 10686.37 | O32: 10686.37 | P32: 10686.37 | Q32: 10686.37 | R32: 10686.37 | S32: 10686.37 | T32: 10686.37 | U32: 10686.37 | V32: 10686.37 | W32: 10686.37 | X32: 10686.37 | Y32: 10686.37 | Z32: 10686.37 | AA32: 10686.37 | AB32: 10686.37 | AC32: 10686.37 | AD32: 10686.37 | AE32: 10686.37 | AF32: 10686.37 | AG32: 10686.37 | AH32: =SUM(C32:AG32) -> 331277.47
A33: 2 | B33: 人事工资 | C33: 680.65 | D33: 680.65 | E33: 680.65 | F33: 680.65 | G33: 680.65 | H33: 680.65 | I33: 680.65 | J33: 680.65 | K33: 680.65 | L33: 680.65 | M33: 680.65 | N33: 680.65 | O33: 680.65 | P33: 680.65 | Q33: 680.65 | R33: 680.65 | S33: 680.65 | T33: 680.65 | U33: 680.65 | V33: 680.65 | W33: 680.65 | X33: 680.65 | Y33: 680.65 | Z33: 680.65 | AA33: 680.65 | AB33: 680.65 | AC33: 680.65 | AD33: 680.65 | AE33: 680.65 | AF33: 680.65 | AG33: 680.65 | AH33: =SUM(C33:AG33) -> 21100.15
A34: 3 | B34: 社会保险费 | C34: 1262.9032 | D34: 1262.9032 | E34: 1262.9032 | F34: 1262.9032 | G34: 1262.9032 | H34: 1262.9032 | I34: 1262.9032 | J34: 1262.9032 | K34: 1262.9032 | L34: 1262.9032 | M34: 1262.9032 | N34: 1262.9032 | O34: 1262.9032 | P34: 1262.9032 | Q34: 1262.9032 | R34: 1262.9032 | S34: 1262.9032 | T34: 1262.9032 | U34: 1262.9032 | V34: 1262.9032 | W34: 1262.9032 | X34: 1262.9032 | Y34: 1262.9032 | Z34: 1262.9032 | AA34: 1262.9032 | AB34: 1262.9032 | AC34: 1262.9032 | AD34: 1262.9032 | AE34: 1262.9032 | AF34: 1262.9032 | AG34: 1262.9032 | AH34: =ROUND(SUM(C34:AG34),2) -> 39150
A35: 4 | B35: 意外险 | C35: 29.17 | D35: 29.17 | E35: 29.17 | F35: 29.17 | G35: 29.17 | H35: 29.17 | I35: 29.17 | J35: 29.17 | K35: 29.17 | L35: 29.17 | M35: 29.17 | N35: 29.17 | O35: 29.17 | P35: 29.17 | Q35: 29.17 | R35: 29.17 | S35: 29.17 | T35: 29.17 | U35: 29.17 | V35: 29.17 | W35: 29.17 | X35: 29.17 | Y35: 29.17 | Z35: 29.17 | AA35: 29.17 | AB35: 29.17 | AC35: 29.17 | AD35: 29.17 | AE35: 29.17 | AF35: 29.17 | AG35: 29.17 | AH35: =SUM(C35:AG35) -> 904.27
A36: 5 | B36: 雇主险 | C36: 34.17 | D36: 34.17 | E36: 34.17 | F36: 34.17 | G36: 34.17 | H36: 34.17 | I36: 34.17 | J36: 34.17 | K36: 34.17 | L36: 34.17 | M36: 34.17 | N36: 34.17 | O36: 34.17 | P36: 34.17 | Q36: 34.17 | R36: 34.17 | S36: 34.17 | T36: 34.17 | U36: 34.17 | V36: 34.17 | W36: 34.17 | X36: 34.17 | Y36: 34.17 | Z36: 34.17 | AA36: 34.17 | AB36: 34.17 | AC36: 34.17 | AD36: 34.17 | AE36: 34.17 | AF36: 34.17 | AG36: 34.17 | AH36: =SUM(C36:AG36) -> 1059.27
A37: 6 | B37: 福利费 | AH37: =SUM(C37:AG37) -> 0
A38: 7 | B38: 招聘费 | C38: 620 | D38: 560 | E38: 580 | F38: 520 | G38: 540 | H38: 560 | I38: 500 | J38: 580 | K38: 540 | L38: 420 | M38: 520 | N38: 560 | O38: 520 | P38: 480 | Q38: 480 | R38: 460 | S38: 500 | T38: 480 | U38: 460 | V38: 480 | W38: 480 | X38: 420 | Y38: 400 | Z38: 380 | AA38: 340 | AB38: 360 | AC38: 300 | AD38: 280 | AE38: 320 | AF38: 320 | AG38: 280 | AH38: =SUM(C38:AG38) -> 14240
A39: 8 | B39: 招标代理费 | AH39: =SUM(C39:AG39) -> 0
A40: 9 | B40: 其他 | D40: 233004.05 | AH40: =SUM(C40:AG40) -> 233004.05
A41: 10 | B41: 设备维修费 | AH41: =SUM(C41:AG41) -> 0
...

Sheet 8月处理量
A1: 日 | B1: 新一代查询业务量 （散件外走） | C1: 新一代查询业务量 （分拣封发） | D1: 新一代查询业务量 （总包经转） | E1: 平刷件量(剔除） | F1: 合计
A2: 45870 | B2: 265918 | C2: 420926 | D2: 28237 | E2: 64498 | F2: =SUM(B2:D2)-E2 -> 650583
A3: =A2+1 -> 45871 | B3: 268929 | C3: 454959 | D3: 23151 | E3: 70686 | F3: =SUM(B3:D3)-E3 -> 676353
A4: =A3+1 -> 45872 | B4: 278901 | C4: 439012 | D4: 21473 | E4: 66878 | F4: =SUM(B4:D4)-E4 -> 672508
A5: =A4+1 -> 45873 | B5: 255750 | C5: 429140 | D5: 24325 | E5: 58905 | F5: =SUM(B5:D5)-E5 -> 650310
A6: =A5+1 -> 45874 | B6: 263565 | C6: 430762 | D6: 26767 | E6: 55573 | F6: =SUM(B6:D6)-E6 -> 665521
A7: =A6+1 -> 45875 | B7: 260161 | C7: 442334 | D7: 31614 | E7: 60928 | F7: =SUM(B7:D7)-E7 -> 673181
A8: =A7+1 -> 45876 | B8: 265972 | C8: 493373 | D8: 27835 | E8: 90321 | F8: =SUM(B8:D8)-E8 -> 696859
A9: =A8+1 -> 45877 | B9: 270233 | C9: 477225 | D9: 29268 | E9: 57001 | F9: =SUM(B9:D9)-E9 -> 719725
A10: =A9+1 -> 45878 | B10: 283386 | C10: 480012 | D10: 26328 | E10: 58310 | F10: =SUM(B10:D10)-E10 -> 731416
A11: =A10+1 -> 45879 | B11: 268084 | C11: 513384 | D11: 21672 | E11: 81991 | F11: =SUM(B11:D11)-E11 -> 721149
A12: =A11+1 -> 45880 | B12: 245764 | C12: 485640 | D12: 26098 | E12: 59619 | F12: =SUM(B12:D12)-E12 -> 697883
A13: =A12+1 -> 45881 | B13: 269576 | C13: 507623 | D13: 28264 | E13: 60690 | F13: =SUM(B13:D13)-E13 -> 744773
A14: =A13+1 -> 45882 | B14: 286425 | C14: 498912 | D14: 28709 | E14: 55097 | F14: =SUM(B14:D14)-E14 -> 758949
... A32: =A31+1 -> 45900 | B32: 304900 | C32: 765662 | D32: 22729 | E32: 278936 | F32: =SUM(B32:D32)-E32 -> 814355
A33: 合计 | B33: =SUM(B2:B32) -> 8697170 | C33: =SUM(C2:C32) -> 15754159 | D33: =SUM(D2:D32) -> 836883 | E33: =SUM(E2:E32) -> 2203285 | F33: =SUM(F2:F32) -> 23084927

Sheet 25年9月日经营数据
A1: 2025年南京项目处理经营情况（9月）
A3: 科目 | C3: 45901 | D3: =C3+1 -> 45902 | E3: =D3+1 -> 45903 | F3: =E3+1 -> 45904 | G3: =F3+1 -> 45905 | H3: =G3+1 -> 45906 | I3: =H3+1 -> 45907 | J3: =I3+1 -> 45908 | K3: =J3+1 -> 45909 | ... AG3: =AF3+1 -> 45931 | AH3: 月度合计
C4: 进口处理 | D4: 进口处理 | E4: 进口处理 | F4: 进口处理 | G4: 进口处理 | H4: 进口处理 | I4: 进口处理 | J4: 进口处理 | K4: 进口处理 | L4: 进口处理 | M4: 进口处理 | N4: 进口处理 | O4: 进口处理 | P4: 进口处理 | Q4: 进口处理 | R4: 进口处理 | S4: 进口处理 | T4: 进口处理 | U4: 进口处理 | V4: 进口处理 | W4: 进口处理 | X4: 进口处理 | Y4: 进口处理 | Z4: 进口处理 | AA4: 进口处理 | AB4: 进口处理 | AC4: 进口处理 | AD4: 进口处理 | AE4: 进口处理 | AF4: 进口处理 | AG4: 进口处理 | AH4: 进口处理
A5: 1 | B5: 散件处理量 | C5: =SUMIFS('25年9月处理量'!$F:$F,'25年9月处理量'!$A:$A,C3) -> 834018 | D5: =SUMIFS('25年9月处理量'!$F:$F,'25年9月处理量'!$A:$A,D3) -> 873579 | E5: =SUMIFS('25年9月处理量'!$F:$F,'25年9月处理量'!$A:$A,E3) -> 938726 | F5: =SUMIFS('25年9月处理量'!$F:$F,'25年9月处理量'!$A:$A,F3) -> 934687 | G5: =SUMIFS('25年9月处理量'!$F:$F,'25年9月处理量'!$A:$A,G3) -> 976230 | H5: =SUMIFS('25年9月处理量'!$F:$F,'25年9月处理量'!$A:$A,H3) -> 892603 | I5: =SUMIFS('25年9月处理量'!$F:$F,'25年9月处理量'!$A:$A,I3) -> 893308 | J5: =SUMIFS('25年9月处理量'!$F:$F,'25年9月处理量'!$A:$A,J3) -> 897556 | ... AG5: =SUMIFS('25年9月处理量'!$F:$F,'25年9月处理量'!$A:$A,AG3) -> 0 | AH5: =SUM(C5:AG5) -> 27199706
A6: 2 | B6: 散件处理单价 | C6: 0.1667 | D6: 0.1667 | E6: 0.1667 | F6: 0.1667 | G6: 0.1667 | H6: 0.1667 | I6: 0.1667 | J6: 0.1667 | K6: 0.1667 | L6: 0.1667 | M6: 0.1667 | N6: 0.1667 | O6: 0.1667 | P6: 0.1667 | Q6: 0.1667 | R6: 0.1667 | S6: 0.1667 | T6: 0.1667 | U6: 0.1667 | V6: 0.1667 | W6: 0.1667 | X6: 0.1667 | Y6: 0.1667 | Z6: 0.1667 | AA6: 0.1667 | AB6: 0.1667 | AC6: 0.1667 | AD6: 0.1667 | AE6: 0.1667 | AF6: 0.1667 | AH6: 0.1667
A7: 3 | B7: 散件处理收入 | C7: 139030.8 | D7: 145625.62 | E7: 156485.62 | F7: 155812.32 | G7: 162737.54 | H7: 148796.92 | I7: 148914.44 | J7: 149622.59 | K7: 154351.7 | L7: 153784.75 | M7: 158537.7 | N7: 149847.8 | O7: 157890.74 | P7: 144718.44 | Q7: 142077.24 | R7: 144449.72 | S7: 151507.3 | T7: 163190.63 | U7: 151643.16 | V7: 149619.42 | W7: 141761.01 | X7: 145759.31 | Y7: 150032.17 | Z7: 154268.68 | AA7: 148896.61 | AB7: 153474.52 | AC7: 157544 | AD7: 153933.61 | AE7: 158569.54 | AF7: 141307.09 | AH7: =SUM(C7:AG7) -> 4534191
A8: 4 | B8: 考核扣款 | C8: 3000 | D8: 3000 | E8: 3000 | F8: 3000 | G8: 3000 | H8: 3000 | I8: 3000 | J8: 3000 | K8: 3000 | L8: 3000 | M8: 3000 | N8: 3000 | O8: 3000 | P8: 3000 | Q8: 3000 | R8: 3000 | S8: 3000 | T8: 3000 | U8: 3000 | V8: 3000 | W8: 3000 | X8: 3000 | Y8: 3000 | Z8: 3000 | AA8: 3000 | AB8: 3000 | AC8: 3000 | AD8: 3000 | AE8: 3000 | AF8: 3000 | AH8: =SUM(C8:AG8) -> 90000
A9: 5 | B9: 补贴费用 | AH9: =SUM(C9:AG9) -> 0
A10: 6 | B10: 开票金额 | C10: 136030.8 | D10: 142625.62 | E10: 153485.62 | F10: 152812.32 | G10: 159737.54 | H10: 145796.92 | I10: 145914.44 | J10: 146622.59 | K10: 151351.7 | L10: 150784.75 | M10: 155537.7 | N10: 146847.8 | O10: 154890.74 | P10: 141718.44 | Q10: 139077.24 | R10: 141449.72 | S10: 148507.3 | T10: 160190.63 | U10: 148643.16 | V10: 146619.42 | W10: 138761.01 | X10: 142759.31 | Y10: 147032.17 | Z10: 151268.68 | AA10: 145896.61 | AB10: 150474.52 | AC10: 154544 | AD10: 150933.61 | AE10: 155569.54 | AF10: 138307.09 | AH10: =SUM(C10:AG10) -> 4444191
A11: 一、主营业务收入总计 | C11: 128330.94 | D11: 134552.47 | E11: 144797.75 | F11: 144162.57 | G11: 150695.79 | H11: 137544.26 | I11: 137655.13 | J11: 138323.2 | K11: 142784.62 | L11: 142249.76 | M11: 146733.68 | N11: 138535.66 | O11: 146123.34 | P11: 133696.64 | Q11: 131204.94 | R11: 133443.13 | S11: 140101.23 | T11: 151123.24 | U11: 140229.4 | V11: 138320.21 | W11: 130906.61 | X11: 134678.59 | Y11: 138709.59 | Z11: 142706.3 | AA11: 137638.31 | AB11: 141957.09 | AC11: 145796.23 | AD11: 142390.2 | AE11: 146763.72 | AF11: 130478.39 | AH11: =SUM(C11:AG11) -> 4192633
A12: 1 | B12: 管理人员数量 | C12: 22 | D12: 20 | E12: 21 | F12: 21 | G12: 22 | H12: 21 | I12: 22 | J12: 20 | K12: 22 | L12: 21 | M12: 21 | N12: 22 | O12: 22 | P12: 24 | Q12: 24 | R12: 21 | S12: 22 | T12: 22 | U12: 20 | V12: 18 | W12: 21 | X12: 20 | Y12: 21 | Z12: 20 | AA12: 17 | AB12: 17 | AC12: 20 | AD12: 18 | AE12: 19 | AF12: 21 | AH12: =SUM(C12:AG12) -> 622
A13: 2 | B13: 自有员工数量 | C13: 281 | D13: 279 | E13: 292 | F13: 293 | G13: 292 | H13: 284 | I13: 282 | J13: 279 | K13: 277 | L13: 290 | M13: 290 | N13: 287 | O13: 297 | P13: 299 | Q13: 276 | R13: 275 | S13: 268 | T13: 281 | U13: 295 | V13: 298 | W13: 301 | X13: 295 | Y13: 282 | Z13: 289 | AA13: 287 | AB13: 286 | AC13: 281 | AD13: 287 | AE13: 273 | AF13: 263 | AH13: =SUM(C13:AG13) -> 8559
A14: 3 | B14: 劳务人员数量 | C14: 72 | D14: 83 | E14: 90 | F14: 85 | G14: 94 | H14: 92 | I14: 89 | J14: 72 | K14: 91 | L14: 102 | M14: 103 | N14: 109 | O14: 107 | P14: 90 | Q14: 89 | R14: 96 | S14: 115 | T14: 126 | U14: 104 | V14: 99 | W14: 82 | X14: 84 | Y14: 90 | Z14: 80 | AA14: 102 | AB14: 103 | AC14: 119 | AD14: 114 | AE14: 105 | AF14: 98 | AH14: =SUM(C14:AG14) -> 2885
A15: 4 | B15: 总人数 | C15: 375 | D15: 382 | E15: 403 | F15: 399 | G15: 408 | H15: 397 | I15: 393 | J15: 371 | K15: 390 | L15: 413 | M15: 414 | N15: 418 | O15: 426 | P15: 413 | Q15: 389 | R15: 392 | S15: 405 | T15: 429 | U15: 419 | V15: 415 | W15: 404 | X15: 399 | Y15: 393 | Z15: 389 | AA15: 406 | AB15: 406 | AC15: 420 | AD15: 419 | AE15: 397 | AF15: 382 | AH15: =SUM(C15:AG15) -> 12066
A16: 5 | B16: 总工时 | C16: 4039.5 | D16: 4148.5 | E16: 4381.5 | F16: 4322.5 | G16: 4408 | H16: 4298.5 | I16: 4186.5 | J16: 3995 | K16: 4214.5 | L16: 4496.5 | M16: 4475.5 | N16: 4536 | O16: 4574 | P16: 4443 | Q16: 4181.5 | R16: 4251.5 | S16: 4393 | T16: 4692 | U16: 4586.5 | V16: 4556 | W16: 4365 | X16: 4301.5 | Y16: 4253.5 | Z16: 4241 | AA16: 4473.5 | AB16: 4466 | AC16: 4599 | AD16: 4609.5 | AE16: 4339.5 | AF16: 4102 | AH16: =SUM(C16:AG16) -> 130930.5
A17: 人均效能 | C17: 2224.048 | D17: 2286.856 | E17: 2329.3449 | F17: 2342.5739 | G17: 2392.7206 | H17: 2248.3703 | I17: 2273.0483 | J17: 2419.2884 | K17: 2374.1667 | L17: 2233.7143 | M17: 2297.1884 | N17: 2150.4952 | O17: 2223.3685 | P17: 2102.0266 | Q17: 2190.9846 | R17: 2210.523 | S17: 2244.1037 | T17: 2281.9301 | U17: 2171.0668 | V17: 2162.7398 | W17: 2104.9406 | X17: 2191.4311 | Y17: 2290.1094 | Z17: 2378.9897 | AA17: 2200.0025 | AB17: 2267.6429 | AC17: 2250.1786 | AD17: 2203.8592 | AE17: 2396.0378 | AF17: 2219.0393 | AH17: =AH5/AH15 -> 2254.2438
A18: 人均小时效能 | C18: 206.46565 | D18: 210.57708 | E18: 214.24763 | F18: 216.23759 | G18: 221.46779 | H18: 207.65453 | I18: 213.37824 | J18: 224.66984 | K18: 219.69985 | L18: 205.16491 | M18: 212.49827 | N18: 198.17174 | O18: 207.07368 | P18: 195.39433 | Q18: 203.8247 | R18: 203.8163 | S18: 206.88869 | T18: 208.64194 | U18: 198.33795 | V18: 197.0011 | W18: 194.82153 | X18: 203.27351 | Y18: 211.59351 | Z18: 218.20962 | AA18: 199.66492 | AB18: 206.14935 | AC18: 205.49576 | AD18: 200.3291 | AE18: 219.20198 | AF18: 206.64871 | AH18: =AH5/AH16 -> 207.74156
A19: 1 | B19: 自有员工工资 | C19: 59222.15 | D19: 58876.8 | E19: 61695.5 | F19: 61657.45 | G19: 61397.45 | H19: 59729.55 | I19: 58279.85 | J19: 58377.85 | K19: 58372.55 | L19: 61216.6 | M19: 60661.55 | N19: 60524 | O19: 61636.8 | P19: 62832.85 | Q19: 58216.3 | R19: 57848.2 | S19: 56711 | T19: 59259.2 | U19: 62211.6 | V19: 62707.15 | W19: 62834.75 | X19: 61272.3 | Y19: 59101.85 | Z19: 60996.85 | AA19: 60589.7 | AB19: 60239.1 | AC19: 59263.5 | AD19: 60577.85 | AE19: 57497.6 | AF19: 54609.05 | AH19: =SUM(C19:AG19) -> 1798416.9
A20: 2 | B20: 员工宿舍费 | AH20: =SUM(C20:AG20) -> 0
A21: 3 | B21: 意外险 | C21: 273.19 | D21: 271.25 | E21: 283.89 | F21: 284.86 | G21: 283.89 | H21: 276.11 | I21: 274.17 | J21: 271.25 | K21: 269.31 | L21: 281.94 | M21: 281.94 | N21: 279.03 | O21: 288.75 | P21: 290.69 | Q21: 268.33 | R21: 267.36 | S21: 260.56 | T21: 273.19 | U21: 286.81 | V21: 289.72 | W21: 292.64 | X21: 286.81 | Y21: 274.17 | Z21: 280.97 | AA21: 279.03 | AB21: 278.06 | AC21: 273.19 | AD21: 279.03 | AE21: 265.42 | AF21: 255.69 | AH21: =SUM(C21:AG21) -> 8321.25
